Workbook
Name ReportObject1_0: 'Ячейка 24'!$E$10
Name ReportObject1_1: 'Ячейка 24'!$H$10
Name ReportObject1_2: 'Ячейка 24'!$B$18
Name ReportObject1_3: 'Ячейка 24'!$F$18
Name ReportObject10_0: 'Ячейка 4'!$E$10
Name ReportObject10_1: 'Ячейка 4'!$H$10
Name ReportObject10_2: 'Ячейка 4'!$B$18
Name ReportObject10_3: 'Ячейка 4'!$F$18
Name ReportObject11_0: 'Ячейка 36'!$E$10
Name ReportObject11_1: 'Ячейка 36'!$H$10
Name ReportObject11_2: 'Ячейка 36'!$B$18
Name ReportObject11_3: 'Ячейка 36'!$F$18
Name ReportObject12_0: 'Ячейка 37'!$E$10
Name ReportObject12_1: 'Ячейка 37'!$H$10
Name ReportObject12_2: 'Ячейка 37'!$B$18
Name ReportObject12_3: 'Ячейка 37'!$F$18
Name ReportObject13_0: 'Ячейка 10Эн'!$E$10
Name ReportObject13_1: 'Ячейка 10Эн'!$H$10
Name ReportObject13_2: 'Ячейка 10Эн'!$B$18
Name ReportObject13_3: 'Ячейка 10Эн'!$F$18
Name ReportObject14_0: 'Ячейка 16РЖД'!$E$10
Name ReportObject14_1: 'Ячейка 16РЖД'!$H$10
Name ReportObject14_2: 'Ячейка 16РЖД'!$B$18
Name ReportObject14_3: 'Ячейка 16РЖД'!$F$18
Name ReportObject15_0: Академия!$E$10
Name ReportObject15_0: 'Добрыня вв1'!$E$10
Name ReportObject15_0: 'Добрыня вв2'!$E$10
Name ReportObject15_0: Мегафон!$E$10
Name ReportObject15_0: Тихомирова!$E$10
Name ReportObject15_0: 'Ячейка 14РЖД'!$E$10
Name ReportObject15_1: Академия!$H$10
Name ReportObject15_1: 'Добрыня вв1'!$H$10
Name ReportObject15_1: 'Добрыня вв2'!$H$10
Name ReportObject15_1: Мегафон!$H$10
Name ReportObject15_1: Тихомирова!$H$10
Name ReportObject15_1: 'Ячейка 14РЖД'!$H$10
Name ReportObject15_2: Академия!$B$18
Name ReportObject15_2: 'Добрыня вв1'!$B$18
Name ReportObject15_2: 'Добрыня вв2'!$B$18
Name ReportObject15_2: Мегафон!$B$18
Name ReportObject15_2: Тихомирова!$B$18
Name ReportObject15_2: 'Ячейка 14РЖД'!$B$18
Name ReportObject15_3: Академия!$F$18
Name ReportObject15_3: 'Добрыня вв1'!$F$18
Name ReportObject15_3: 'Добрыня вв2'!$F$18
Name ReportObject15_3: Мегафон!$F$18
Name ReportObject15_3: Тихомирова!$F$18
Name ReportObject15_3: 'Ячейка 14РЖД'!$F$18
Name ReportObject16_0: 'Ячейка 13БОС'!$E$10
Name ReportObject16_1: 'Ячейка 13БОС'!$H$10
Name ReportObject16_2: 'Ячейка 13БОС'!$B$18
Name ReportObject16_3: 'Ячейка 13БОС'!$F$18
Name ReportObject17_0: 'Ячейка 32БОС'!$E$10
Name ReportObject17_1: 'Ячейка 32БОС'!$H$10
Name ReportObject17_2: 'Ячейка 32БОС'!$B$18
Name ReportObject17_3: 'Ячейка 32БОС'!$F$18
Name ReportObject18_0: 'УЗСК вв1'!$E$10
Name ReportObject18_0: 'УЗСК вв2'!$E$10
Name ReportObject18_0: 'УЗСК вв3'!$E$10
Name ReportObject18_0: 'ячейка 25БОС'!$E$10

Sheet ObserverReportInfo_&!()$bbQ
A1: Режимный день
A2: TYPE2 | B2: HOUR | C2: 25 | D2: 1 | E2: H | F2: 1 | G2: MAIN | K2: EXCEL | M2: 4 | W2: 1
A3: MAINSHEET | B3: 2
A4: DATE | B4: 10 | C4: 5 | D4: dd mmmm | F4: BEGIN | O4: NOSHIFT
A5: DATE | B5: 10 | C5: 8 | D5: yyyy года | F5: BEGIN | O5: NOSHIFT
A6: COLUMN | B6: 18 | C6: 2 | E6: 692 | G6: RESNONE | J6: NONE | K6: CHN | M6: BEGINVALUE | N6: 0 | O6: 480 | P6: 4 | T6: ZONENAMES | Z6: RESULT_CAPTIONS | AF6: -1 | AG6: 0 | AO6: NOSHIFT | AT6: 0 | AV6: 61 | AW6: NOCHANGE | BC6: CUTDATEBEGIN | BI6: 4 | BJ6: 0 | BK6: 0 | BL6: 1 | BM6: 0
A7: COLUMN | B7: 18 | C7: 6 | E7: 694 | G7: RESNONE | J7: NONE | K7: CHN | M7: BEGINVALUE | N7: 0 | O7: 480 | P7: 4 | T7: ZONENAMES | Z7: RESULT_CAPTIONS | AF7: -1 | AG7: 0 | AO7: NOSHIFT | AT7: 0 | AV7: 95 | AW7: NOCHANGE | BC7: CUTDATEBEGIN | BE7: ENLIKEPOW | BI7: 8 | BJ7: 0 | BK7: 0 | BL7: 1 | BM7: 0
A8: MAINSHEET | B8: 3
A9: DATE | B9: 10 | C9: 5 | D9: dd mmmm | F9: BEGIN | O9: NOSHIFT
A10: DATE | B10: 10 | C10: 8 | D10: yyyy года | F10: BEGIN | O10: NOSHIFT
A11: COLUMN | B11: 18 | C11: 2 | E11: 687 | G11: RESNONE | J11: NONE | K11: CHN | M11: BEGINVALUE | N11: 0 | O11: 483 | P11: 4 | T11: ZONENAMES | Z11: RESULT_CAPTIONS | AF11: -1 | AG11: 0 | AO11: NOSHIFT | AT11: 0 | AV11: 61 | AW11: NOCHANGE | BC11: CUTDATEBEGIN | BI11: 4 | BJ11: 0 | BK11: 0 | BL11: 1 | BM11: 0
A12: COLUMN | B12: 18 | C12: 6 | E12: 689 | G12: RESNONE | J12: NONE | K12: CHN | M12: BEGINVALUE | N12: 0 | O12: 483 | P12: 4 | T12: ZONENAMES | Z12: RESULT_CAPTIONS | AF12: -1 | AG12: 0 | AO12: NOSHIFT | AT12: 0 | AV12: 95 | AW12: NOCHANGE | BC12: CUTDATEBEGIN | BE12: ENLIKEPOW | BI12: 8 | BJ12: 0 | BK12: 0 | BL12: 1 | BM12: 0
A13: MAINSHEET | B13: 4
A14: DATE | B14: 10 | C14: 5 | D14: dd mmmm | F14: BEGIN | O14: NOSHIFT
A15: DATE | B15: 10 | C15: 8 | D15: yyyy года | F15: BEGIN | O15: NOSHIFT
A16: COLUMN | B16: 18 | C16: 2 | E16: 702 | G16: RESNONE | J16: NONE | K16: CHN | M16: BEGINVALUE | N16: 0 | O16: 484 | P16: 4 | T16: ZONENAMES | Z16: RESULT_CAPTIONS | AF16: -1 | AG16: 0 | AO16: NOSHIFT | AT16: 0 | AV16: 61 | AW16: NOCHANGE | BC16: CUTDATEBEGIN | BI16: 4 | BJ16: 0 | BK16: 0 | BL16: 1 | BM16: 0
A17: COLUMN | B17: 18 | C17: 6 | E17: 704 | G17: RESNONE | J17: NONE | K17: CHN | M17: BEGINVALUE | N17: 0 | O17: 484 | P17: 4 | T17: ZONENAMES | Z17: RESULT_CAPTIONS | AF17: -1 | AG17: 0 | AO17: NOSHIFT | AT17: 0 | AV17: 95 | AW17: NOCHANGE | BC17: CUTDATEBEGIN | BE17: ENLIKEPOW | BI17: 8 | BJ17: 0 | BK17: 0 | BL17: 1 | BM17: 0
A18: MAINSHEET | B18: 5
A19: DATE | B19: 10 | C19: 5 | D19: dd mmmm | F19: BEGIN | O19: NOSHIFT
A20: DATE | B20: 10 | C20: 8 | D20: yyyy года | F20: BEGIN | O20: NOSHIFT
A21: COLUMN | B21: 18 | C21: 2 | E21: 697 | G21: RESNONE | J21: NONE | K21: CHN | M21: BEGINVALUE | N21: 0 | O21: 481 | P21: 4 | T21: ZONENAMES | Z21: RESULT_CAPTIONS | AF21: -1 | AG21: 0 | AO21: NOSHIFT | AT21: 0 | AV21: 61 | AW21: NOCHANGE | BC21: CUTDATEBEGIN | BI21: 4 | BJ21: 0 | BK21: 0 | BL21: 1 | BM21: 0
A22: COLUMN | B22: 18 | C22: 6 | E22: 699 | G22: RESNONE | J22: NONE | K22: CHN | M22: BEGINVALUE | N22: 0 | O22: 481 | P22: 4 | T22: ZONENAMES | Z22: RESULT_CAPTIONS | AF22: -1 | AG22: 0 | AO22: NOSHIFT | AT22: 0 | AV22: 95 | AW22: NOCHANGE | BC22: CUTDATEBEGIN | BE22: ENLIKEPOW | BI22: 8 | BJ22: 0 | BK22: 0 | BL22: 1 | BM22: 0
A23: MAINSHEET | B23: 6
A24: DATE | B24: 10 | C24: 5 | D24: dd mmmm | F24: BEGIN | O24: NOSHIFT
A25: DATE | B25: 10 | C25: 8 | D25: yyyy года | F25: BEGIN | O25: NOSHIFT
A26: COLUMN | B26: 18 | C26: 2 | E26: 1786 | G26: RESNONE | J26: NONE | K26: CHN | M26: BEGINVALUE | N26: 0 | O26: 790 | P26: 4 | T26: ZONENAMES | Z26: RESULT_CAPTIONS | AF26: -1 | AG26: 0 | AO26: NOSHIFT | AT26: 0 | AV26: 61 | AW26: NOCHANGE | BC26: CUTDATEBEGIN | BI26: 4 | BJ26: 0 | BK26: 0 | BL26: 1 | BM26: 0
A27: COLUMN | B27: 18 | C27: 6 | E27: 1788 | G27: RESNONE | J27: NONE | K27: CHN | M27: BEGINVALUE | N27: 0 | O27: 790 | P27: 4 | T27: ZONENAMES | Z27: RESULT_CAPTIONS | AF27: -1 | AG27: 0 | AO27: NOSHIFT | AT27: 0 | AV27: 95 | AW27: NOCHANGE | BC27: CUTDATEBEGIN | BE27: ENLIKEPOW | BI27: 8 | BJ27: 0 | BK27: 0 | BL27: 1 | BM27: 0
A28: MAINSHEET | B28: 7
A29: DATE | B29: 10 | C29: 5 | D29: dd mmmm | F29: BEGIN | O29: NOSHIFT
A30: DATE | B30: 10 | C30: 8 | D30: yyyy года | F30: BEGIN | O30: NOSHIFT
A31: COLUMN | B31: 18 | C31: 2 | E31: 1769 | G31: RESNONE | J31: NONE | K31: CHN | M31: BEGINVALUE | N31: 0 | O31: 784 | P31: 4 | T31: ZONENAMES | Z31: RESULT_CAPTIONS | AF31: -1 | AG31: 0 | AO31: NOSHIFT | AT31: 0 | AV31: 61 | AW31: NOCHANGE | BC31: CUTDATEBEGIN | BI31: 4 | BJ31: 0 | BK31: 0 | BL31: 1 | BM31: 0
A32: COLUMN | B32: 18 | C32: 6 | E32: 1771 | G32: RESNONE | J32: NONE | K32: CHN | M32: BEGINVALUE | N32: 0 | O32: 784 | P32: 4 | T32: ZONENAMES | Z32: RESULT_CAPTIONS | AF32: -1 | AG32: 0 | AO32: NOSHIFT | AT32: 0 | AV32: 95 | AW32: NOCHANGE | BC32: CUTDATEBEGIN | BE32: ENLIKEPOW | BI32: 8 | BJ32: 0 | BK32: 0 | BL32: 1 | BM32: 0
A33: MAINSHEET | B33: 8
A34: DATE | B34: 10 | C34: 5 | D34: dd mmmm | F34: BEGIN | O34: NOSHIFT
A35: DATE | B35: 10 | C35: 8 | D35: yyyy года | F35: BEGIN | O35: NOSHIFT
A36: COLUMN | B36: 18 | C36: 2 | E36: 117 | G36: RESNONE | J36: NONE | K36: CHN | M36: BEGINVALUE | N36: 0 | O36: 201 | P36: 4 | T36: ZONENAMES | Z36: RESULT_CAPTIONS | AF36: -1 | AG36: 0 | AO36: NOSHIFT | AT36: 0 | AV36: 61 | AW36: NOCHANGE | BC36: CUTDATEBEGIN | BI36: 4 | BJ36: 0 | BK36: 0 | BL36: 1 | BM36: 0
A37: COLUMN | B37: 18 | C37: 6 | E37: 119 | G37: RESNONE | J37: NONE | K37: CHN | M37: BEGINVALUE | N37: 0 | O37: 201 | P37: 4 | T37: ZONENAMES | Z37: RESULT_CAPTIONS | AF37: -1 | AG37: 0 | AO37: NOSHIFT | AT37: 0 | AV37: 95 | AW37: NOCHANGE | BC37: CUTDATEBEGIN | BE37: ENLIKEPOW | BI37: 8 | BJ37: 0 | BK37: 0 | BL37: 1 | BM37: 0
A38: MAINSHEET | B38: 9
A39: DATE | B39: 10 | C39: 5 | D39: dd mmmm | F39: BEGIN | O39: NOSHIFT
A40: DATE | B40: 10 | C40: 8 | D40: yyyy года | F40: BEGIN | O40: NOSHIFT
...

Sheet Ячейка 24
A1: ОАО "Пластик" | G1: Шифр | M1: I. Сведения о присоединенных трансформаторах и высоковольтных электродвигателях
A2: (наименование предприятия) | M2: 1. Трансформаторы
A3: г. Узловая, Тульская, 1 | G3: Питающий центр | I3: П/ст №167 (ГПП-1) | M3: №№ | N3: Место установки | P3: Мощность | R3: Номинальн. | T3: Включен. | V3: Назначение | X3: Примечание
A4: (адрес) | R4: напряжение | T4: на ответвление | V4: тр-ра
G5: № фидера | I5: яч 24 тр-р №1 | M5: п/п | P5: ква | R5: ________ кВ | T5: ________ кВ | V5: силов. освет.
A6: (министерство, ведомство) | V6: печной
A8: ПРОТОКОЛ (первичный)
A9: записей показания электросчетчиков и вольтметров, а также определение
A10: нагрузок и тангенса "фи" за | E10: 20 декабря | H10: 2017года
A11: напряжения | E11: ______6000_____________ | I11: вольт
A13: Время записи часы | B13: Активн. сч-к тип | D13: СЭТ-4ТМ.03М | F13: Реактивн. сч-к тип | H13: СЭТ-4ТМ.03М | I13: Тангенс "фи" | J13: Показание | L13: Мощность
B14: ____________л__ | D14: № 812091210 | F14: ____________л__ | H14: №812091210 | J14: вольтметр. | L14: включен.
B15: Расчетн. коэф | D15: 18000 | F15: Расчетн. коэф | H15: 18000 | J15: на стороне | L15: компенсир.
B16: показ. | C16: разность | D16: расход за | F16: показ. | G16: разность | H16: расход за | J16: в\н | K16: н\н | L16: устройств
B17: сч-ка | C17: показ. | D17: час (кВт) | F17: сч-ка | G17: показ. | H17: час (кВт) | L17: кВар | M17: 2. Высоковольтные электродвигатели
A18: 0-00 | B18: 6528.6958 | F18: 2117.867 | M18: №№ | N18: Место | Q18: Тип | T18: Номинальная | W18: Примечание
A19: 1-00 | B19: 6528.7743 | C19: =IF(B19="","",IF(LEN(TRUNC(B18,0))-LEN(TRUNC(B19,0))=0,B19-B18,IF(LEN(TRUNC(B18,0))-LEN(TRUNC(B19,0))>0,VALUE(LEFT(B18,LEN(TRUNC(B18,0))-LEN(TRUNC(B19,0))))*POWER(10,LEN(TRUNC(B19,0)))+B19-B18,B19-B18-VALUE(LEFT(B19,LEN(TRUNC(B19,0))-LEN(TRUNC(B18,0))))*POWER(10,LEN(TRUNC(B18,0)))))) -> 0.0785 | D19: =IF(C19="","",C19*$D$15) -> 1413 | F19: 2117.8958 | G19: =IF(F19="","",IF(LEN(TRUNC(F18,0))-LEN(TRUNC(F19,0))=0,F19-F18,IF(LEN(TRUNC(F18,0))-LEN(TRUNC(F19,0))>0,VALUE(LEFT(F18,LEN(TRUNC(F18,0))-LEN(TRUNC(F19,0))))*POWER(10,LEN(TRUNC(F19,0)))+F19-F18,F19-F18-VALUE(LEFT(F19,LEN(TRUNC(F19,0))-LEN(TRUNC(F18,0))))*POWER(10,LEN(TRUNC(F18,0)))))) -> 0.0288 | H19: =IF(G19="","",G19*$H$15) -> 518.4 | I19: =IF(H19="","",IF(D19="","",IF(AND(H19=0,D19=0),0,H19/D19))) -> 0.36687898 | K19: 6.275262 | Q19: (синхронный,
A20: 2-00 | B20: 6528.8563 | C20: =IF(B20="","",IF(LEN(TRUNC(B19,0))-LEN(TRUNC(B20,0))=0,B20-B19,IF(LEN(TRUNC(B19,0))-LEN(TRUNC(B20,0))>0,VALUE(LEFT(B19,LEN(TRUNC(B19,0))-LEN(TRUNC(B20,0))))*POWER(10,LEN(TRUNC(B20,0)))+B20-B19,B20-B19-VALUE(LEFT(B20,LEN(TRUNC(B20,0))-LEN(TRUNC(B19,0))))*POWER(10,LEN(TRUNC(B19,0)))))) -> 0.082 | D20: =IF(C20="","",C20*$D$15) -> 1476 | F20: 2117.9254 | G20: =IF(F20="","",IF(LEN(TRUNC(F19,0))-LEN(TRUNC(F20,0))=0,F20-F19,IF(LEN(TRUNC(F19,0))-LEN(TRUNC(F20,0))>0,VALUE(LEFT(F19,LEN(TRUNC(F19,0))-LEN(TRUNC(F20,0))))*POWER(10,LEN(TRUNC(F20,0)))+F20-F19,F20-F19-VALUE(LEFT(F20,LEN(TRUNC(F20,0))-LEN(TRUNC(F19,0))))*POWER(10,LEN(TRUNC(F19,0)))))) -> 0.0296 | H20: =IF(G20="","",G20*$H$15) -> 532.8 | I20: =IF(H20="","",IF(D20="","",IF(AND(H20=0,D20=0),0,H20/D20))) -> 0.36097561 | K20: 6.415853 | M20: п/п | N20: установки | Q20: асинхронный) | T20: мощность кВт
A21: 3-00 | B21: 6528.9362 | C21: =IF(B21="","",IF(LEN(TRUNC(B20,0))-LEN(TRUNC(B21,0))=0,B21-B20,IF(LEN(TRUNC(B20,0))-LEN(TRUNC(B21,0))>0,VALUE(LEFT(B20,LEN(TRUNC(B20,0))-LEN(TRUNC(B21,0))))*POWER(10,LEN(TRUNC(B21,0)))+B21-B20,B21-B20-VALUE(LEFT(B21,LEN(TRUNC(B21,0))-LEN(TRUNC(B20,0))))*POWER(10,LEN(TRUNC(B20,0)))))) -> 0.0799 | D21: =IF(C21="","",C21*$D$15) -> 1438.2 | F21: 2117.9548 | G21: =IF(F21="","",IF(LEN(TRUNC(F20,0))-LEN(TRUNC(F21,0))=0,F21-F20,IF(LEN(TRUNC(F20,0))-LEN(TRUNC(F21,0))>0,VALUE(LEFT(F20,LEN(TRUNC(F20,0))-LEN(TRUNC(F21,0))))*POWER(10,LEN(TRUNC(F21,0)))+F21-F20,F21-F20-VALUE(LEFT(F21,LEN(TRUNC(F21,0))-LEN(TRUNC(F20,0))))*POWER(10,LEN(TRUNC(F20,0)))))) -> 0.0294 | H21: =IF(G21="","",G21*$H$15) -> 529.2 | I21: =IF(H21="","",IF(D21="","",IF(AND(H21=0,D21=0),0,H21/D21))) -> 0.36795995 | K21: 6.332952
A22: 4-00 | B22: 6529.0152 | C22: =IF(B22="","",IF(LEN(TRUNC(B21,0))-LEN(TRUNC(B22,0))=0,B22-B21,IF(LEN(TRUNC(B21,0))-LEN(TRUNC(B22,0))>0,VALUE(LEFT(B21,LEN(TRUNC(B21,0))-LEN(TRUNC(B22,0))))*POWER(10,LEN(TRUNC(B22,0)))+B22-B21,B22-B21-VALUE(LEFT(B22,LEN(TRUNC(B22,0))-LEN(TRUNC(B21,0))))*POWER(10,LEN(TRUNC(B21,0)))))) -> 0.079 | D22: =IF(C22="","",C22*$D$15) -> 1422 | F22: 2117.9843 | G22: =IF(F22="","",IF(LEN(TRUNC(F21,0))-LEN(TRUNC(F22,0))=0,F22-F21,IF(LEN(TRUNC(F21,0))-LEN(TRUNC(F22,0))>0,VALUE(LEFT(F21,LEN(TRUNC(F21,0))-LEN(TRUNC(F22,0))))*POWER(10,LEN(TRUNC(F22,0)))+F22-F21,F22-F21-VALUE(LEFT(F22,LEN(TRUNC(F22,0))-LEN(TRUNC(F21,0))))*POWER(10,LEN(TRUNC(F21,0)))))) -> 0.0295 | H22: =IF(G22="","",G22*$H$15) -> 531 | I22: =IF(H22="","",IF(D22="","",IF(AND(H22=0,D22=0),0,H22/D22))) -> 0.37341772 | K22: 6.435564
A23: 5-00 | B23: 6529.0938 | C23: =IF(B23="","",IF(LEN(TRUNC(B22,0))-LEN(TRUNC(B23,0))=0,B23-B22,IF(LEN(TRUNC(B22,0))-LEN(TRUNC(B23,0))>0,VALUE(LEFT(B22,LEN(TRUNC(B22,0))-LEN(TRUNC(B23,0))))*POWER(10,LEN(TRUNC(B23,0)))+B23-B22,B23-B22-VALUE(LEFT(B23,LEN(TRUNC(B23,0))-LEN(TRUNC(B22,0))))*POWER(10,LEN(TRUNC(B22,0)))))) -> 0.0786 | D23: =IF(C23="","",C23*$D$15) -> 1414.8 | F23: 2118.0138 | G23: =IF(F23="","",IF(LEN(TRUNC(F22,0))-LEN(TRUNC(F23,0))=0,F23-F22,IF(LEN(TRUNC(F22,0))-LEN(TRUNC(F23,0))>0,VALUE(LEFT(F22,LEN(TRUNC(F22,0))-LEN(TRUNC(F23,0))))*POWER(10,LEN(TRUNC(F23,0)))+F23-F22,F23-F22-VALUE(LEFT(F23,LEN(TRUNC(F23,0))-LEN(TRUNC(F22,0))))*POWER(10,LEN(TRUNC(F22,0)))))) -> 0.0295 | H23: =IF(G23="","",G23*$H$15) -> 531 | I23: =IF(H23="","",IF(D23="","",IF(AND(H23=0,D23=0),0,H23/D23))) -> 0.37531807 | K23: 6.443177
A24: 6-00 | B24: 6529.172 | C24: =IF(B24="","",IF(LEN(TRUNC(B23,0))-LEN(TRUNC(B24,0))=0,B24-B23,IF(LEN(TRUNC(B23,0))-LEN(TRUNC(B24,0))>0,VALUE(LEFT(B23,LEN(TRUNC(B23,0))-LEN(TRUNC(B24,0))))*POWER(10,LEN(TRUNC(B24,0)))+B24-B23,B24-B23-VALUE(LEFT(B24,LEN(TRUNC(B24,0))-LEN(TRUNC(B23,0))))*POWER(10,LEN(TRUNC(B23,0)))))) -> 0.0782 | D24: =IF(C24="","",C24*$D$15) -> 1407.6 | F24: 2118.0427 | G24: =IF(F24="","",IF(LEN(TRUNC(F23,0))-LEN(TRUNC(F24,0))=0,F24-F23,IF(LEN(TRUNC(F23,0))-LEN(TRUNC(F24,0))>0,VALUE(LEFT(F23,LEN(TRUNC(F23,0))-LEN(TRUNC(F24,0))))*POWER(10,LEN(TRUNC(F24,0)))+F24-F23,F24-F23-VALUE(LEFT(F24,LEN(TRUNC(F24,0))-LEN(TRUNC(F23,0))))*POWER(10,LEN(TRUNC(F23,0)))))) -> 0.0289 | H24: =IF(G24="","",G24*$H$15) -> 520.2 | I24: =IF(H24="","",IF(D24="","",IF(AND(H24=0,D24=0),0,H24/D24))) -> 0.36956522 | K24: 6.43589
A25: 7-00 | B25: 6529.2494 | C25: =IF(B25="","",IF(LEN(TRUNC(B24,0))-LEN(TRUNC(B25,0))=0,B25-B24,IF(LEN(TRUNC(B24,0))-LEN(TRUNC(B25,0))>0,VALUE(LEFT(B24,LEN(TRUNC(B24,0))-LEN(TRUNC(B25,0))))*POWER(10,LEN(TRUNC(B25,0)))+B25-B24,B25-B24-VALUE(LEFT(B25,LEN(TRUNC(B25,0))-LEN(TRUNC(B24,0))))*POWER(10,LEN(TRUNC(B24,0)))))) -> 0.0774 | D25: =IF(C25="","",C25*$D$15) -> 1393.2 | F25: 2118.0693 | G25: =IF(F25="","",IF(LEN(TRUNC(F24,0))-LEN(TRUNC(F25,0))=0,F25-F24,IF(LEN(TRUNC(F24,0))-LEN(TRUNC(F25,0))>0,VALUE(LEFT(F24,LEN(TRUNC(F24,0))-LEN(TRUNC(F25,0))))*POWER(10,LEN(TRUNC(F25,0)))+F25-F24,F25-F24-VALUE(LEFT(F25,LEN(TRUNC(F25,0))-LEN(TRUNC(F24,0))))*POWER(10,LEN(TRUNC(F24,0)))))) -> 0.0266 | H25: =IF(G25="","",G25*$H$15) -> 478.8 | I25: =IF(H25="","",IF(D25="","",IF(AND(H25=0,D25=0),0,H25/D25))) -> 0.34366925 | K25: 6.301332
A26: 8-00 | B26: 6529.3305 | C26: =IF(B26="","",IF(LEN(TRUNC(B25,0))-LEN(TRUNC(B26,0))=0,B26-B25,IF(LEN(TRUNC(B25,0))-LEN(TRUNC(B26,0))>0,VALUE(LEFT(B25,LEN(TRUNC(B25,0))-LEN(TRUNC(B26,0))))*POWER(10,LEN(TRUNC(B26,0)))+B26-B25,B26-B25-VALUE(LEFT(B26,LEN(TRUNC(B26,0))-LEN(TRUNC(B25,0))))*POWER(10,LEN(TRUNC(B25,0)))))) -> 0.0811 | D26: =IF(C26="","",C26*$D$15) -> 1459.8 | F26: 2118.0953 | G26: =IF(F26="","",IF(LEN(TRUNC(F25,0))-LEN(TRUNC(F26,0))=0,F26-F25,IF(LEN(TRUNC(F25,0))-LEN(TRUNC(F26,0))>0,VALUE(LEFT(F25,LEN(TRUNC(F25,0))-LEN(TRUNC(F26,0))))*POWER(10,LEN(TRUNC(F26,0)))+F26-F25,F26-F25-VALUE(LEFT(F26,LEN(TRUNC(F26,0))-LEN(TRUNC(F25,0))))*POWER(10,LEN(TRUNC(F25,0)))))) -> 0.026 | H26: =IF(G26="","",G26*$H$15) -> 468 | I26: =IF(H26="","",IF(D26="","",IF(AND(H26=0,D26=0),0,H26/D26))) -> 0.32059186 | K26: 6.383555
A27: 9-00 | B27: 6529.4226 | C27: =IF(B27="","",IF(LEN(TRUNC(B26,0))-LEN(TRUNC(B27,0))=0,B27-B26,IF(LEN(TRUNC(B26,0))-LEN(TRUNC(B27,0))>0,VALUE(LEFT(B26,LEN(TRUNC(B26,0))-LEN(TRUNC(B27,0))))*POWER(10,LEN(TRUNC(B27,0)))+B27-B26,B27-B26-VALUE(LEFT(B27,LEN(TRUNC(B27,0))-LEN(TRUNC(B26,0))))*POWER(10,LEN(TRUNC(B26,0)))))) -> 0.0921 | D27: =IF(C27="","",C27*$D$15) -> 1657.8 | F27: 2118.1304 | G27: =IF(F27="","",IF(LEN(TRUNC(F26,0))-LEN(TRUNC(F27,0))=0,F27-F26,IF(LEN(TRUNC(F26,0))-LEN(TRUNC(F27,0))>0,VALUE(LEFT(F26,LEN(TRUNC(F26,0))-LEN(TRUNC(F27,0))))*POWER(10,LEN(TRUNC(F27,0)))+F27-F26,F27-F26-VALUE(LEFT(F27,LEN(TRUNC(F27,0))-LEN(TRUNC(F26,0))))*POWER(10,LEN(TRUNC(F26,0)))))) -> 0.0351 | H27: =IF(G27="","",G27*$H$15) -> 631.8 | I27: =IF(H27="","",IF(D27="","",IF(AND(H27=0,D27=0),0,H27/D27))) -> 0.38110749 | K27: 6.31399
A28: 10-00 | B28: 6529.5224 | C28: =IF(B28="","",IF(LEN(TRUNC(B27,0))-LEN(TRUNC(B28,0))=0,B28-B27,IF(LEN(TRUNC(B27,0))-LEN(TRUNC(B28,0))>0,VALUE(LEFT(B27,LEN(TRUNC(B27,0))-LEN(TRUNC(B28,0))))*POWER(10,LEN(TRUNC(B28,0)))+B28-B27,B28-B27-VALUE(LEFT(B28,LEN(TRUNC(B28,0))-LEN(TRUNC(B27,0))))*POWER(10,LEN(TRUNC(B27,0)))))) -> 0.0998 | D28: =IF(C28="","",C28*$D$15) -> 1796.4 | F28: 2118.171 | G28: =IF(F28="","",IF(LEN(TRUNC(F27,0))-LEN(TRUNC(F28,0))=0,F28-F27,IF(LEN(TRUNC(F27,0))-LEN(TRUNC(F28,0))>0,VALUE(LEFT(F27,LEN(TRUNC(F27,0))-LEN(TRUNC(F28,0))))*POWER(10,LEN(TRUNC(F28,0)))+F28-F27,F28-F27-VALUE(LEFT(F28,LEN(TRUNC(F28,0))-LEN(TRUNC(F27,0))))*POWER(10,LEN(TRUNC(F27,0)))))) -> 0.0406 | H28: =IF(G28="","",G28*$H$15) -> 730.8 | I28: =IF(H28="","",IF(D28="","",IF(AND(H28=0,D28=0),0,H28/D28))) -> 0.40681363 | K28: 6.287243
A29: 11-00 | B29: 6529.6249 | C29: =IF(B29="","",IF(LEN(TRUNC(B28,0))-LEN(TRUNC(B29,0))=0,B29-B28,IF(LEN(TRUNC(B28,0))-LEN(TRUNC(B29,0))>0,VALUE(LEFT(B28,LEN(TRUNC(B28,0))-LEN(TRUNC(B29,0))))*POWER(10,LEN(TRUNC(B29,0)))+B29-B28,B29-B28-VALUE(LEFT(B29,LEN(TRUNC(B29,0))-LEN(TRUNC(B28,0))))*POWER(10,LEN(TRUNC(B28,0)))))) -> 0.1025 | D29: =IF(C29="","",C29*$D$15) -> 1845 | F29: 2118.215 | G29: =IF(F29="","",IF(LEN(TRUNC(F28,0))-LEN(TRUNC(F29,0))=0,F29-F28,IF(LEN(TRUNC(F28,0))-LEN(TRUNC(F29,0))>0,VALUE(LEFT(F28,LEN(TRUNC(F28,0))-LEN(TRUNC(F29,0))))*POWER(10,LEN(TRUNC(F29,0)))+F29-F28,F29-F28-VALUE(LEFT(F29,LEN(TRUNC(F29,0))-LEN(TRUNC(F28,0))))*POWER(10,LEN(TRUNC(F28,0)))))) -> 0.044 | H29: =IF(G29="","",G29*$H$15) -> 792 | I29: =IF(H29="","",IF(D29="","",IF(AND(H29=0,D29=0),0,H29/D29))) -> 0.42926829 | K29: 6.320937 | M29: Указать отдельно рабочие и запломбированные трансформаторы и высоковольтные электродвигатели
A30: 12-00 | B30: 6529.7242 | C30: =IF(B30="","",IF(LEN(TRUNC(B29,0))-LEN(TRUNC(B30,0))=0,B30-B29,IF(LEN(TRUNC(B29,0))-LEN(TRUNC(B30,0))>0,VALUE(LEFT(B29,LEN(TRUNC(B29,0))-LEN(TRUNC(B30,0))))*POWER(10,LEN(TRUNC(B30,0)))+B30-B29,B30-B29-VALUE(LEFT(B30,LEN(TRUNC(B30,0))-LEN(TRUNC(B29,0))))*POWER(10,LEN(TRUNC(B29,0)))))) -> 0.0993 | D30: =IF(C30="","",C30*$D$15) -> 1787.4 | F30: 2118.2597 | G30: =IF(F30="","",IF(LEN(TRUNC(F29,0))-LEN(TRUNC(F30,0))=0,F30-F29,IF(LEN(TRUNC(F29,0))-LEN(TRUNC(F30,0))>0,VALUE(LEFT(F29,LEN(TRUNC(F29,0))-LEN(TRUNC(F30,0))))*POWER(10,LEN(TRUNC(F30,0)))+F30-F29,F30-F29-VALUE(LEFT(F30,LEN(TRUNC(F30,0))-LEN(TRUNC(F29,0))))*POWER(10,LEN(TRUNC(F29,0)))))) -> 0.0447 | H30: =IF(G30="","",G30*$H$15) -> 804.6 | I30: =IF(H30="","",IF(D30="","",IF(AND(H30=0,D30=0),0,H30/D30))) -> 0.45015106 | K30: 6.344934 | M30: II. Статконденсаторы всех напряжений
A31: 13-00 | B31: 6529.818 | C31: =IF(B31="","",IF(LEN(TRUNC(B30,0))-LEN(TRUNC(B31,0))=0,B31-B30,IF(LEN(TRUNC(B30,0))-LEN(TRUNC(B31,0))>0,VALUE(LEFT(B30,LEN(TRUNC(B30,0))-LEN(TRUNC(B31,0))))*POWER(10,LEN(TRUNC(B31,0)))+B31-B30,B31-B30-VALUE(LEFT(B31,LEN(TRUNC(B31,0))-LEN(TRUNC(B30,0))))*POWER(10,LEN(TRUNC(B30,0)))))) -> 0.0938 | D31: =IF(C31="","",C31*$D$15) -> 1688.4 | F31: 2118.3027 | G31: =IF(F31="","",IF(LEN(TRUNC(F30,0))-LEN(TRUNC(F31,0))=0,F31-F30,IF(LEN(TRUNC(F30,0))-LEN(TRUNC(F31,0))>0,VALUE(LEFT(F30,LEN(TRUNC(F30,0))-LEN(TRUNC(F31,0))))*POWER(10,LEN(TRUNC(F31,0)))+F31-F30,F31-F30-VALUE(LEFT(F31,LEN(TRUNC(F31,0))-LEN(TRUNC(F30,0))))*POWER(10,LEN(TRUNC(F30,0)))))) -> 0.043 | H31: =IF(G31="","",G31*$H$15) -> 774 | I31: =IF(H31="","",IF(D31="","",IF(AND(H31=0,D31=0),0,H31/D31))) -> 0.45842217 | K31: 6.373718 | M31: №№ | N31: Место | P31: Номинальное | R31: Номинальная | T31: В т.ч. с | V31: Время включения | Y31: Примечание
A32: 14-00 | B32: 6529.9173 | C32: =IF(B32="","",IF(LEN(TRUNC(B31,0))-LEN(TRUNC(B32,0))=0,B32-B31,IF(LEN(TRUNC(B31,0))-LEN(TRUNC(B32,0))>0,VALUE(LEFT(B31,LEN(TRUNC(B31,0))-LEN(TRUNC(B32,0))))*POWER(10,LEN(TRUNC(B32,0)))+B32-B31,B32-B31-VALUE(LEFT(B32,LEN(TRUNC(B32,0))-LEN(TRUNC(B31,0))))*POWER(10,LEN(TRUNC(B31,0)))))) -> 0.0993 | D32: =IF(C32="","",C32*$D$15) -> 1787.4 | F32: 2118.3476 | G32: =IF(F32="","",IF(LEN(TRUNC(F31,0))-LEN(TRUNC(F32,0))=0,F32-F31,IF(LEN(TRUNC(F31,0))-LEN(TRUNC(F32,0))>0,VALUE(LEFT(F31,LEN(TRUNC(F31,0))-LEN(TRUNC(F32,0))))*POWER(10,LEN(TRUNC(F32,0)))+F32-F31,F32-F31-VALUE(LEFT(F32,LEN(TRUNC(F32,0))-LEN(TRUNC(F31,0))))*POWER(10,LEN(TRUNC(F31,0)))))) -> 0.0449 | H32: =IF(G32="","",G32*$H$15) -> 808.2 | I32: =IF(H32="","",IF(D32="","",IF(AND(H32=0,D32=0),0,H32/D32))) -> 0.45216516 | K32: 6.346944 | P32: напряжение | R32: мощность | T32: авторегулир. | V32: и отключения
A33: 15-00 | B33: 6530.019 | C33: =IF(B33="","",IF(LEN(TRUNC(B32,0))-LEN(TRUNC(B33,0))=0,B33-B32,IF(LEN(TRUNC(B32,0))-LEN(TRUNC(B33,0))>0,VALUE(LEFT(B32,LEN(TRUNC(B32,0))-LEN(TRUNC(B33,0))))*POWER(10,LEN(TRUNC(B33,0)))+B33-B32,B33-B32-VALUE(LEFT(B33,LEN(TRUNC(B33,0))-LEN(TRUNC(B32,0))))*POWER(10,LEN(TRUNC(B32,0)))))) -> 0.1017 | D33: =IF(C33="","",C33*$D$15) -> 1830.6 | F33: 2118.3938 | G33: =IF(F33="","",IF(LEN(TRUNC(F32,0))-LEN(TRUNC(F33,0))=0,F33-F32,IF(LEN(TRUNC(F32,0))-LEN(TRUNC(F33,0))>0,VALUE(LEFT(F32,LEN(TRUNC(F32,0))-LEN(TRUNC(F33,0))))*POWER(10,LEN(TRUNC(F33,0)))+F33-F32,F33-F32-VALUE(LEFT(F33,LEN(TRUNC(F33,0))-LEN(TRUNC(F32,0))))*POWER(10,LEN(TRUNC(F32,0)))))) -> 0.0462 | H33: =IF(G33="","",G33*$H$15) -> 831.6 | I33: =IF(H33="","",IF(D33="","",IF(AND(H33=0,D33=0),0,H33/D33))) -> 0.45427729 | K33: 6.232457 | M33: п/п | N33: установки | P33: кВ | R33: кВар | T33: кВар | V33: установки за сутки
A34: 16-00 | B34: 6530.1197 | C34: =IF(B34="","",IF(LEN(TRUNC(B33,0))-LEN(TRUNC(B34,0))=0,B34-B33,IF(LEN(TRUNC(B33,0))-LEN(TRUNC(B34,0))>0,VALUE(LEFT(B33,LEN(TRUNC(B33,0))-LEN(TRUNC(B34,0))))*POWER(10,LEN(TRUNC(B34,0)))+B34-B33,B34-B33-VALUE(LEFT(B34,LEN(TRUNC(B34,0))-LEN(TRUNC(B33,0))))*POWER(10,LEN(TRUNC(B33,0)))))) -> 0.1007 | D34: =IF(C34="","",C34*$D$15) -> 1812.6 | F34: 2118.4388 | G34: =IF(F34="","",IF(LEN(TRUNC(F33,0))-LEN(TRUNC(F34,0))=0,F34-F33,IF(LEN(TRUNC(F33,0))-LEN(TRUNC(F34,0))>0,VALUE(LEFT(F33,LEN(TRUNC(F33,0))-LEN(TRUNC(F34,0))))*POWER(10,LEN(TRUNC(F34,0)))+F34-F33,F34-F33-VALUE(LEFT(F34,LEN(TRUNC(F34,0))-LEN(TRUNC(F33,0))))*POWER(10,LEN(TRUNC(F33,0)))))) -> 0.045 | H34: =IF(G34="","",G34*$H$15) -> 810 | I34: =IF(H34="","",IF(D34="","",IF(AND(H34=0,D34=0),0,H34/D34))) -> 0.4468719 | K34: 6.355583
A35: 17-00 | B35: 6530.2135 | C35: =IF(B35="","",IF(LEN(TRUNC(B34,0))-LEN(TRUNC(B35,0))=0,B35-B34,IF(LEN(TRUNC(B34,0))-LEN(TRUNC(B35,0))>0,VALUE(LEFT(B34,LEN(TRUNC(B34,0))-LEN(TRUNC(B35,0))))*POWER(10,LEN(TRUNC(B35,0)))+B35-B34,B35-B34-VALUE(LEFT(B35,LEN(TRUNC(B35,0))-LEN(TRUNC(B34,0))))*POWER(10,LEN(TRUNC(B34,0)))))) -> 0.0938 | D35: =IF(C35="","",C35*$D$15) -> 1688.4 | F35: 2118.4734 | G35: =IF(F35="","",IF(LEN(TRUNC(F34,0))-LEN(TRUNC(F35,0))=0,F35-F34,IF(LEN(TRUNC(F34,0))-LEN(TRUNC(F35,0))>0,VALUE(LEFT(F34,LEN(TRUNC(F34,0))-LEN(TRUNC(F35,0))))*POWER(10,LEN(TRUNC(F35,0)))+F35-F34,F35-F34-VALUE(LEFT(F35,LEN(TRUNC(F35,0))-LEN(TRUNC(F34,0))))*POWER(10,LEN(TRUNC(F34,0)))))) -> 0.0346 | H35: =IF(G35="","",G35*$H$15) -> 622.8 | I35: =IF(H35="","",IF(D35="","",IF(AND(H35=0,D35=0),0,H35/D35))) -> 0.36886994 | K35: 6.277733 | N35: КТП-22,23,24,25 | P35: 0.4 | R35: 696
A36: 18-00 | B36: 6530.2995 | C36: =IF(B36="","",IF(LEN(TRUNC(B35,0))-LEN(TRUNC(B36,0))=0,B36-B35,IF(LEN(TRUNC(B35,0))-LEN(TRUNC(B36,0))>0,VALUE(LEFT(B35,LEN(TRUNC(B35,0))-LEN(TRUNC(B36,0))))*POWER(10,LEN(TRUNC(B36,0)))+B36-B35,B36-B35-VALUE(LEFT(B36,LEN(TRUNC(B36,0))-LEN(TRUNC(B35,0))))*POWER(10,LEN(TRUNC(B35,0)))))) -> 0.086 | D36: =IF(C36="","",C36*$D$15) -> 1548 | F36: 2118.5053 | G36: =IF(F36="","",IF(LEN(TRUNC(F35,0))-LEN(TRUNC(F36,0))=0,F36-F35,IF(LEN(TRUNC(F35,0))-LEN(TRUNC(F36,0))>0,VALUE(LEFT(F35,LEN(TRUNC(F35,0))-LEN(TRUNC(F36,0))))*POWER(10,LEN(TRUNC(F36,0)))+F36-F35,F36-F35-VALUE(LEFT(F36,LEN(TRUNC(F36,0))-LEN(TRUNC(F35,0))))*POWER(10,LEN(TRUNC(F35,0)))))) -> 0.0319 | H36: =IF(G36="","",G36*$H$15) -> 574.2 | I36: =IF(H36="","",IF(D36="","",IF(AND(H36=0,D36=0),0,H36/D36))) -> 0.37093023 | K36: 6.342901 | N36: РП-1 | P36: 6 | R36: 870
A37: 19-00 | B37: 6530.3766 | C37: =IF(B37="","",IF(LEN(TRUNC(B36,0))-LEN(TRUNC(B37,0))=0,B37-B36,IF(LEN(TRUNC(B36,0))-LEN(TRUNC(B37,0))>0,VALUE(LEFT(B36,LEN(TRUNC(B36,0))-LEN(TRUNC(B37,0))))*POWER(10,LEN(TRUNC(B37,0)))+B37-B36,B37-B36-VALUE(LEFT(B37,LEN(TRUNC(B37,0))-LEN(TRUNC(B36,0))))*POWER(10,LEN(TRUNC(B36,0)))))) -> 0.0771 | D37: =IF(C37="","",C37*$D$15) -> 1387.8 | F37: 2118.5285 | G37: =IF(F37="","",IF(LEN(TRUNC(F36,0))-LEN(TRUNC(F37,0))=0,F37-F36,IF(LEN(TRUNC(F36,0))-LEN(TRUNC(F37,0))>0,VALUE(LEFT(F36,LEN(TRUNC(F36,0))-LEN(TRUNC(F37,0))))*POWER(10,LEN(TRUNC(F37,0)))+F37-F36,F37-F36-VALUE(LEFT(F37,LEN(TRUNC(F37,0))-LEN(TRUNC(F36,0))))*POWER(10,LEN(TRUNC(F36,0)))))) -> 0.0232 | H37: =IF(G37="","",G37*$H$15) -> 417.6 | I37: =IF(H37="","",IF(D37="","",IF(AND(H37=0,D37=0),0,H37/D37))) -> 0.30090791 | K37: 6.291354
A38: 20-00 | B38: 6530.4517 | C38: =IF(B38="","",IF(LEN(TRUNC(B37,0))-LEN(TRUNC(B38,0))=0,B38-B37,IF(LEN(TRUNC(B37,0))-LEN(TRUNC(B38,0))>0,VALUE(LEFT(B37,LEN(TRUNC(B37,0))-LEN(TRUNC(B38,0))))*POWER(10,LEN(TRUNC(B38,0)))+B38-B37,B38-B37-VALUE(LEFT(B38,LEN(TRUNC(B38,0))-LEN(TRUNC(B37,0))))*POWER(10,LEN(TRUNC(B37,0)))))) -> 0.0751 | D38: =IF(C38="","",C38*$D$15) -> 1351.8 | F38: 2118.5486 | G38: =IF(F38="","",IF(LEN(TRUNC(F37,0))-LEN(TRUNC(F38,0))=0,F38-F37,IF(LEN(TRUNC(F37,0))-LEN(TRUNC(F38,0))>0,VALUE(LEFT(F37,LEN(TRUNC(F37,0))-LEN(TRUNC(F38,0))))*POWER(10,LEN(TRUNC(F38,0)))+F38-F37,F38-F37-VALUE(LEFT(F38,LEN(TRUNC(F38,0))-LEN(TRUNC(F37,0))))*POWER(10,LEN(TRUNC(F37,0)))))) -> 0.0201 | H38: =IF(G38="","",G38*$H$15) -> 361.8 | I38: =IF(H38="","",IF(D38="","",IF(AND(H38=0,D38=0),0,H38/D38))) -> 0.26764314 | K38: 6.321241
A39: 21-00 | B39: 6530.5277 | C39: =IF(B39="","",IF(LEN(TRUNC(B38,0))-LEN(TRUNC(B39,0))=0,B39-B38,IF(LEN(TRUNC(B38,0))-LEN(TRUNC(B39,0))>0,VALUE(LEFT(B38,LEN(TRUNC(B38,0))-LEN(TRUNC(B39,0))))*POWER(10,LEN(TRUNC(B39,0)))+B39-B38,B39-B38-VALUE(LEFT(B39,LEN(TRUNC(B39,0))-LEN(TRUNC(B38,0))))*POWER(10,LEN(TRUNC(B38,0)))))) -> 0.076 | D39: =IF(C39="","",C39*$D$15) -> 1368 | F39: 2118.5709 | G39: =IF(F39="","",IF(LEN(TRUNC(F38,0))-LEN(TRUNC(F39,0))=0,F39-F38,IF(LEN(TRUNC(F38,0))-LEN(TRUNC(F39,0))>0,VALUE(LEFT(F38,LEN(TRUNC(F38,0))-LEN(TRUNC(F39,0))))*POWER(10,LEN(TRUNC(F39,0)))+F39-F38,F39-F38-VALUE(LEFT(F39,LEN(TRUNC(F39,0))-LEN(TRUNC(F38,0))))*POWER(10,LEN(TRUNC(F38,0)))))) -> 0.0223 | H39: =IF(G39="","",G39*$H$15) -> 401.4 | I39: =IF(H39="","",IF(D39="","",IF(AND(H39=0,D39=0),0,H39/D39))) -> 0.29342105 | K39: 6.344234
A40: 22-00 | B40: 6530.6029 | C40: =IF(B40="","",IF(LEN(TRUNC(B39,0))-LEN(TRUNC(B40,0))=0,B40-B39,IF(LEN(TRUNC(B39,0))-LEN(TRUNC(B40,0))>0,VALUE(LEFT(B39,LEN(TRUNC(B39,0))-LEN(TRUNC(B40,0))))*POWER(10,LEN(TRUNC(B40,0)))+B40-B39,B40-B39-VALUE(LEFT(B40,LEN(TRUNC(B40,0))-LEN(TRUNC(B39,0))))*POWER(10,LEN(TRUNC(B39,0)))))) -> 0.0752 | D40: =IF(C40="","",C40*$D$15) -> 1353.6 | F40: 2118.5929 | G40: =IF(F40="","",IF(LEN(TRUNC(F39,0))-LEN(TRUNC(F40,0))=0,F40-F39,IF(LEN(TRUNC(F39,0))-LEN(TRUNC(F40,0))>0,VALUE(LEFT(F39,LEN(TRUNC(F39,0))-LEN(TRUNC(F40,0))))*POWER(10,LEN(TRUNC(F40,0)))+F40-F39,F40-F39-VALUE(LEFT(F40,LEN(TRUNC(F40,0))-LEN(TRUNC(F39,0))))*POWER(10,LEN(TRUNC(F39,0)))))) -> 0.022 | H40: =IF(G40="","",G40*$H$15) -> 396 | I40: =IF(H40="","",IF(D40="","",IF(AND(H40=0,D40=0),0,H40/D40))) -> 0.29255319 | K40: 6.364006 | M40: III. Синхронные электродвигатели напряжением до 1000 В
A41: 23-00 | B41: 6530.6819 | C41: =IF(B41="","",IF(LEN(TRUNC(B40,0))-LEN(TRUNC(B41,0))=0,B41-B40,IF(LEN(TRUNC(B40,0))-LEN(TRUNC(B41,0))>0,VALUE(LEFT(B40,LEN(TRUNC(B40,0))-LEN(TRUNC(B41,0))))*POWER(10,LEN(TRUNC(B41,0)))+B41-B40,B41-B40-VALUE(LEFT(B41,LEN(TRUNC(B41,0))-LEN(TRUNC(B40,0))))*POWER(10,LEN(TRUNC(B40,0)))))) -> 0.079 | D41: =IF(C41="","",C41*$D$15) -> 1422 | F41: 2118.6173 | G41: =IF(F41="","",IF(LEN(TRUNC(F40,0))-LEN(TRUNC(F41,0))=0,F41-F40,IF(LEN(TRUNC(F40,0))-LEN(TRUNC(F41,0))>0,VALUE(LEFT(F40,LEN(TRUNC(F40,0))-LEN(TRUNC(F41,0))))*POWER(10,LEN(TRUNC(F41,0)))+F41-F40,F41-F40-VALUE(LEFT(F41,LEN(TRUNC(F41,0))-LEN(TRUNC(F40,0))))*POWER(10,LEN(TRUNC(F40,0)))))) -> 0.0244 | H41: =IF(G41="","",G41*$H$15) -> 439.2 | I41: =IF(H41="","",IF(D41="","",IF(AND(H41=0,D41=0),0,H41/D41))) -> 0.30886076 | K41: 6.400516 | M41: №№ | N41: Место | P41: Номинальная | S41: № п-п | T41: Место установки | X41: Номинальная
A42: 24-00 | B42: 6530.7593 | C42: =IF(B42="","",IF(LEN(TRUNC(B41,0))-LEN(TRUNC(B42,0))=0,B42-B41,IF(LEN(TRUNC(B41,0))-LEN(TRUNC(B42,0))>0,VALUE(LEFT(B41,LEN(TRUNC(B41,0))-LEN(TRUNC(B42,0))))*POWER(10,LEN(TRUNC(B42,0)))+B42-B41,B42-B41-VALUE(LEFT(B42,LEN(TRUNC(B42,0))-LEN(TRUNC(B41,0))))*POWER(10,LEN(TRUNC(B41,0)))))) -> 0.0774 | D42: =IF(C42="","",C42*$D$15) -> 1393.2 | F42: 2118.642 | G42: =IF(F42="","",IF(LEN(TRUNC(F41,0))-LEN(TRUNC(F42,0))=0,F42-F41,IF(LEN(TRUNC(F41,0))-LEN(TRUNC(F42,0))>0,VALUE(LEFT(F41,LEN(TRUNC(F41,0))-LEN(TRUNC(F42,0))))*POWER(10,LEN(TRUNC(F42,0)))+F42-F41,F42-F41-VALUE(LEFT(F42,LEN(TRUNC(F42,0))-LEN(TRUNC(F41,0))))*POWER(10,LEN(TRUNC(F41,0)))))) -> 0.0247 | H42: =IF(G42="","",G42*$H$15) -> 444.6 | I42: =IF(H42="","",IF(D42="","",IF(AND(H42=0,D42=0),0,H42/D42))) -> 0.31912145 | K42: 6.412046
...

Sheet Ячейка 2
A1: ОАО "Пластик" | G1: Шифр | M1: I. Сведения о присоединенных трансформаторах и высоковольтных электродвигателях
A2: (наименование предприятия) | M2: 1. Трансформаторы
A3: г. Узловая, Тульская, 1 | G3: Питающий центр | I3: П/ст №167 (ГПП-1) | M3: №№ | N3: Место установки | P3: Мощность | R3: Номинальн. | T3: Включен. | V3: Назначение | X3: Примечание
A4: (адрес) | R4: напряжение | T4: на ответвление | V4: тр-ра
G5: № фидера | I5: яч 2 тр-р №2 | M5: п/п | P5: ква | R5: ________ кВ | T5: ________ кВ | V5: силов. освет.
A6: (министерство, ведомство) | V6: печной
A8: ПРОТОКОЛ (первичный)
A9: записей показания электросчетчиков и вольтметров, а также определение
A10: нагрузок и тангенса "фи" за | E10: 20 декабря | H10: 2017года
A11: напряжения | E11: _______6000_____________ | I11: вольт
A13: Время записи часы | B13: Активн. сч-к тип | D13: СЭТ-4ТМ.03М | F13: Реактивн. сч-к тип | H13: СЭТ-4ТМ.03М | I13: Тангенс "фи" | J13: Показание | L13: Мощность
B14: ____________л__ | D14: №0808090590 | F14: ____________л__ | H14: №0808090590 | J14: вольтметр. | L14: включен.
B15: Расчетн. коэф | D15: 18000 | F15: Расчетн. коэф | H15: 18000 | J15: на стороне | L15: компенсир.
B16: показ. | C16: разность | D16: расход за | F16: показ. | G16: разность | H16: расход за | J16: в\н | K16: н\н | L16: устройств
B17: сч-ка | C17: показ. | D17: час (кВт) | F17: сч-ка | G17: показ. | H17: час (кВт) | L17: кВар | M17: 2. Высоковольтные электродвигатели
A18: 0-00 | B18: 14969.41 | F18: 7520.7948 | M18: №№ | N18: Место | Q18: Тип | T18: Номинальная | W18: Примечание
A19: 1-00 | B19: 14969.569 | C19: =IF(B19="","",IF(LEN(TRUNC(B18,0))-LEN(TRUNC(B19,0))=0,B19-B18,IF(LEN(TRUNC(B18,0))-LEN(TRUNC(B19,0))>0,VALUE(LEFT(B18,LEN(TRUNC(B18,0))-LEN(TRUNC(B19,0))))*POWER(10,LEN(TRUNC(B19,0)))+B19-B18,B19-B18-VALUE(LEFT(B19,LEN(TRUNC(B19,0))-LEN(TRUNC(B18,0))))*POWER(10,LEN(TRUNC(B18,0)))))) -> 0.1586 | D19: =IF(C19="","",C19*$D$15) -> 2854.8 | F19: 7520.8658 | G19: =IF(F19="","",IF(LEN(TRUNC(F18,0))-LEN(TRUNC(F19,0))=0,F19-F18,IF(LEN(TRUNC(F18,0))-LEN(TRUNC(F19,0))>0,VALUE(LEFT(F18,LEN(TRUNC(F18,0))-LEN(TRUNC(F19,0))))*POWER(10,LEN(TRUNC(F19,0)))+F19-F18,F19-F18-VALUE(LEFT(F19,LEN(TRUNC(F19,0))-LEN(TRUNC(F18,0))))*POWER(10,LEN(TRUNC(F18,0)))))) -> 0.071 | H19: =IF(G19="","",G19*$H$15) -> 1278 | I19: =IF(H19="","",IF(D19="","",IF(AND(H19=0,D19=0),0,H19/D19))) -> 0.44766709 | K19: 6.402756 | Q19: (синхронный,
A20: 2-00 | B20: 14969.719 | C20: =IF(B20="","",IF(LEN(TRUNC(B19,0))-LEN(TRUNC(B20,0))=0,B20-B19,IF(LEN(TRUNC(B19,0))-LEN(TRUNC(B20,0))>0,VALUE(LEFT(B19,LEN(TRUNC(B19,0))-LEN(TRUNC(B20,0))))*POWER(10,LEN(TRUNC(B20,0)))+B20-B19,B20-B19-VALUE(LEFT(B20,LEN(TRUNC(B20,0))-LEN(TRUNC(B19,0))))*POWER(10,LEN(TRUNC(B19,0)))))) -> 0.1502 | D20: =IF(C20="","",C20*$D$15) -> 2703.6 | F20: 7520.9345 | G20: =IF(F20="","",IF(LEN(TRUNC(F19,0))-LEN(TRUNC(F20,0))=0,F20-F19,IF(LEN(TRUNC(F19,0))-LEN(TRUNC(F20,0))>0,VALUE(LEFT(F19,LEN(TRUNC(F19,0))-LEN(TRUNC(F20,0))))*POWER(10,LEN(TRUNC(F20,0)))+F20-F19,F20-F19-VALUE(LEFT(F20,LEN(TRUNC(F20,0))-LEN(TRUNC(F19,0))))*POWER(10,LEN(TRUNC(F19,0)))))) -> 0.0687 | H20: =IF(G20="","",G20*$H$15) -> 1236.6 | I20: =IF(H20="","",IF(D20="","",IF(AND(H20=0,D20=0),0,H20/D20))) -> 0.45739015 | K20: 6.401501 | M20: п/п | N20: установки | Q20: асинхронный) | T20: мощность кВт
A21: 3-00 | B21: 14969.867 | C21: =IF(B21="","",IF(LEN(TRUNC(B20,0))-LEN(TRUNC(B21,0))=0,B21-B20,IF(LEN(TRUNC(B20,0))-LEN(TRUNC(B21,0))>0,VALUE(LEFT(B20,LEN(TRUNC(B20,0))-LEN(TRUNC(B21,0))))*POWER(10,LEN(TRUNC(B21,0)))+B21-B20,B21-B20-VALUE(LEFT(B21,LEN(TRUNC(B21,0))-LEN(TRUNC(B20,0))))*POWER(10,LEN(TRUNC(B20,0)))))) -> 0.148 | D21: =IF(C21="","",C21*$D$15) -> 2664 | F21: 7521.0027 | G21: =IF(F21="","",IF(LEN(TRUNC(F20,0))-LEN(TRUNC(F21,0))=0,F21-F20,IF(LEN(TRUNC(F20,0))-LEN(TRUNC(F21,0))>0,VALUE(LEFT(F20,LEN(TRUNC(F20,0))-LEN(TRUNC(F21,0))))*POWER(10,LEN(TRUNC(F21,0)))+F21-F20,F21-F20-VALUE(LEFT(F21,LEN(TRUNC(F21,0))-LEN(TRUNC(F20,0))))*POWER(10,LEN(TRUNC(F20,0)))))) -> 0.0682 | H21: =IF(G21="","",G21*$H$15) -> 1227.6 | I21: =IF(H21="","",IF(D21="","",IF(AND(H21=0,D21=0),0,H21/D21))) -> 0.46081081 | K21: 6.405905
A22: 4-00 | B22: 14970.022 | C22: =IF(B22="","",IF(LEN(TRUNC(B21,0))-LEN(TRUNC(B22,0))=0,B22-B21,IF(LEN(TRUNC(B21,0))-LEN(TRUNC(B22,0))>0,VALUE(LEFT(B21,LEN(TRUNC(B21,0))-LEN(TRUNC(B22,0))))*POWER(10,LEN(TRUNC(B22,0)))+B22-B21,B22-B21-VALUE(LEFT(B22,LEN(TRUNC(B22,0))-LEN(TRUNC(B21,0))))*POWER(10,LEN(TRUNC(B21,0)))))) -> 0.1547 | D22: =IF(C22="","",C22*$D$15) -> 2784.6 | F22: 7521.0754 | G22: =IF(F22="","",IF(LEN(TRUNC(F21,0))-LEN(TRUNC(F22,0))=0,F22-F21,IF(LEN(TRUNC(F21,0))-LEN(TRUNC(F22,0))>0,VALUE(LEFT(F21,LEN(TRUNC(F21,0))-LEN(TRUNC(F22,0))))*POWER(10,LEN(TRUNC(F22,0)))+F22-F21,F22-F21-VALUE(LEFT(F22,LEN(TRUNC(F22,0))-LEN(TRUNC(F21,0))))*POWER(10,LEN(TRUNC(F21,0)))))) -> 0.0727 | H22: =IF(G22="","",G22*$H$15) -> 1308.6 | I22: =IF(H22="","",IF(D22="","",IF(AND(H22=0,D22=0),0,H22/D22))) -> 0.46994182 | K22: 6.417461
A23: 5-00 | B23: 14970.177 | C23: =IF(B23="","",IF(LEN(TRUNC(B22,0))-LEN(TRUNC(B23,0))=0,B23-B22,IF(LEN(TRUNC(B22,0))-LEN(TRUNC(B23,0))>0,VALUE(LEFT(B22,LEN(TRUNC(B22,0))-LEN(TRUNC(B23,0))))*POWER(10,LEN(TRUNC(B23,0)))+B23-B22,B23-B22-VALUE(LEFT(B23,LEN(TRUNC(B23,0))-LEN(TRUNC(B22,0))))*POWER(10,LEN(TRUNC(B22,0)))))) -> 0.1555 | D23: =IF(C23="","",C23*$D$15) -> 2799 | F23: 7521.1504 | G23: =IF(F23="","",IF(LEN(TRUNC(F22,0))-LEN(TRUNC(F23,0))=0,F23-F22,IF(LEN(TRUNC(F22,0))-LEN(TRUNC(F23,0))>0,VALUE(LEFT(F22,LEN(TRUNC(F22,0))-LEN(TRUNC(F23,0))))*POWER(10,LEN(TRUNC(F23,0)))+F23-F22,F23-F22-VALUE(LEFT(F23,LEN(TRUNC(F23,0))-LEN(TRUNC(F22,0))))*POWER(10,LEN(TRUNC(F22,0)))))) -> 0.075 | H23: =IF(G23="","",G23*$H$15) -> 1350 | I23: =IF(H23="","",IF(D23="","",IF(AND(H23=0,D23=0),0,H23/D23))) -> 0.48231511 | K23: 6.423085
A24: 6-00 | B24: 14970.334 | C24: =IF(B24="","",IF(LEN(TRUNC(B23,0))-LEN(TRUNC(B24,0))=0,B24-B23,IF(LEN(TRUNC(B23,0))-LEN(TRUNC(B24,0))>0,VALUE(LEFT(B23,LEN(TRUNC(B23,0))-LEN(TRUNC(B24,0))))*POWER(10,LEN(TRUNC(B24,0)))+B24-B23,B24-B23-VALUE(LEFT(B24,LEN(TRUNC(B24,0))-LEN(TRUNC(B23,0))))*POWER(10,LEN(TRUNC(B23,0)))))) -> 0.1569 | D24: =IF(C24="","",C24*$D$15) -> 2824.2 | F24: 7521.2236 | G24: =IF(F24="","",IF(LEN(TRUNC(F23,0))-LEN(TRUNC(F24,0))=0,F24-F23,IF(LEN(TRUNC(F23,0))-LEN(TRUNC(F24,0))>0,VALUE(LEFT(F23,LEN(TRUNC(F23,0))-LEN(TRUNC(F24,0))))*POWER(10,LEN(TRUNC(F24,0)))+F24-F23,F24-F23-VALUE(LEFT(F24,LEN(TRUNC(F24,0))-LEN(TRUNC(F23,0))))*POWER(10,LEN(TRUNC(F23,0)))))) -> 0.0732 | H24: =IF(G24="","",G24*$H$15) -> 1317.6 | I24: =IF(H24="","",IF(D24="","",IF(AND(H24=0,D24=0),0,H24/D24))) -> 0.4665392 | K24: 6.416529
A25: 7-00 | B25: 14970.496 | C25: =IF(B25="","",IF(LEN(TRUNC(B24,0))-LEN(TRUNC(B25,0))=0,B25-B24,IF(LEN(TRUNC(B24,0))-LEN(TRUNC(B25,0))>0,VALUE(LEFT(B24,LEN(TRUNC(B24,0))-LEN(TRUNC(B25,0))))*POWER(10,LEN(TRUNC(B25,0)))+B25-B24,B25-B24-VALUE(LEFT(B25,LEN(TRUNC(B25,0))-LEN(TRUNC(B24,0))))*POWER(10,LEN(TRUNC(B24,0)))))) -> 0.1622 | D25: =IF(C25="","",C25*$D$15) -> 2919.6 | F25: 7521.2955 | G25: =IF(F25="","",IF(LEN(TRUNC(F24,0))-LEN(TRUNC(F25,0))=0,F25-F24,IF(LEN(TRUNC(F24,0))-LEN(TRUNC(F25,0))>0,VALUE(LEFT(F24,LEN(TRUNC(F24,0))-LEN(TRUNC(F25,0))))*POWER(10,LEN(TRUNC(F25,0)))+F25-F24,F25-F24-VALUE(LEFT(F25,LEN(TRUNC(F25,0))-LEN(TRUNC(F24,0))))*POWER(10,LEN(TRUNC(F24,0)))))) -> 0.0719 | H25: =IF(G25="","",G25*$H$15) -> 1294.2 | I25: =IF(H25="","",IF(D25="","",IF(AND(H25=0,D25=0),0,H25/D25))) -> 0.4432799 | K25: 6.384053
A26: 8-00 | B26: 14970.669 | C26: =IF(B26="","",IF(LEN(TRUNC(B25,0))-LEN(TRUNC(B26,0))=0,B26-B25,IF(LEN(TRUNC(B25,0))-LEN(TRUNC(B26,0))>0,VALUE(LEFT(B25,LEN(TRUNC(B25,0))-LEN(TRUNC(B26,0))))*POWER(10,LEN(TRUNC(B26,0)))+B26-B25,B26-B25-VALUE(LEFT(B26,LEN(TRUNC(B26,0))-LEN(TRUNC(B25,0))))*POWER(10,LEN(TRUNC(B25,0)))))) -> 0.1729 | D26: =IF(C26="","",C26*$D$15) -> 3112.2 | F26: 7521.3677 | G26: =IF(F26="","",IF(LEN(TRUNC(F25,0))-LEN(TRUNC(F26,0))=0,F26-F25,IF(LEN(TRUNC(F25,0))-LEN(TRUNC(F26,0))>0,VALUE(LEFT(F25,LEN(TRUNC(F25,0))-LEN(TRUNC(F26,0))))*POWER(10,LEN(TRUNC(F26,0)))+F26-F25,F26-F25-VALUE(LEFT(F26,LEN(TRUNC(F26,0))-LEN(TRUNC(F25,0))))*POWER(10,LEN(TRUNC(F25,0)))))) -> 0.0722 | H26: =IF(G26="","",G26*$H$15) -> 1299.6 | I26: =IF(H26="","",IF(D26="","",IF(AND(H26=0,D26=0),0,H26/D26))) -> 0.41758242 | K26: 6.217087
A27: 9-00 | B27: 14970.85 | C27: =IF(B27="","",IF(LEN(TRUNC(B26,0))-LEN(TRUNC(B27,0))=0,B27-B26,IF(LEN(TRUNC(B26,0))-LEN(TRUNC(B27,0))>0,VALUE(LEFT(B26,LEN(TRUNC(B26,0))-LEN(TRUNC(B27,0))))*POWER(10,LEN(TRUNC(B27,0)))+B27-B26,B27-B26-VALUE(LEFT(B27,LEN(TRUNC(B27,0))-LEN(TRUNC(B26,0))))*POWER(10,LEN(TRUNC(B26,0)))))) -> 0.1811 | D27: =IF(C27="","",C27*$D$15) -> 3259.8 | F27: 7521.4409 | G27: =IF(F27="","",IF(LEN(TRUNC(F26,0))-LEN(TRUNC(F27,0))=0,F27-F26,IF(LEN(TRUNC(F26,0))-LEN(TRUNC(F27,0))>0,VALUE(LEFT(F26,LEN(TRUNC(F26,0))-LEN(TRUNC(F27,0))))*POWER(10,LEN(TRUNC(F27,0)))+F27-F26,F27-F26-VALUE(LEFT(F27,LEN(TRUNC(F27,0))-LEN(TRUNC(F26,0))))*POWER(10,LEN(TRUNC(F26,0)))))) -> 0.0732 | H27: =IF(G27="","",G27*$H$15) -> 1317.6 | I27: =IF(H27="","",IF(D27="","",IF(AND(H27=0,D27=0),0,H27/D27))) -> 0.40419658 | K27: 6.093546
A28: 10-00 | B28: 14971.043 | C28: =IF(B28="","",IF(LEN(TRUNC(B27,0))-LEN(TRUNC(B28,0))=0,B28-B27,IF(LEN(TRUNC(B27,0))-LEN(TRUNC(B28,0))>0,VALUE(LEFT(B27,LEN(TRUNC(B27,0))-LEN(TRUNC(B28,0))))*POWER(10,LEN(TRUNC(B28,0)))+B28-B27,B28-B27-VALUE(LEFT(B28,LEN(TRUNC(B28,0))-LEN(TRUNC(B27,0))))*POWER(10,LEN(TRUNC(B27,0)))))) -> 0.1927 | D28: =IF(C28="","",C28*$D$15) -> 3468.6 | F28: 7521.5195 | G28: =IF(F28="","",IF(LEN(TRUNC(F27,0))-LEN(TRUNC(F28,0))=0,F28-F27,IF(LEN(TRUNC(F27,0))-LEN(TRUNC(F28,0))>0,VALUE(LEFT(F27,LEN(TRUNC(F27,0))-LEN(TRUNC(F28,0))))*POWER(10,LEN(TRUNC(F28,0)))+F28-F27,F28-F27-VALUE(LEFT(F28,LEN(TRUNC(F28,0))-LEN(TRUNC(F27,0))))*POWER(10,LEN(TRUNC(F27,0)))))) -> 0.0786 | H28: =IF(G28="","",G28*$H$15) -> 1414.8 | I28: =IF(H28="","",IF(D28="","",IF(AND(H28=0,D28=0),0,H28/D28))) -> 0.40788791 | K28: 6.145785
A29: 11-00 | B29: 14971.229 | C29: =IF(B29="","",IF(LEN(TRUNC(B28,0))-LEN(TRUNC(B29,0))=0,B29-B28,IF(LEN(TRUNC(B28,0))-LEN(TRUNC(B29,0))>0,VALUE(LEFT(B28,LEN(TRUNC(B28,0))-LEN(TRUNC(B29,0))))*POWER(10,LEN(TRUNC(B29,0)))+B29-B28,B29-B28-VALUE(LEFT(B29,LEN(TRUNC(B29,0))-LEN(TRUNC(B28,0))))*POWER(10,LEN(TRUNC(B28,0)))))) -> 0.1857 | D29: =IF(C29="","",C29*$D$15) -> 3342.6 | F29: 7521.596 | G29: =IF(F29="","",IF(LEN(TRUNC(F28,0))-LEN(TRUNC(F29,0))=0,F29-F28,IF(LEN(TRUNC(F28,0))-LEN(TRUNC(F29,0))>0,VALUE(LEFT(F28,LEN(TRUNC(F28,0))-LEN(TRUNC(F29,0))))*POWER(10,LEN(TRUNC(F29,0)))+F29-F28,F29-F28-VALUE(LEFT(F29,LEN(TRUNC(F29,0))-LEN(TRUNC(F28,0))))*POWER(10,LEN(TRUNC(F28,0)))))) -> 0.0765 | H29: =IF(G29="","",G29*$H$15) -> 1377 | I29: =IF(H29="","",IF(D29="","",IF(AND(H29=0,D29=0),0,H29/D29))) -> 0.41195477 | K29: 6.10347 | M29: Указать отдельно рабочие и запломбированные трансформаторы и высоковольтные электродвигатели
A30: 12-00 | B30: 14971.413 | C30: =IF(B30="","",IF(LEN(TRUNC(B29,0))-LEN(TRUNC(B30,0))=0,B30-B29,IF(LEN(TRUNC(B29,0))-LEN(TRUNC(B30,0))>0,VALUE(LEFT(B29,LEN(TRUNC(B29,0))-LEN(TRUNC(B30,0))))*POWER(10,LEN(TRUNC(B30,0)))+B30-B29,B30-B29-VALUE(LEFT(B30,LEN(TRUNC(B30,0))-LEN(TRUNC(B29,0))))*POWER(10,LEN(TRUNC(B29,0)))))) -> 0.1839 | D30: =IF(C30="","",C30*$D$15) -> 3310.2 | F30: 7521.6727 | G30: =IF(F30="","",IF(LEN(TRUNC(F29,0))-LEN(TRUNC(F30,0))=0,F30-F29,IF(LEN(TRUNC(F29,0))-LEN(TRUNC(F30,0))>0,VALUE(LEFT(F29,LEN(TRUNC(F29,0))-LEN(TRUNC(F30,0))))*POWER(10,LEN(TRUNC(F30,0)))+F30-F29,F30-F29-VALUE(LEFT(F30,LEN(TRUNC(F30,0))-LEN(TRUNC(F29,0))))*POWER(10,LEN(TRUNC(F29,0)))))) -> 0.0767 | H30: =IF(G30="","",G30*$H$15) -> 1380.6 | I30: =IF(H30="","",IF(D30="","",IF(AND(H30=0,D30=0),0,H30/D30))) -> 0.4170745 | K30: 6.33539 | M30: II. Статконденсаторы всех напряжений
A31: 13-00 | B31: 14971.592 | C31: =IF(B31="","",IF(LEN(TRUNC(B30,0))-LEN(TRUNC(B31,0))=0,B31-B30,IF(LEN(TRUNC(B30,0))-LEN(TRUNC(B31,0))>0,VALUE(LEFT(B30,LEN(TRUNC(B30,0))-LEN(TRUNC(B31,0))))*POWER(10,LEN(TRUNC(B31,0)))+B31-B30,B31-B30-VALUE(LEFT(B31,LEN(TRUNC(B31,0))-LEN(TRUNC(B30,0))))*POWER(10,LEN(TRUNC(B30,0)))))) -> 0.1793 | D31: =IF(C31="","",C31*$D$15) -> 3227.4 | F31: 7521.7471 | G31: =IF(F31="","",IF(LEN(TRUNC(F30,0))-LEN(TRUNC(F31,0))=0,F31-F30,IF(LEN(TRUNC(F30,0))-LEN(TRUNC(F31,0))>0,VALUE(LEFT(F30,LEN(TRUNC(F30,0))-LEN(TRUNC(F31,0))))*POWER(10,LEN(TRUNC(F31,0)))+F31-F30,F31-F30-VALUE(LEFT(F31,LEN(TRUNC(F31,0))-LEN(TRUNC(F30,0))))*POWER(10,LEN(TRUNC(F30,0)))))) -> 0.0744 | H31: =IF(G31="","",G31*$H$15) -> 1339.2 | I31: =IF(H31="","",IF(D31="","",IF(AND(H31=0,D31=0),0,H31/D31))) -> 0.41494702 | K31: 6.363932 | M31: №№ | N31: Место | P31: Номинальное | R31: Номинальная | T31: В т.ч. с | V31: Время включения | Y31: Примечание
A32: 14-00 | B32: 14971.777 | C32: =IF(B32="","",IF(LEN(TRUNC(B31,0))-LEN(TRUNC(B32,0))=0,B32-B31,IF(LEN(TRUNC(B31,0))-LEN(TRUNC(B32,0))>0,VALUE(LEFT(B31,LEN(TRUNC(B31,0))-LEN(TRUNC(B32,0))))*POWER(10,LEN(TRUNC(B32,0)))+B32-B31,B32-B31-VALUE(LEFT(B32,LEN(TRUNC(B32,0))-LEN(TRUNC(B31,0))))*POWER(10,LEN(TRUNC(B31,0)))))) -> 0.1847 | D32: =IF(C32="","",C32*$D$15) -> 3324.6 | F32: 7521.8286 | G32: =IF(F32="","",IF(LEN(TRUNC(F31,0))-LEN(TRUNC(F32,0))=0,F32-F31,IF(LEN(TRUNC(F31,0))-LEN(TRUNC(F32,0))>0,VALUE(LEFT(F31,LEN(TRUNC(F31,0))-LEN(TRUNC(F32,0))))*POWER(10,LEN(TRUNC(F32,0)))+F32-F31,F32-F31-VALUE(LEFT(F32,LEN(TRUNC(F32,0))-LEN(TRUNC(F31,0))))*POWER(10,LEN(TRUNC(F31,0)))))) -> 0.0815 | H32: =IF(G32="","",G32*$H$15) -> 1467 | I32: =IF(H32="","",IF(D32="","",IF(AND(H32=0,D32=0),0,H32/D32))) -> 0.44125609 | K32: 6.332851 | P32: напряжение | R32: мощность | T32: авторегулир. | V32: и отключения
A33: 15-00 | B33: 14971.958 | C33: =IF(B33="","",IF(LEN(TRUNC(B32,0))-LEN(TRUNC(B33,0))=0,B33-B32,IF(LEN(TRUNC(B32,0))-LEN(TRUNC(B33,0))>0,VALUE(LEFT(B32,LEN(TRUNC(B32,0))-LEN(TRUNC(B33,0))))*POWER(10,LEN(TRUNC(B33,0)))+B33-B32,B33-B32-VALUE(LEFT(B33,LEN(TRUNC(B33,0))-LEN(TRUNC(B32,0))))*POWER(10,LEN(TRUNC(B32,0)))))) -> 0.1815 | D33: =IF(C33="","",C33*$D$15) -> 3267 | F33: 7521.9093 | G33: =IF(F33="","",IF(LEN(TRUNC(F32,0))-LEN(TRUNC(F33,0))=0,F33-F32,IF(LEN(TRUNC(F32,0))-LEN(TRUNC(F33,0))>0,VALUE(LEFT(F32,LEN(TRUNC(F32,0))-LEN(TRUNC(F33,0))))*POWER(10,LEN(TRUNC(F33,0)))+F33-F32,F33-F32-VALUE(LEFT(F33,LEN(TRUNC(F33,0))-LEN(TRUNC(F32,0))))*POWER(10,LEN(TRUNC(F32,0)))))) -> 0.0807 | H33: =IF(G33="","",G33*$H$15) -> 1452.6 | I33: =IF(H33="","",IF(D33="","",IF(AND(H33=0,D33=0),0,H33/D33))) -> 0.4446281 | K33: 6.327693 | M33: п/п | N33: установки | P33: кВ | R33: кВар | T33: кВар | V33: установки за сутки
A34: 16-00 | B34: 14972.14 | C34: =IF(B34="","",IF(LEN(TRUNC(B33,0))-LEN(TRUNC(B34,0))=0,B34-B33,IF(LEN(TRUNC(B33,0))-LEN(TRUNC(B34,0))>0,VALUE(LEFT(B33,LEN(TRUNC(B33,0))-LEN(TRUNC(B34,0))))*POWER(10,LEN(TRUNC(B34,0)))+B34-B33,B34-B33-VALUE(LEFT(B34,LEN(TRUNC(B34,0))-LEN(TRUNC(B33,0))))*POWER(10,LEN(TRUNC(B33,0)))))) -> 0.1823 | D34: =IF(C34="","",C34*$D$15) -> 3281.4 | F34: 7521.9911 | G34: =IF(F34="","",IF(LEN(TRUNC(F33,0))-LEN(TRUNC(F34,0))=0,F34-F33,IF(LEN(TRUNC(F33,0))-LEN(TRUNC(F34,0))>0,VALUE(LEFT(F33,LEN(TRUNC(F33,0))-LEN(TRUNC(F34,0))))*POWER(10,LEN(TRUNC(F34,0)))+F34-F33,F34-F33-VALUE(LEFT(F34,LEN(TRUNC(F34,0))-LEN(TRUNC(F33,0))))*POWER(10,LEN(TRUNC(F33,0)))))) -> 0.0818 | H34: =IF(G34="","",G34*$H$15) -> 1472.4 | I34: =IF(H34="","",IF(D34="","",IF(AND(H34=0,D34=0),0,H34/D34))) -> 0.44871092 | K34: 6.341585
A35: 17-00 | B35: 14972.321 | C35: =IF(B35="","",IF(LEN(TRUNC(B34,0))-LEN(TRUNC(B35,0))=0,B35-B34,IF(LEN(TRUNC(B34,0))-LEN(TRUNC(B35,0))>0,VALUE(LEFT(B34,LEN(TRUNC(B34,0))-LEN(TRUNC(B35,0))))*POWER(10,LEN(TRUNC(B35,0)))+B35-B34,B35-B34-VALUE(LEFT(B35,LEN(TRUNC(B35,0))-LEN(TRUNC(B34,0))))*POWER(10,LEN(TRUNC(B34,0)))))) -> 0.1804 | D35: =IF(C35="","",C35*$D$15) -> 3247.2 | F35: 7522.0692 | G35: =IF(F35="","",IF(LEN(TRUNC(F34,0))-LEN(TRUNC(F35,0))=0,F35-F34,IF(LEN(TRUNC(F34,0))-LEN(TRUNC(F35,0))>0,VALUE(LEFT(F34,LEN(TRUNC(F34,0))-LEN(TRUNC(F35,0))))*POWER(10,LEN(TRUNC(F35,0)))+F35-F34,F35-F34-VALUE(LEFT(F35,LEN(TRUNC(F35,0))-LEN(TRUNC(F34,0))))*POWER(10,LEN(TRUNC(F34,0)))))) -> 0.0781 | H35: =IF(G35="","",G35*$H$15) -> 1405.8 | I35: =IF(H35="","",IF(D35="","",IF(AND(H35=0,D35=0),0,H35/D35))) -> 0.43292683 | K35: 6.331864 | N35: КТП-22,23,24,25 | P35: 0.4 | R35: 696
A36: 18-00 | B36: 14972.501 | C36: =IF(B36="","",IF(LEN(TRUNC(B35,0))-LEN(TRUNC(B36,0))=0,B36-B35,IF(LEN(TRUNC(B35,0))-LEN(TRUNC(B36,0))>0,VALUE(LEFT(B35,LEN(TRUNC(B35,0))-LEN(TRUNC(B36,0))))*POWER(10,LEN(TRUNC(B36,0)))+B36-B35,B36-B35-VALUE(LEFT(B36,LEN(TRUNC(B36,0))-LEN(TRUNC(B35,0))))*POWER(10,LEN(TRUNC(B35,0)))))) -> 0.1803 | D36: =IF(C36="","",C36*$D$15) -> 3245.4 | F36: 7522.1456 | G36: =IF(F36="","",IF(LEN(TRUNC(F35,0))-LEN(TRUNC(F36,0))=0,F36-F35,IF(LEN(TRUNC(F35,0))-LEN(TRUNC(F36,0))>0,VALUE(LEFT(F35,LEN(TRUNC(F35,0))-LEN(TRUNC(F36,0))))*POWER(10,LEN(TRUNC(F36,0)))+F36-F35,F36-F35-VALUE(LEFT(F36,LEN(TRUNC(F36,0))-LEN(TRUNC(F35,0))))*POWER(10,LEN(TRUNC(F35,0)))))) -> 0.0764 | H36: =IF(G36="","",G36*$H$15) -> 1375.2 | I36: =IF(H36="","",IF(D36="","",IF(AND(H36=0,D36=0),0,H36/D36))) -> 0.42373821 | K36: 6.240767 | N36: РП-1 | P36: 6 | R36: 870
A37: 19-00 | B37: 14972.678 | C37: =IF(B37="","",IF(LEN(TRUNC(B36,0))-LEN(TRUNC(B37,0))=0,B37-B36,IF(LEN(TRUNC(B36,0))-LEN(TRUNC(B37,0))>0,VALUE(LEFT(B36,LEN(TRUNC(B36,0))-LEN(TRUNC(B37,0))))*POWER(10,LEN(TRUNC(B37,0)))+B37-B36,B37-B36-VALUE(LEFT(B37,LEN(TRUNC(B37,0))-LEN(TRUNC(B36,0))))*POWER(10,LEN(TRUNC(B36,0)))))) -> 0.1772 | D37: =IF(C37="","",C37*$D$15) -> 3189.6 | F37: 7522.2172 | G37: =IF(F37="","",IF(LEN(TRUNC(F36,0))-LEN(TRUNC(F37,0))=0,F37-F36,IF(LEN(TRUNC(F36,0))-LEN(TRUNC(F37,0))>0,VALUE(LEFT(F36,LEN(TRUNC(F36,0))-LEN(TRUNC(F37,0))))*POWER(10,LEN(TRUNC(F37,0)))+F37-F36,F37-F36-VALUE(LEFT(F37,LEN(TRUNC(F37,0))-LEN(TRUNC(F36,0))))*POWER(10,LEN(TRUNC(F36,0)))))) -> 0.0716 | H37: =IF(G37="","",G37*$H$15) -> 1288.8 | I37: =IF(H37="","",IF(D37="","",IF(AND(H37=0,D37=0),0,H37/D37))) -> 0.40406321 | K37: 6.265226
A38: 20-00 | B38: 14972.864 | C38: =IF(B38="","",IF(LEN(TRUNC(B37,0))-LEN(TRUNC(B38,0))=0,B38-B37,IF(LEN(TRUNC(B37,0))-LEN(TRUNC(B38,0))>0,VALUE(LEFT(B37,LEN(TRUNC(B37,0))-LEN(TRUNC(B38,0))))*POWER(10,LEN(TRUNC(B38,0)))+B38-B37,B38-B37-VALUE(LEFT(B38,LEN(TRUNC(B38,0))-LEN(TRUNC(B37,0))))*POWER(10,LEN(TRUNC(B37,0)))))) -> 0.1862 | D38: =IF(C38="","",C38*$D$15) -> 3351.6 | F38: 7522.2894 | G38: =IF(F38="","",IF(LEN(TRUNC(F37,0))-LEN(TRUNC(F38,0))=0,F38-F37,IF(LEN(TRUNC(F37,0))-LEN(TRUNC(F38,0))>0,VALUE(LEFT(F37,LEN(TRUNC(F37,0))-LEN(TRUNC(F38,0))))*POWER(10,LEN(TRUNC(F38,0)))+F38-F37,F38-F37-VALUE(LEFT(F38,LEN(TRUNC(F38,0))-LEN(TRUNC(F37,0))))*POWER(10,LEN(TRUNC(F37,0)))))) -> 0.0722 | H38: =IF(G38="","",G38*$H$15) -> 1299.6 | I38: =IF(H38="","",IF(D38="","",IF(AND(H38=0,D38=0),0,H38/D38))) -> 0.3877551 | K38: 6.182233
A39: 21-00 | B39: 14973.045 | C39: =IF(B39="","",IF(LEN(TRUNC(B38,0))-LEN(TRUNC(B39,0))=0,B39-B38,IF(LEN(TRUNC(B38,0))-LEN(TRUNC(B39,0))>0,VALUE(LEFT(B38,LEN(TRUNC(B38,0))-LEN(TRUNC(B39,0))))*POWER(10,LEN(TRUNC(B39,0)))+B39-B38,B39-B38-VALUE(LEFT(B39,LEN(TRUNC(B39,0))-LEN(TRUNC(B38,0))))*POWER(10,LEN(TRUNC(B38,0)))))) -> 0.1809 | D39: =IF(C39="","",C39*$D$15) -> 3256.2 | F39: 7522.3624 | G39: =IF(F39="","",IF(LEN(TRUNC(F38,0))-LEN(TRUNC(F39,0))=0,F39-F38,IF(LEN(TRUNC(F38,0))-LEN(TRUNC(F39,0))>0,VALUE(LEFT(F38,LEN(TRUNC(F38,0))-LEN(TRUNC(F39,0))))*POWER(10,LEN(TRUNC(F39,0)))+F39-F38,F39-F38-VALUE(LEFT(F39,LEN(TRUNC(F39,0))-LEN(TRUNC(F38,0))))*POWER(10,LEN(TRUNC(F38,0)))))) -> 0.073 | H39: =IF(G39="","",G39*$H$15) -> 1314 | I39: =IF(H39="","",IF(D39="","",IF(AND(H39=0,D39=0),0,H39/D39))) -> 0.40353787 | K39: 6.234414
A40: 22-00 | B40: 14973.225 | C40: =IF(B40="","",IF(LEN(TRUNC(B39,0))-LEN(TRUNC(B40,0))=0,B40-B39,IF(LEN(TRUNC(B39,0))-LEN(TRUNC(B40,0))>0,VALUE(LEFT(B39,LEN(TRUNC(B39,0))-LEN(TRUNC(B40,0))))*POWER(10,LEN(TRUNC(B40,0)))+B40-B39,B40-B39-VALUE(LEFT(B40,LEN(TRUNC(B40,0))-LEN(TRUNC(B39,0))))*POWER(10,LEN(TRUNC(B39,0)))))) -> 0.1799 | D40: =IF(C40="","",C40*$D$15) -> 3238.2 | F40: 7522.4368 | G40: =IF(F40="","",IF(LEN(TRUNC(F39,0))-LEN(TRUNC(F40,0))=0,F40-F39,IF(LEN(TRUNC(F39,0))-LEN(TRUNC(F40,0))>0,VALUE(LEFT(F39,LEN(TRUNC(F39,0))-LEN(TRUNC(F40,0))))*POWER(10,LEN(TRUNC(F40,0)))+F40-F39,F40-F39-VALUE(LEFT(F40,LEN(TRUNC(F40,0))-LEN(TRUNC(F39,0))))*POWER(10,LEN(TRUNC(F39,0)))))) -> 0.0744 | H40: =IF(G40="","",G40*$H$15) -> 1339.2 | I40: =IF(H40="","",IF(D40="","",IF(AND(H40=0,D40=0),0,H40/D40))) -> 0.41356309 | K40: 6.153194 | M40: III. Синхронные электродвигатели напряжением до 1000 В
A41: 23-00 | B41: 14973.4 | C41: =IF(B41="","",IF(LEN(TRUNC(B40,0))-LEN(TRUNC(B41,0))=0,B41-B40,IF(LEN(TRUNC(B40,0))-LEN(TRUNC(B41,0))>0,VALUE(LEFT(B40,LEN(TRUNC(B40,0))-LEN(TRUNC(B41,0))))*POWER(10,LEN(TRUNC(B41,0)))+B41-B40,B41-B40-VALUE(LEFT(B41,LEN(TRUNC(B41,0))-LEN(TRUNC(B40,0))))*POWER(10,LEN(TRUNC(B40,0)))))) -> 0.1743 | D41: =IF(C41="","",C41*$D$15) -> 3137.4 | F41: 7522.5129 | G41: =IF(F41="","",IF(LEN(TRUNC(F40,0))-LEN(TRUNC(F41,0))=0,F41-F40,IF(LEN(TRUNC(F40,0))-LEN(TRUNC(F41,0))>0,VALUE(LEFT(F40,LEN(TRUNC(F40,0))-LEN(TRUNC(F41,0))))*POWER(10,LEN(TRUNC(F41,0)))+F41-F40,F41-F40-VALUE(LEFT(F41,LEN(TRUNC(F41,0))-LEN(TRUNC(F40,0))))*POWER(10,LEN(TRUNC(F40,0)))))) -> 0.0761 | H41: =IF(G41="","",G41*$H$15) -> 1369.8 | I41: =IF(H41="","",IF(D41="","",IF(AND(H41=0,D41=0),0,H41/D41))) -> 0.43660356 | K41: 6.372995 | M41: №№ | N41: Место | P41: Номинальная | S41: № п-п | T41: Место установки | X41: Номинальная
A42: 24-00 | B42: 14973.565 | C42: =IF(B42="","",IF(LEN(TRUNC(B41,0))-LEN(TRUNC(B42,0))=0,B42-B41,IF(LEN(TRUNC(B41,0))-LEN(TRUNC(B42,0))>0,VALUE(LEFT(B41,LEN(TRUNC(B41,0))-LEN(TRUNC(B42,0))))*POWER(10,LEN(TRUNC(B42,0)))+B42-B41,B42-B41-VALUE(LEFT(B42,LEN(TRUNC(B42,0))-LEN(TRUNC(B41,0))))*POWER(10,LEN(TRUNC(B41,0)))))) -> 0.1653 | D42: =IF(C42="","",C42*$D$15) -> 2975.4 | F42: 7522.5873 | G42: =IF(F42="","",IF(LEN(TRUNC(F41,0))-LEN(TRUNC(F42,0))=0,F42-F41,IF(LEN(TRUNC(F41,0))-LEN(TRUNC(F42,0))>0,VALUE(LEFT(F41,LEN(TRUNC(F41,0))-LEN(TRUNC(F42,0))))*POWER(10,LEN(TRUNC(F42,0)))+F42-F41,F42-F41-VALUE(LEFT(F42,LEN(TRUNC(F42,0))-LEN(TRUNC(F41,0))))*POWER(10,LEN(TRUNC(F41,0)))))) -> 0.0744 | H42: =IF(G42="","",G42*$H$15) -> 1339.2 | I42: =IF(H42="","",IF(D42="","",IF(AND(H42=0,D42=0),0,H42/D42))) -> 0.45009074 | K42: 6.386526
...

Sheet Ячейка 3
A1: ОАО "Пластик" | G1: Шифр | M1: I. Сведения о присоединенных трансформаторах и высоковольтных электродвигателях
A2: (наименование предприятия) | M2: 1. Трансформаторы
A3: г. Узловая, Тульская, 1 | G3: Питающий центр | I3: П/ст №214 (ГПП-2) | M3: №№ | N3: Место установки | P3: Мощность | R3: Номинальн. | T3: Включен. | V3: Назначение | X3: Примечание
A4: (адрес) | R4: напряжение | T4: на ответвление | V4: тр-ра
G5: № фидера | I5: яч 3 тр-р №1 | M5: п/п | P5: ква | R5: ________ кВ | T5: ________ кВ | V5: силов. освет.
A6: (министерство, ведомство) | V6: печной
A8: ПРОТОКОЛ (первичный)
A9: записей показания электросчетчиков и вольтметров, а также определение
A10: нагрузок и тангенса "фи" за | E10: 20 декабря | H10: 2017года
A11: напряжения | E11: _________6000____________ | I11: вольт
A13: Время записи часы | B13: Активн. сч-к тип | D13: СЭТ-4ТМ.03 | F13: Реактивн. сч-к тип | H13: СЭТ-4ТМ.03 | I13: Тангенс "фи" | J13: Показание | L13: Мощность
B14: ____________л__ | D14: №0103062007 | F14: ____________л__ | H14: №0103062007 | J14: вольтметр. | L14: включен.
B15: Расчетн. коэф | D15: 36000 | F15: Расчетн. коэф | H15: 36000 | J15: на стороне | L15: компенсир.
B16: показ. | C16: разность | D16: расход за | F16: показ. | G16: разность | H16: расход за | J16: в\н | K16: н\н | L16: устройств
B17: сч-ка | C17: показ. | D17: час (кВт) | F17: сч-ка | G17: показ. | H17: час (кВт) | L17: кВар | M17: 2. Высоковольтные электродвигатели
A18: 0-00 | B18: 3589.1975 | F18: 2437.6984 | M18: №№ | N18: Место | Q18: Тип | T18: Номинальная | W18: Примечание
A19: 1-00 | B19: 3589.2378 | C19: =IF(B19="","",IF(LEN(TRUNC(B18,0))-LEN(TRUNC(B19,0))=0,B19-B18,IF(LEN(TRUNC(B18,0))-LEN(TRUNC(B19,0))>0,VALUE(LEFT(B18,LEN(TRUNC(B18,0))-LEN(TRUNC(B19,0))))*POWER(10,LEN(TRUNC(B19,0)))+B19-B18,B19-B18-VALUE(LEFT(B19,LEN(TRUNC(B19,0))-LEN(TRUNC(B18,0))))*POWER(10,LEN(TRUNC(B18,0)))))) -> 0.0403 | D19: =IF(C19="","",C19*$D$15) -> 1450.8 | F19: 2437.726 | G19: =F19-ReportObject9_3 -> 0.0276 | H19: =IF(G19="","",G19*$H$15) -> 993.6 | I19: =IF(H19="","",IF(D19="","",IF(AND(H19=0,D19=0),0,H19/D19))) -> 0.68486352 | K19: 6.34385 | Q19: (синхронный,
A20: 2-00 | B20: 3589.2779 | C20: =IF(B20="","",IF(LEN(TRUNC(B19,0))-LEN(TRUNC(B20,0))=0,B20-B19,IF(LEN(TRUNC(B19,0))-LEN(TRUNC(B20,0))>0,VALUE(LEFT(B19,LEN(TRUNC(B19,0))-LEN(TRUNC(B20,0))))*POWER(10,LEN(TRUNC(B20,0)))+B20-B19,B20-B19-VALUE(LEFT(B20,LEN(TRUNC(B20,0))-LEN(TRUNC(B19,0))))*POWER(10,LEN(TRUNC(B19,0)))))) -> 0.0401 | D20: =IF(C20="","",C20*$D$15) -> 1443.6 | F20: 2437.7535 | G20: =F20-F19 -> 0.0275 | H20: =IF(G20="","",G20*$H$15) -> 990 | I20: =IF(H20="","",IF(D20="","",IF(AND(H20=0,D20=0),0,H20/D20))) -> 0.68578554 | K20: 6.136908 | M20: п/п | N20: установки | Q20: асинхронный) | T20: мощность кВт
A21: 3-00 | B21: 3589.3186 | C21: =IF(B21="","",IF(LEN(TRUNC(B20,0))-LEN(TRUNC(B21,0))=0,B21-B20,IF(LEN(TRUNC(B20,0))-LEN(TRUNC(B21,0))>0,VALUE(LEFT(B20,LEN(TRUNC(B20,0))-LEN(TRUNC(B21,0))))*POWER(10,LEN(TRUNC(B21,0)))+B21-B20,B21-B20-VALUE(LEFT(B21,LEN(TRUNC(B21,0))-LEN(TRUNC(B20,0))))*POWER(10,LEN(TRUNC(B20,0)))))) -> 0.0407 | D21: =IF(C21="","",C21*$D$15) -> 1465.2 | F21: 2437.7813 | G21: =F21-F20 -> 0.0278 | H21: =IF(G21="","",G21*$H$15) -> 1000.8 | I21: =IF(H21="","",IF(D21="","",IF(AND(H21=0,D21=0),0,H21/D21))) -> 0.68304668 | K21: 6.343235
A22: 4-00 | B22: 3589.3586 | C22: =IF(B22="","",IF(LEN(TRUNC(B21,0))-LEN(TRUNC(B22,0))=0,B22-B21,IF(LEN(TRUNC(B21,0))-LEN(TRUNC(B22,0))>0,VALUE(LEFT(B21,LEN(TRUNC(B21,0))-LEN(TRUNC(B22,0))))*POWER(10,LEN(TRUNC(B22,0)))+B22-B21,B22-B21-VALUE(LEFT(B22,LEN(TRUNC(B22,0))-LEN(TRUNC(B21,0))))*POWER(10,LEN(TRUNC(B21,0)))))) -> 0.04 | D22: =IF(C22="","",C22*$D$15) -> 1440 | F22: 2437.8088 | G22: =F22-F21 -> 0.0275 | H22: =IF(G22="","",G22*$H$15) -> 990 | I22: =IF(H22="","",IF(D22="","",IF(AND(H22=0,D22=0),0,H22/D22))) -> 0.6875 | K22: 6.358594
A23: 5-00 | B23: 3589.3979 | C23: =IF(B23="","",IF(LEN(TRUNC(B22,0))-LEN(TRUNC(B23,0))=0,B23-B22,IF(LEN(TRUNC(B22,0))-LEN(TRUNC(B23,0))>0,VALUE(LEFT(B22,LEN(TRUNC(B22,0))-LEN(TRUNC(B23,0))))*POWER(10,LEN(TRUNC(B23,0)))+B23-B22,B23-B22-VALUE(LEFT(B23,LEN(TRUNC(B23,0))-LEN(TRUNC(B22,0))))*POWER(10,LEN(TRUNC(B22,0)))))) -> 0.0393 | D23: =IF(C23="","",C23*$D$15) -> 1414.8 | F23: 2437.8359 | G23: =F23-F22 -> 0.0271 | H23: =IF(G23="","",G23*$H$15) -> 975.6 | I23: =IF(H23="","",IF(D23="","",IF(AND(H23=0,D23=0),0,H23/D23))) -> 0.68956743 | K23: 6.366836
A24: 6-00 | B24: 3589.4371 | C24: =IF(B24="","",IF(LEN(TRUNC(B23,0))-LEN(TRUNC(B24,0))=0,B24-B23,IF(LEN(TRUNC(B23,0))-LEN(TRUNC(B24,0))>0,VALUE(LEFT(B23,LEN(TRUNC(B23,0))-LEN(TRUNC(B24,0))))*POWER(10,LEN(TRUNC(B24,0)))+B24-B23,B24-B23-VALUE(LEFT(B24,LEN(TRUNC(B24,0))-LEN(TRUNC(B23,0))))*POWER(10,LEN(TRUNC(B23,0)))))) -> 0.0392 | D24: =IF(C24="","",C24*$D$15) -> 1411.2 | F24: 2437.8629 | G24: =F24-F23 -> 0.027 | H24: =IF(G24="","",G24*$H$15) -> 972 | I24: =IF(H24="","",IF(D24="","",IF(AND(H24=0,D24=0),0,H24/D24))) -> 0.68877551 | K24: 6.261262
A25: 7-00 | B25: 3589.4767 | C25: =IF(B25="","",IF(LEN(TRUNC(B24,0))-LEN(TRUNC(B25,0))=0,B25-B24,IF(LEN(TRUNC(B24,0))-LEN(TRUNC(B25,0))>0,VALUE(LEFT(B24,LEN(TRUNC(B24,0))-LEN(TRUNC(B25,0))))*POWER(10,LEN(TRUNC(B25,0)))+B25-B24,B25-B24-VALUE(LEFT(B25,LEN(TRUNC(B25,0))-LEN(TRUNC(B24,0))))*POWER(10,LEN(TRUNC(B24,0)))))) -> 0.0396 | D25: =IF(C25="","",C25*$D$15) -> 1425.6 | F25: 2437.8898 | G25: =F25-F24 -> 0.0269 | H25: =IF(G25="","",G25*$H$15) -> 968.4 | I25: =IF(H25="","",IF(D25="","",IF(AND(H25=0,D25=0),0,H25/D25))) -> 0.67929293 | K25: 6.326325
A26: 8-00 | B26: 3589.5191 | C26: =IF(B26="","",IF(LEN(TRUNC(B25,0))-LEN(TRUNC(B26,0))=0,B26-B25,IF(LEN(TRUNC(B25,0))-LEN(TRUNC(B26,0))>0,VALUE(LEFT(B25,LEN(TRUNC(B25,0))-LEN(TRUNC(B26,0))))*POWER(10,LEN(TRUNC(B26,0)))+B26-B25,B26-B25-VALUE(LEFT(B26,LEN(TRUNC(B26,0))-LEN(TRUNC(B25,0))))*POWER(10,LEN(TRUNC(B25,0)))))) -> 0.0424 | D26: =IF(C26="","",C26*$D$15) -> 1526.4 | F26: 2437.9178 | G26: =F26-F25 -> 0.028 | H26: =IF(G26="","",G26*$H$15) -> 1008 | I26: =IF(H26="","",IF(D26="","",IF(AND(H26=0,D26=0),0,H26/D26))) -> 0.66037736 | K26: 6.302521
A27: 9-00 | B27: 3589.5671 | C27: =IF(B27="","",IF(LEN(TRUNC(B26,0))-LEN(TRUNC(B27,0))=0,B27-B26,IF(LEN(TRUNC(B26,0))-LEN(TRUNC(B27,0))>0,VALUE(LEFT(B26,LEN(TRUNC(B26,0))-LEN(TRUNC(B27,0))))*POWER(10,LEN(TRUNC(B27,0)))+B27-B26,B27-B26-VALUE(LEFT(B27,LEN(TRUNC(B27,0))-LEN(TRUNC(B26,0))))*POWER(10,LEN(TRUNC(B26,0)))))) -> 0.048 | D27: =IF(C27="","",C27*$D$15) -> 1728 | F27: 2437.9497 | G27: =F27-F26 -> 0.0319 | H27: =IF(G27="","",G27*$H$15) -> 1148.4 | I27: =IF(H27="","",IF(D27="","",IF(AND(H27=0,D27=0),0,H27/D27))) -> 0.66458333 | K27: 6.235003
