Workbook
Name ReportObject1_0: 'Ячейка 24'!$E$10
Name ReportObject1_1: 'Ячейка 24'!$H$10
Name ReportObject1_2: 'Ячейка 24'!$B$18
Name ReportObject1_3: 'Ячейка 24'!$F$18
Name ReportObject10_0: 'Ячейка 4'!$E$10
Name ReportObject10_1: 'Ячейка 4'!$H$10
Name ReportObject10_2: 'Ячейка 4'!$B$18
Name ReportObject10_3: 'Ячейка 4'!$F$18
Name ReportObject11_0: 'Ячейка 36'!$E$10
Name ReportObject11_1: 'Ячейка 36'!$H$10
Name ReportObject11_2: 'Ячейка 36'!$B$18
Name ReportObject11_3: 'Ячейка 36'!$F$18
Name ReportObject12_0: 'Ячейка 37'!$E$10
Name ReportObject12_1: 'Ячейка 37'!$H$10
Name ReportObject12_2: 'Ячейка 37'!$B$18
Name ReportObject12_3: 'Ячейка 37'!$F$18
Name ReportObject13_0: 'Ячейка 10'!$E$10
Name ReportObject13_1: 'Ячейка 10'!$H$10
Name ReportObject13_2: 'Ячейка 10'!$B$18
Name ReportObject13_3: 'Ячейка 10'!$F$18
Name ReportObject14_0: 'Ячейка 16'!$E$10
Name ReportObject14_1: 'Ячейка 16'!$H$10
Name ReportObject14_2: 'Ячейка 16'!$B$18
Name ReportObject14_3: 'Ячейка 16'!$F$18
Name ReportObject15_0: 'Ячейка 14 '!$E$10
Name ReportObject15_1: 'Ячейка 14 '!$H$10
Name ReportObject15_2: 'Ячейка 14 '!$B$18
Name ReportObject15_3: 'Ячейка 14 '!$F$18
Name ReportObject16_0: 'Ячейка 13БОС'!$E$10
Name ReportObject16_1: 'Ячейка 13БОС'!$H$10
Name ReportObject16_2: 'Ячейка 13БОС'!$B$18
Name ReportObject16_3: 'Ячейка 13БОС'!$F$18
Name ReportObject17_0: 'Ячейка 32БОС'!$E$10
Name ReportObject17_1: 'Ячейка 32БОС'!$H$10
Name ReportObject17_2: 'Ячейка 32БОС'!$B$18
Name ReportObject17_3: 'Ячейка 32БОС'!$F$18
Name ReportObject18_0: 'ячейка 25БОС'!$E$10
Name ReportObject18_1: 'ячейка 25БОС'!$H$10
Name ReportObject18_2: 'ячейка 25БОС'!$B$18
Name ReportObject18_3: 'ячейка 25БОС'!$F$18
Name ReportObject2_0: 'Ячейка 2'!$E$10
Name ReportObject2_1: 'Ячейка 2'!$H$10
Name ReportObject2_2: 'Ячейка 2'!$B$18
Name ReportObject2_3: 'Ячейка 2'!$F$18
Name ReportObject3_0: 'Ячейка 30'!$E$10
Name ReportObject3_1: 'Ячейка 30'!$H$10
Name ReportObject3_2: 'Ячейка 30'!$B$18
Name ReportObject3_3: 'Ячейка 30'!$F$18
Name ReportObject4_0: 'Ячейка 27'!$E$10
Name ReportObject4_1: 'Ячейка 27'!$H$10
Name ReportObject4_2: 'Ячейка 27'!$B$18
Name ReportObject4_3: 'Ячейка 27'!$F$18
Name ReportObject5_0: 'Ячейка 3Гео'!$E$10
Name ReportObject5_1: 'Ячейка 3Гео'!$H$10
Name ReportObject5_2: 'Ячейка 3Гео'!$B$18
Name ReportObject5_3: 'Ячейка 3Гео'!$F$18
Name ReportObject6_0: 'Ячейка 26Гео '!$E$10
Name ReportObject6_1: 'Ячейка 26Гео '!$H$10
Name ReportObject6_2: 'Ячейка 26Гео '!$B$18
Name ReportObject6_3: 'Ячейка 26Гео '!$F$18

Sheet ObserverReportInfo_&!()$bbQ
A1: Режимный день
A2: TYPE2 | B2: HOUR | C2: 25 | D2: 1 | E2: H | F2: 1 | G2: MAIN | K2: EXCEL | M2: 4 | W2: 1
A3: MAINSHEET | B3: 2
A4: DATE | B4: 10 | C4: 5 | D4: dd mmmm | F4: BEGIN | O4: NOSHIFT
A5: DATE | B5: 10 | C5: 8 | D5: yyyy года | F5: BEGIN | O5: NOSHIFT
A6: COLUMN | B6: 18 | C6: 2 | E6: 692 | G6: RESNONE | J6: NONE | K6: CHN | M6: BEGINVALUE | N6: 0 | O6: 480 | P6: 4 | T6: ZONENAMES | Z6: RESULT_CAPTIONS | AF6: -1 | AG6: 0 | AO6: NOSHIFT | AT6: 0 | AV6: 61 | AW6: NOCHANGE | BC6: CUTDATEBEGIN | BI6: 4 | BJ6: 0 | BK6: 0 | BL6: 1 | BM6: 0
A7: COLUMN | B7: 18 | C7: 6 | E7: 694 | G7: RESNONE | J7: NONE | K7: CHN | M7: BEGINVALUE | N7: 0 | O7: 480 | P7: 4 | T7: ZONENAMES | Z7: RESULT_CAPTIONS | AF7: -1 | AG7: 0 | AO7: NOSHIFT | AT7: 0 | AV7: 95 | AW7: NOCHANGE | BC7: CUTDATEBEGIN | BE7: ENLIKEPOW | BI7: 8 | BJ7: 0 | BK7: 0 | BL7: 1 | BM7: 0
A8: MAINSHEET | B8: 3
A9: DATE | B9: 10 | C9: 5 | D9: dd mmmm | F9: BEGIN | O9: NOSHIFT
A10: DATE | B10: 10 | C10: 8 | D10: yyyy года | F10: BEGIN | O10: NOSHIFT
A11: COLUMN | B11: 18 | C11: 2 | E11: 687 | G11: RESNONE | J11: NONE | K11: CHN | M11: BEGINVALUE | N11: 0 | O11: 483 | P11: 4 | T11: ZONENAMES | Z11: RESULT_CAPTIONS | AF11: -1 | AG11: 0 | AO11: NOSHIFT | AT11: 0 | AV11: 61 | AW11: NOCHANGE | BC11: CUTDATEBEGIN | BI11: 4 | BJ11: 0 | BK11: 0 | BL11: 1 | BM11: 0
A12: COLUMN | B12: 18 | C12: 6 | E12: 689 | G12: RESNONE | J12: NONE | K12: CHN | M12: BEGINVALUE | N12: 0 | O12: 483 | P12: 4 | T12: ZONENAMES | Z12: RESULT_CAPTIONS | AF12: -1 | AG12: 0 | AO12: NOSHIFT | AT12: 0 | AV12: 95 | AW12: NOCHANGE | BC12: CUTDATEBEGIN | BE12: ENLIKEPOW | BI12: 8 | BJ12: 0 | BK12: 0 | BL12: 1 | BM12: 0
A13: MAINSHEET | B13: 4
A14: DATE | B14: 10 | C14: 5 | D14: dd mmmm | F14: BEGIN | O14: NOSHIFT
A15: DATE | B15: 10 | C15: 8 | D15: yyyy года | F15: BEGIN | O15: NOSHIFT
A16: COLUMN | B16: 18 | C16: 2 | E16: 702 | G16: RESNONE | J16: NONE | K16: CHN | M16: BEGINVALUE | N16: 0 | O16: 484 | P16: 4 | T16: ZONENAMES | Z16: RESULT_CAPTIONS | AF16: -1 | AG16: 0 | AO16: NOSHIFT | AT16: 0 | AV16: 61 | AW16: NOCHANGE | BC16: CUTDATEBEGIN | BI16: 4 | BJ16: 0 | BK16: 0 | BL16: 1 | BM16: 0
A17: COLUMN | B17: 18 | C17: 6 | E17: 704 | G17: RESNONE | J17: NONE | K17: CHN | M17: BEGINVALUE | N17: 0 | O17: 484 | P17: 4 | T17: ZONENAMES | Z17: RESULT_CAPTIONS | AF17: -1 | AG17: 0 | AO17: NOSHIFT | AT17: 0 | AV17: 95 | AW17: NOCHANGE | BC17: CUTDATEBEGIN | BE17: ENLIKEPOW | BI17: 8 | BJ17: 0 | BK17: 0 | BL17: 1 | BM17: 0
A18: MAINSHEET | B18: 5
A19: DATE | B19: 10 | C19: 5 | D19: dd mmmm | F19: BEGIN | O19: NOSHIFT
A20: DATE | B20: 10 | C20: 8 | D20: yyyy года | F20: BEGIN | O20: NOSHIFT
A21: COLUMN | B21: 18 | C21: 2 | E21: 697 | G21: RESNONE | J21: NONE | K21: CHN | M21: BEGINVALUE | N21: 0 | O21: 481 | P21: 4 | T21: ZONENAMES | Z21: RESULT_CAPTIONS | AF21: -1 | AG21: 0 | AO21: NOSHIFT | AT21: 0 | AV21: 61 | AW21: NOCHANGE | BC21: CUTDATEBEGIN | BI21: 4 | BJ21: 0 | BK21: 0 | BL21: 1 | BM21: 0
A22: COLUMN | B22: 18 | C22: 6 | E22: 699 | G22: RESNONE | J22: NONE | K22: CHN | M22: BEGINVALUE | N22: 0 | O22: 481 | P22: 4 | T22: ZONENAMES | Z22: RESULT_CAPTIONS | AF22: -1 | AG22: 0 | AO22: NOSHIFT | AT22: 0 | AV22: 95 | AW22: NOCHANGE | BC22: CUTDATEBEGIN | BE22: ENLIKEPOW | BI22: 8 | BJ22: 0 | BK22: 0 | BL22: 1 | BM22: 0
A23: MAINSHEET | B23: 6
A24: DATE | B24: 10 | C24: 5 | D24: dd mmmm | F24: BEGIN | O24: NOSHIFT
A25: DATE | B25: 10 | C25: 8 | D25: yyyy года | F25: BEGIN | O25: NOSHIFT
A26: COLUMN | B26: 18 | C26: 2 | E26: 1786 | G26: RESNONE | J26: NONE | K26: CHN | M26: BEGINVALUE | N26: 0 | O26: 790 | P26: 4 | T26: ZONENAMES | Z26: RESULT_CAPTIONS | AF26: -1 | AG26: 0 | AO26: NOSHIFT | AT26: 0 | AV26: 61 | AW26: NOCHANGE | BC26: CUTDATEBEGIN | BI26: 4 | BJ26: 0 | BK26: 0 | BL26: 1 | BM26: 0
A27: COLUMN | B27: 18 | C27: 6 | E27: 1788 | G27: RESNONE | J27: NONE | K27: CHN | M27: BEGINVALUE | N27: 0 | O27: 790 | P27: 4 | T27: ZONENAMES | Z27: RESULT_CAPTIONS | AF27: -1 | AG27: 0 | AO27: NOSHIFT | AT27: 0 | AV27: 95 | AW27: NOCHANGE | BC27: CUTDATEBEGIN | BE27: ENLIKEPOW | BI27: 8 | BJ27: 0 | BK27: 0 | BL27: 1 | BM27: 0
A28: MAINSHEET | B28: 7
A29: DATE | B29: 10 | C29: 5 | D29: dd mmmm | F29: BEGIN | O29: NOSHIFT
A30: DATE | B30: 10 | C30: 8 | D30: yyyy года | F30: BEGIN | O30: NOSHIFT
A31: COLUMN | B31: 18 | C31: 2 | E31: 1769 | G31: RESNONE | J31: NONE | K31: CHN | M31: BEGINVALUE | N31: 0 | O31: 784 | P31: 4 | T31: ZONENAMES | Z31: RESULT_CAPTIONS | AF31: -1 | AG31: 0 | AO31: NOSHIFT | AT31: 0 | AV31: 61 | AW31: NOCHANGE | BC31: CUTDATEBEGIN | BI31: 4 | BJ31: 0 | BK31: 0 | BL31: 1 | BM31: 0
A32: COLUMN | B32: 18 | C32: 6 | E32: 1771 | G32: RESNONE | J32: NONE | K32: CHN | M32: BEGINVALUE | N32: 0 | O32: 784 | P32: 4 | T32: ZONENAMES | Z32: RESULT_CAPTIONS | AF32: -1 | AG32: 0 | AO32: NOSHIFT | AT32: 0 | AV32: 95 | AW32: NOCHANGE | BC32: CUTDATEBEGIN | BE32: ENLIKEPOW | BI32: 8 | BJ32: 0 | BK32: 0 | BL32: 1 | BM32: 0
A33: MAINSHEET | B33: 8
A34: DATE | B34: 10 | C34: 5 | D34: dd mmmm | F34: BEGIN | O34: NOSHIFT
A35: DATE | B35: 10 | C35: 8 | D35: yyyy года | F35: BEGIN | O35: NOSHIFT
A36: COLUMN | B36: 18 | C36: 2 | E36: 117 | G36: RESNONE | J36: NONE | K36: CHN | M36: BEGINVALUE | N36: 0 | O36: 201 | P36: 4 | T36: ZONENAMES | Z36: RESULT_CAPTIONS | AF36: -1 | AG36: 0 | AO36: NOSHIFT | AT36: 0 | AV36: 61 | AW36: NOCHANGE | BC36: CUTDATEBEGIN | BI36: 4 | BJ36: 0 | BK36: 0 | BL36: 1 | BM36: 0
A37: COLUMN | B37: 18 | C37: 6 | E37: 119 | G37: RESNONE | J37: NONE | K37: CHN | M37: BEGINVALUE | N37: 0 | O37: 201 | P37: 4 | T37: ZONENAMES | Z37: RESULT_CAPTIONS | AF37: -1 | AG37: 0 | AO37: NOSHIFT | AT37: 0 | AV37: 95 | AW37: NOCHANGE | BC37: CUTDATEBEGIN | BE37: ENLIKEPOW | BI37: 8 | BJ37: 0 | BK37: 0 | BL37: 1 | BM37: 0
A38: MAINSHEET | B38: 9
A39: DATE | B39: 10 | C39: 5 | D39: dd mmmm | F39: BEGIN | O39: NOSHIFT
A40: DATE | B40: 10 | C40: 8 | D40: yyyy года | F40: BEGIN | O40: NOSHIFT
...

Sheet Ячейка 24
A1: ОАО "Пластик" | G1: Шифр | M1: I. Сведения о присоединенных трансформаторах и высоковольтных электродвигателях
A2: (наименование предприятия) | M2: 1. Трансформаторы
A3: г. Узловая, Тульская, 1 | G3: Питающий центр | I3: П/ст №167 (ГПП-1) | M3: №№ | N3: Место установки | P3: Мощность | R3: Номинальн. | T3: Включен. | V3: Назначение | X3: Примечание
A4: (адрес) | R4: напряжение | T4: на ответвление | V4: тр-ра
G5: № фидера | I5: яч 24 тр-р №1 | M5: п/п | P5: ква | R5: ________ кВ | T5: ________ кВ | V5: силов. освет.
A6: (министерство, ведомство) | V6: печной
A8: ПРОТОКОЛ (первичный)
A9: записей показания электросчетчиков и вольтметров, а также определение
A10: нагрузок и тангенса "фи" за | E10: 21 июня | H10: 2017года
A11: напряжения | E11: ______6000_____________ | I11: вольт
A13: Время записи часы | B13: Активн. сч-к тип | D13: СЭТ-4ТМ.03 | F13: Реактивн. сч-к тип | H13: СЭТ-4ТМ.03 | I13: Тангенс "фи" | J13: Показание | L13: Мощность
B14: ____________л__ | D14: № 812091210 | F14: ____________л__ | H14: №812091210 | J14: вольтметр. | L14: включен.
B15: Расчетн. коэф | D15: 18000 | F15: Расчетн. коэф | H15: 18000 | J15: на стороне | L15: компенсир.
B16: показ. | C16: разность | D16: расход за | F16: показ. | G16: разность | H16: расход за | J16: в\н | K16: н\н | L16: устройств
B17: сч-ка | C17: показ. | D17: час (кВт) | F17: сч-ка | G17: показ. | H17: час (кВт) | L17: кВар | M17: 2. Высоковольтные электродвигатели
A18: 0-00 | B18: 6123.1382 | F18: 1979.5839 | M18: №№ | N18: Место | Q18: Тип | T18: Номинальная | W18: Примечание
A19: 1-00 | B19: 6123.197 | C19: =IF(B19="","",IF(LEN(TRUNC(B18,0))-LEN(TRUNC(B19,0))=0,B19-B18,IF(LEN(TRUNC(B18,0))-LEN(TRUNC(B19,0))>0,VALUE(LEFT(B18,LEN(TRUNC(B18,0))-LEN(TRUNC(B19,0))))*POWER(10,LEN(TRUNC(B19,0)))+B19-B18,B19-B18-VALUE(LEFT(B19,LEN(TRUNC(B19,0))-LEN(TRUNC(B18,0))))*POWER(10,LEN(TRUNC(B18,0)))))) -> 0.0588 | D19: =IF(C19="","",C19*$D$15) -> 1058.4 | F19: 1979.6027 | G19: =IF(F19="","",IF(LEN(TRUNC(F18,0))-LEN(TRUNC(F19,0))=0,F19-F18,IF(LEN(TRUNC(F18,0))-LEN(TRUNC(F19,0))>0,VALUE(LEFT(F18,LEN(TRUNC(F18,0))-LEN(TRUNC(F19,0))))*POWER(10,LEN(TRUNC(F19,0)))+F19-F18,F19-F18-VALUE(LEFT(F19,LEN(TRUNC(F19,0))-LEN(TRUNC(F18,0))))*POWER(10,LEN(TRUNC(F18,0)))))) -> 0.0188 | H19: =IF(G19="","",G19*$H$15) -> 338.4 | I19: =IF(H19="","",IF(D19="","",IF(AND(H19=0,D19=0),0,H19/D19))) -> 0.31972789 | K19: 6.437719 | Q19: (синхронный,
A20: 2-00 | B20: 6123.2548 | C20: =IF(B20="","",IF(LEN(TRUNC(B19,0))-LEN(TRUNC(B20,0))=0,B20-B19,IF(LEN(TRUNC(B19,0))-LEN(TRUNC(B20,0))>0,VALUE(LEFT(B19,LEN(TRUNC(B19,0))-LEN(TRUNC(B20,0))))*POWER(10,LEN(TRUNC(B20,0)))+B20-B19,B20-B19-VALUE(LEFT(B20,LEN(TRUNC(B20,0))-LEN(TRUNC(B19,0))))*POWER(10,LEN(TRUNC(B19,0)))))) -> 0.0578 | D20: =IF(C20="","",C20*$D$15) -> 1040.4 | F20: 1979.6227 | G20: =IF(F20="","",IF(LEN(TRUNC(F19,0))-LEN(TRUNC(F20,0))=0,F20-F19,IF(LEN(TRUNC(F19,0))-LEN(TRUNC(F20,0))>0,VALUE(LEFT(F19,LEN(TRUNC(F19,0))-LEN(TRUNC(F20,0))))*POWER(10,LEN(TRUNC(F20,0)))+F20-F19,F20-F19-VALUE(LEFT(F20,LEN(TRUNC(F20,0))-LEN(TRUNC(F19,0))))*POWER(10,LEN(TRUNC(F19,0)))))) -> 0.02 | H20: =IF(G20="","",G20*$H$15) -> 360 | I20: =IF(H20="","",IF(D20="","",IF(AND(H20=0,D20=0),0,H20/D20))) -> 0.34602076 | K20: 6.469511 | M20: п/п | N20: установки | Q20: асинхронный) | T20: мощность кВт
A21: 3-00 | B21: 6123.3131 | C21: =IF(B21="","",IF(LEN(TRUNC(B20,0))-LEN(TRUNC(B21,0))=0,B21-B20,IF(LEN(TRUNC(B20,0))-LEN(TRUNC(B21,0))>0,VALUE(LEFT(B20,LEN(TRUNC(B20,0))-LEN(TRUNC(B21,0))))*POWER(10,LEN(TRUNC(B21,0)))+B21-B20,B21-B20-VALUE(LEFT(B21,LEN(TRUNC(B21,0))-LEN(TRUNC(B20,0))))*POWER(10,LEN(TRUNC(B20,0)))))) -> 0.0583 | D21: =IF(C21="","",C21*$D$15) -> 1049.4 | F21: 1979.6422 | G21: =IF(F21="","",IF(LEN(TRUNC(F20,0))-LEN(TRUNC(F21,0))=0,F21-F20,IF(LEN(TRUNC(F20,0))-LEN(TRUNC(F21,0))>0,VALUE(LEFT(F20,LEN(TRUNC(F20,0))-LEN(TRUNC(F21,0))))*POWER(10,LEN(TRUNC(F21,0)))+F21-F20,F21-F20-VALUE(LEFT(F21,LEN(TRUNC(F21,0))-LEN(TRUNC(F20,0))))*POWER(10,LEN(TRUNC(F20,0)))))) -> 0.0195 | H21: =IF(G21="","",G21*$H$15) -> 351 | I21: =IF(H21="","",IF(D21="","",IF(AND(H21=0,D21=0),0,H21/D21))) -> 0.33447684 | K21: 6.473572
A22: 4-00 | B22: 6123.3719 | C22: =IF(B22="","",IF(LEN(TRUNC(B21,0))-LEN(TRUNC(B22,0))=0,B22-B21,IF(LEN(TRUNC(B21,0))-LEN(TRUNC(B22,0))>0,VALUE(LEFT(B21,LEN(TRUNC(B21,0))-LEN(TRUNC(B22,0))))*POWER(10,LEN(TRUNC(B22,0)))+B22-B21,B22-B21-VALUE(LEFT(B22,LEN(TRUNC(B22,0))-LEN(TRUNC(B21,0))))*POWER(10,LEN(TRUNC(B21,0)))))) -> 0.0588 | D22: =IF(C22="","",C22*$D$15) -> 1058.4 | F22: 1979.6618 | G22: =IF(F22="","",IF(LEN(TRUNC(F21,0))-LEN(TRUNC(F22,0))=0,F22-F21,IF(LEN(TRUNC(F21,0))-LEN(TRUNC(F22,0))>0,VALUE(LEFT(F21,LEN(TRUNC(F21,0))-LEN(TRUNC(F22,0))))*POWER(10,LEN(TRUNC(F22,0)))+F22-F21,F22-F21-VALUE(LEFT(F22,LEN(TRUNC(F22,0))-LEN(TRUNC(F21,0))))*POWER(10,LEN(TRUNC(F21,0)))))) -> 0.0196 | H22: =IF(G22="","",G22*$H$15) -> 352.8 | I22: =IF(H22="","",IF(D22="","",IF(AND(H22=0,D22=0),0,H22/D22))) -> 0.33333333 | K22: 6.500047
A23: 5-00 | B23: 6123.4302 | C23: =IF(B23="","",IF(LEN(TRUNC(B22,0))-LEN(TRUNC(B23,0))=0,B23-B22,IF(LEN(TRUNC(B22,0))-LEN(TRUNC(B23,0))>0,VALUE(LEFT(B22,LEN(TRUNC(B22,0))-LEN(TRUNC(B23,0))))*POWER(10,LEN(TRUNC(B23,0)))+B23-B22,B23-B22-VALUE(LEFT(B23,LEN(TRUNC(B23,0))-LEN(TRUNC(B22,0))))*POWER(10,LEN(TRUNC(B22,0)))))) -> 0.0583 | D23: =IF(C23="","",C23*$D$15) -> 1049.4 | F23: 1979.6817 | G23: =IF(F23="","",IF(LEN(TRUNC(F22,0))-LEN(TRUNC(F23,0))=0,F23-F22,IF(LEN(TRUNC(F22,0))-LEN(TRUNC(F23,0))>0,VALUE(LEFT(F22,LEN(TRUNC(F22,0))-LEN(TRUNC(F23,0))))*POWER(10,LEN(TRUNC(F23,0)))+F23-F22,F23-F22-VALUE(LEFT(F23,LEN(TRUNC(F23,0))-LEN(TRUNC(F22,0))))*POWER(10,LEN(TRUNC(F22,0)))))) -> 0.0199 | H23: =IF(G23="","",G23*$H$15) -> 358.2 | I23: =IF(H23="","",IF(D23="","",IF(AND(H23=0,D23=0),0,H23/D23))) -> 0.34133791 | K23: 6.424461
A24: 6-00 | B24: 6123.4847 | C24: =IF(B24="","",IF(LEN(TRUNC(B23,0))-LEN(TRUNC(B24,0))=0,B24-B23,IF(LEN(TRUNC(B23,0))-LEN(TRUNC(B24,0))>0,VALUE(LEFT(B23,LEN(TRUNC(B23,0))-LEN(TRUNC(B24,0))))*POWER(10,LEN(TRUNC(B24,0)))+B24-B23,B24-B23-VALUE(LEFT(B24,LEN(TRUNC(B24,0))-LEN(TRUNC(B23,0))))*POWER(10,LEN(TRUNC(B23,0)))))) -> 0.0545 | D24: =IF(C24="","",C24*$D$15) -> 981 | F24: 1979.6987 | G24: =IF(F24="","",IF(LEN(TRUNC(F23,0))-LEN(TRUNC(F24,0))=0,F24-F23,IF(LEN(TRUNC(F23,0))-LEN(TRUNC(F24,0))>0,VALUE(LEFT(F23,LEN(TRUNC(F23,0))-LEN(TRUNC(F24,0))))*POWER(10,LEN(TRUNC(F24,0)))+F24-F23,F24-F23-VALUE(LEFT(F24,LEN(TRUNC(F24,0))-LEN(TRUNC(F23,0))))*POWER(10,LEN(TRUNC(F23,0)))))) -> 0.017 | H24: =IF(G24="","",G24*$H$15) -> 306 | I24: =IF(H24="","",IF(D24="","",IF(AND(H24=0,D24=0),0,H24/D24))) -> 0.31192661 | K24: 6.408624
A25: 7-00 | B25: 6123.5375 | C25: =IF(B25="","",IF(LEN(TRUNC(B24,0))-LEN(TRUNC(B25,0))=0,B25-B24,IF(LEN(TRUNC(B24,0))-LEN(TRUNC(B25,0))>0,VALUE(LEFT(B24,LEN(TRUNC(B24,0))-LEN(TRUNC(B25,0))))*POWER(10,LEN(TRUNC(B25,0)))+B25-B24,B25-B24-VALUE(LEFT(B25,LEN(TRUNC(B25,0))-LEN(TRUNC(B24,0))))*POWER(10,LEN(TRUNC(B24,0)))))) -> 0.0528 | D25: =IF(C25="","",C25*$D$15) -> 950.4 | F25: 1979.7132 | G25: =IF(F25="","",IF(LEN(TRUNC(F24,0))-LEN(TRUNC(F25,0))=0,F25-F24,IF(LEN(TRUNC(F24,0))-LEN(TRUNC(F25,0))>0,VALUE(LEFT(F24,LEN(TRUNC(F24,0))-LEN(TRUNC(F25,0))))*POWER(10,LEN(TRUNC(F25,0)))+F25-F24,F25-F24-VALUE(LEFT(F25,LEN(TRUNC(F25,0))-LEN(TRUNC(F24,0))))*POWER(10,LEN(TRUNC(F24,0)))))) -> 0.0145 | H25: =IF(G25="","",G25*$H$15) -> 261 | I25: =IF(H25="","",IF(D25="","",IF(AND(H25=0,D25=0),0,H25/D25))) -> 0.27462121 | K25: 6.493739
A26: 8-00 | B26: 6123.592 | C26: =IF(B26="","",IF(LEN(TRUNC(B25,0))-LEN(TRUNC(B26,0))=0,B26-B25,IF(LEN(TRUNC(B25,0))-LEN(TRUNC(B26,0))>0,VALUE(LEFT(B25,LEN(TRUNC(B25,0))-LEN(TRUNC(B26,0))))*POWER(10,LEN(TRUNC(B26,0)))+B26-B25,B26-B25-VALUE(LEFT(B26,LEN(TRUNC(B26,0))-LEN(TRUNC(B25,0))))*POWER(10,LEN(TRUNC(B25,0)))))) -> 0.0545 | D26: =IF(C26="","",C26*$D$15) -> 981 | F26: 1979.7263 | G26: =IF(F26="","",IF(LEN(TRUNC(F25,0))-LEN(TRUNC(F26,0))=0,F26-F25,IF(LEN(TRUNC(F25,0))-LEN(TRUNC(F26,0))>0,VALUE(LEFT(F25,LEN(TRUNC(F25,0))-LEN(TRUNC(F26,0))))*POWER(10,LEN(TRUNC(F26,0)))+F26-F25,F26-F25-VALUE(LEFT(F26,LEN(TRUNC(F26,0))-LEN(TRUNC(F25,0))))*POWER(10,LEN(TRUNC(F25,0)))))) -> 0.0131 | H26: =IF(G26="","",G26*$H$15) -> 235.8 | I26: =IF(H26="","",IF(D26="","",IF(AND(H26=0,D26=0),0,H26/D26))) -> 0.24036697 | K26: 6.347729
A27: 9-00 | B27: 6123.6421 | C27: =IF(B27="","",IF(LEN(TRUNC(B26,0))-LEN(TRUNC(B27,0))=0,B27-B26,IF(LEN(TRUNC(B26,0))-LEN(TRUNC(B27,0))>0,VALUE(LEFT(B26,LEN(TRUNC(B26,0))-LEN(TRUNC(B27,0))))*POWER(10,LEN(TRUNC(B27,0)))+B27-B26,B27-B26-VALUE(LEFT(B27,LEN(TRUNC(B27,0))-LEN(TRUNC(B26,0))))*POWER(10,LEN(TRUNC(B26,0)))))) -> 0.0501 | D27: =IF(C27="","",C27*$D$15) -> 901.8 | F27: 1979.7412 | G27: =IF(F27="","",IF(LEN(TRUNC(F26,0))-LEN(TRUNC(F27,0))=0,F27-F26,IF(LEN(TRUNC(F26,0))-LEN(TRUNC(F27,0))>0,VALUE(LEFT(F26,LEN(TRUNC(F26,0))-LEN(TRUNC(F27,0))))*POWER(10,LEN(TRUNC(F27,0)))+F27-F26,F27-F26-VALUE(LEFT(F27,LEN(TRUNC(F27,0))-LEN(TRUNC(F26,0))))*POWER(10,LEN(TRUNC(F26,0)))))) -> 0.0149 | H27: =IF(G27="","",G27*$H$15) -> 268.2 | I27: =IF(H27="","",IF(D27="","",IF(AND(H27=0,D27=0),0,H27/D27))) -> 0.29740519 | K27: 6.287414
A28: 10-00 | B28: 6123.7018 | C28: =IF(B28="","",IF(LEN(TRUNC(B27,0))-LEN(TRUNC(B28,0))=0,B28-B27,IF(LEN(TRUNC(B27,0))-LEN(TRUNC(B28,0))>0,VALUE(LEFT(B27,LEN(TRUNC(B27,0))-LEN(TRUNC(B28,0))))*POWER(10,LEN(TRUNC(B28,0)))+B28-B27,B28-B27-VALUE(LEFT(B28,LEN(TRUNC(B28,0))-LEN(TRUNC(B27,0))))*POWER(10,LEN(TRUNC(B27,0)))))) -> 0.0597 | D28: =IF(C28="","",C28*$D$15) -> 1074.6 | F28: 1979.7594 | G28: =IF(F28="","",IF(LEN(TRUNC(F27,0))-LEN(TRUNC(F28,0))=0,F28-F27,IF(LEN(TRUNC(F27,0))-LEN(TRUNC(F28,0))>0,VALUE(LEFT(F27,LEN(TRUNC(F27,0))-LEN(TRUNC(F28,0))))*POWER(10,LEN(TRUNC(F28,0)))+F28-F27,F28-F27-VALUE(LEFT(F28,LEN(TRUNC(F28,0))-LEN(TRUNC(F27,0))))*POWER(10,LEN(TRUNC(F27,0)))))) -> 0.0182 | H28: =IF(G28="","",G28*$H$15) -> 327.6 | I28: =IF(H28="","",IF(D28="","",IF(AND(H28=0,D28=0),0,H28/D28))) -> 0.30485762 | K28: 6.216361
A29: 11-00 | B29: 6123.7593 | C29: =IF(B29="","",IF(LEN(TRUNC(B28,0))-LEN(TRUNC(B29,0))=0,B29-B28,IF(LEN(TRUNC(B28,0))-LEN(TRUNC(B29,0))>0,VALUE(LEFT(B28,LEN(TRUNC(B28,0))-LEN(TRUNC(B29,0))))*POWER(10,LEN(TRUNC(B29,0)))+B29-B28,B29-B28-VALUE(LEFT(B29,LEN(TRUNC(B29,0))-LEN(TRUNC(B28,0))))*POWER(10,LEN(TRUNC(B28,0)))))) -> 0.0575 | D29: =IF(C29="","",C29*$D$15) -> 1035 | F29: 1979.7775 | G29: =IF(F29="","",IF(LEN(TRUNC(F28,0))-LEN(TRUNC(F29,0))=0,F29-F28,IF(LEN(TRUNC(F28,0))-LEN(TRUNC(F29,0))>0,VALUE(LEFT(F28,LEN(TRUNC(F28,0))-LEN(TRUNC(F29,0))))*POWER(10,LEN(TRUNC(F29,0)))+F29-F28,F29-F28-VALUE(LEFT(F29,LEN(TRUNC(F29,0))-LEN(TRUNC(F28,0))))*POWER(10,LEN(TRUNC(F28,0)))))) -> 0.0181 | H29: =IF(G29="","",G29*$H$15) -> 325.8 | I29: =IF(H29="","",IF(D29="","",IF(AND(H29=0,D29=0),0,H29/D29))) -> 0.31478261 | K29: 6.209973 | M29: Указать отдельно рабочие и запломбированные трансформаторы и высоковольтные электродвигатели
A30: 12-00 | B30: 6123.8113 | C30: =IF(B30="","",IF(LEN(TRUNC(B29,0))-LEN(TRUNC(B30,0))=0,B30-B29,IF(LEN(TRUNC(B29,0))-LEN(TRUNC(B30,0))>0,VALUE(LEFT(B29,LEN(TRUNC(B29,0))-LEN(TRUNC(B30,0))))*POWER(10,LEN(TRUNC(B30,0)))+B30-B29,B30-B29-VALUE(LEFT(B30,LEN(TRUNC(B30,0))-LEN(TRUNC(B29,0))))*POWER(10,LEN(TRUNC(B29,0)))))) -> 0.052 | D30: =IF(C30="","",C30*$D$15) -> 936 | F30: 1979.7926 | G30: =IF(F30="","",IF(LEN(TRUNC(F29,0))-LEN(TRUNC(F30,0))=0,F30-F29,IF(LEN(TRUNC(F29,0))-LEN(TRUNC(F30,0))>0,VALUE(LEFT(F29,LEN(TRUNC(F29,0))-LEN(TRUNC(F30,0))))*POWER(10,LEN(TRUNC(F30,0)))+F30-F29,F30-F29-VALUE(LEFT(F30,LEN(TRUNC(F30,0))-LEN(TRUNC(F29,0))))*POWER(10,LEN(TRUNC(F29,0)))))) -> 0.0151 | H30: =IF(G30="","",G30*$H$15) -> 271.8 | I30: =IF(H30="","",IF(D30="","",IF(AND(H30=0,D30=0),0,H30/D30))) -> 0.29038462 | K30: 6.150782 | M30: II. Статконденсаторы всех напряжений
A31: 13-00 | B31: 6123.8612 | C31: =IF(B31="","",IF(LEN(TRUNC(B30,0))-LEN(TRUNC(B31,0))=0,B31-B30,IF(LEN(TRUNC(B30,0))-LEN(TRUNC(B31,0))>0,VALUE(LEFT(B30,LEN(TRUNC(B30,0))-LEN(TRUNC(B31,0))))*POWER(10,LEN(TRUNC(B31,0)))+B31-B30,B31-B30-VALUE(LEFT(B31,LEN(TRUNC(B31,0))-LEN(TRUNC(B30,0))))*POWER(10,LEN(TRUNC(B30,0)))))) -> 0.0499 | D31: =IF(C31="","",C31*$D$15) -> 898.2 | F31: 1979.8073 | G31: =IF(F31="","",IF(LEN(TRUNC(F30,0))-LEN(TRUNC(F31,0))=0,F31-F30,IF(LEN(TRUNC(F30,0))-LEN(TRUNC(F31,0))>0,VALUE(LEFT(F30,LEN(TRUNC(F30,0))-LEN(TRUNC(F31,0))))*POWER(10,LEN(TRUNC(F31,0)))+F31-F30,F31-F30-VALUE(LEFT(F31,LEN(TRUNC(F31,0))-LEN(TRUNC(F30,0))))*POWER(10,LEN(TRUNC(F30,0)))))) -> 0.0147 | H31: =IF(G31="","",G31*$H$15) -> 264.6 | I31: =IF(H31="","",IF(D31="","",IF(AND(H31=0,D31=0),0,H31/D31))) -> 0.29458918 | K31: 6.265051 | M31: №№ | N31: Место | P31: Номинальное | R31: Номинальная | T31: В т.ч. с | V31: Время включения | Y31: Примечание
A32: 14-00 | B32: 6123.9202 | C32: =IF(B32="","",IF(LEN(TRUNC(B31,0))-LEN(TRUNC(B32,0))=0,B32-B31,IF(LEN(TRUNC(B31,0))-LEN(TRUNC(B32,0))>0,VALUE(LEFT(B31,LEN(TRUNC(B31,0))-LEN(TRUNC(B32,0))))*POWER(10,LEN(TRUNC(B32,0)))+B32-B31,B32-B31-VALUE(LEFT(B32,LEN(TRUNC(B32,0))-LEN(TRUNC(B31,0))))*POWER(10,LEN(TRUNC(B31,0)))))) -> 0.059 | D32: =IF(C32="","",C32*$D$15) -> 1062 | F32: 1979.8231 | G32: =IF(F32="","",IF(LEN(TRUNC(F31,0))-LEN(TRUNC(F32,0))=0,F32-F31,IF(LEN(TRUNC(F31,0))-LEN(TRUNC(F32,0))>0,VALUE(LEFT(F31,LEN(TRUNC(F31,0))-LEN(TRUNC(F32,0))))*POWER(10,LEN(TRUNC(F32,0)))+F32-F31,F32-F31-VALUE(LEFT(F32,LEN(TRUNC(F32,0))-LEN(TRUNC(F31,0))))*POWER(10,LEN(TRUNC(F31,0)))))) -> 0.0158 | H32: =IF(G32="","",G32*$H$15) -> 284.4 | I32: =IF(H32="","",IF(D32="","",IF(AND(H32=0,D32=0),0,H32/D32))) -> 0.26779661 | K32: 5.949984 | P32: напряжение | R32: мощность | T32: авторегулир. | V32: и отключения
A33: 15-00 | B33: 6123.9729 | C33: =IF(B33="","",IF(LEN(TRUNC(B32,0))-LEN(TRUNC(B33,0))=0,B33-B32,IF(LEN(TRUNC(B32,0))-LEN(TRUNC(B33,0))>0,VALUE(LEFT(B32,LEN(TRUNC(B32,0))-LEN(TRUNC(B33,0))))*POWER(10,LEN(TRUNC(B33,0)))+B33-B32,B33-B32-VALUE(LEFT(B33,LEN(TRUNC(B33,0))-LEN(TRUNC(B32,0))))*POWER(10,LEN(TRUNC(B32,0)))))) -> 0.0527 | D33: =IF(C33="","",C33*$D$15) -> 948.6 | F33: 1979.8383 | G33: =IF(F33="","",IF(LEN(TRUNC(F32,0))-LEN(TRUNC(F33,0))=0,F33-F32,IF(LEN(TRUNC(F32,0))-LEN(TRUNC(F33,0))>0,VALUE(LEFT(F32,LEN(TRUNC(F32,0))-LEN(TRUNC(F33,0))))*POWER(10,LEN(TRUNC(F33,0)))+F33-F32,F33-F32-VALUE(LEFT(F33,LEN(TRUNC(F33,0))-LEN(TRUNC(F32,0))))*POWER(10,LEN(TRUNC(F32,0)))))) -> 0.0152 | H33: =IF(G33="","",G33*$H$15) -> 273.6 | I33: =IF(H33="","",IF(D33="","",IF(AND(H33=0,D33=0),0,H33/D33))) -> 0.28842505 | K33: 6.209528 | M33: п/п | N33: установки | P33: кВ | R33: кВар | T33: кВар | V33: установки за сутки
A34: 16-00 | B34: 6124.0251 | C34: =IF(B34="","",IF(LEN(TRUNC(B33,0))-LEN(TRUNC(B34,0))=0,B34-B33,IF(LEN(TRUNC(B33,0))-LEN(TRUNC(B34,0))>0,VALUE(LEFT(B33,LEN(TRUNC(B33,0))-LEN(TRUNC(B34,0))))*POWER(10,LEN(TRUNC(B34,0)))+B34-B33,B34-B33-VALUE(LEFT(B34,LEN(TRUNC(B34,0))-LEN(TRUNC(B33,0))))*POWER(10,LEN(TRUNC(B33,0)))))) -> 0.0522 | D34: =IF(C34="","",C34*$D$15) -> 939.6 | F34: 1979.8537 | G34: =IF(F34="","",IF(LEN(TRUNC(F33,0))-LEN(TRUNC(F34,0))=0,F34-F33,IF(LEN(TRUNC(F33,0))-LEN(TRUNC(F34,0))>0,VALUE(LEFT(F33,LEN(TRUNC(F33,0))-LEN(TRUNC(F34,0))))*POWER(10,LEN(TRUNC(F34,0)))+F34-F33,F34-F33-VALUE(LEFT(F34,LEN(TRUNC(F34,0))-LEN(TRUNC(F33,0))))*POWER(10,LEN(TRUNC(F33,0)))))) -> 0.0154 | H34: =IF(G34="","",G34*$H$15) -> 277.2 | I34: =IF(H34="","",IF(D34="","",IF(AND(H34=0,D34=0),0,H34/D34))) -> 0.29501916 | K34: 6.135647
A35: 17-00 | B35: 6124.079 | C35: =IF(B35="","",IF(LEN(TRUNC(B34,0))-LEN(TRUNC(B35,0))=0,B35-B34,IF(LEN(TRUNC(B34,0))-LEN(TRUNC(B35,0))>0,VALUE(LEFT(B34,LEN(TRUNC(B34,0))-LEN(TRUNC(B35,0))))*POWER(10,LEN(TRUNC(B35,0)))+B35-B34,B35-B34-VALUE(LEFT(B35,LEN(TRUNC(B35,0))-LEN(TRUNC(B34,0))))*POWER(10,LEN(TRUNC(B34,0)))))) -> 0.0539 | D35: =IF(C35="","",C35*$D$15) -> 970.2 | F35: 1979.8687 | G35: =IF(F35="","",IF(LEN(TRUNC(F34,0))-LEN(TRUNC(F35,0))=0,F35-F34,IF(LEN(TRUNC(F34,0))-LEN(TRUNC(F35,0))>0,VALUE(LEFT(F34,LEN(TRUNC(F34,0))-LEN(TRUNC(F35,0))))*POWER(10,LEN(TRUNC(F35,0)))+F35-F34,F35-F34-VALUE(LEFT(F35,LEN(TRUNC(F35,0))-LEN(TRUNC(F34,0))))*POWER(10,LEN(TRUNC(F34,0)))))) -> 0.015 | H35: =IF(G35="","",G35*$H$15) -> 270 | I35: =IF(H35="","",IF(D35="","",IF(AND(H35=0,D35=0),0,H35/D35))) -> 0.27829314 | K35: 6.158191 | N35: КТП-22,23,24,25 | P35: 0.4 | R35: 696
A36: 18-00 | B36: 6124.1277 | C36: =IF(B36="","",IF(LEN(TRUNC(B35,0))-LEN(TRUNC(B36,0))=0,B36-B35,IF(LEN(TRUNC(B35,0))-LEN(TRUNC(B36,0))>0,VALUE(LEFT(B35,LEN(TRUNC(B35,0))-LEN(TRUNC(B36,0))))*POWER(10,LEN(TRUNC(B36,0)))+B36-B35,B36-B35-VALUE(LEFT(B36,LEN(TRUNC(B36,0))-LEN(TRUNC(B35,0))))*POWER(10,LEN(TRUNC(B35,0)))))) -> 0.0487 | D36: =IF(C36="","",C36*$D$15) -> 876.6 | F36: 1979.8828 | G36: =IF(F36="","",IF(LEN(TRUNC(F35,0))-LEN(TRUNC(F36,0))=0,F36-F35,IF(LEN(TRUNC(F35,0))-LEN(TRUNC(F36,0))>0,VALUE(LEFT(F35,LEN(TRUNC(F35,0))-LEN(TRUNC(F36,0))))*POWER(10,LEN(TRUNC(F36,0)))+F36-F35,F36-F35-VALUE(LEFT(F36,LEN(TRUNC(F36,0))-LEN(TRUNC(F35,0))))*POWER(10,LEN(TRUNC(F35,0)))))) -> 0.0141 | H36: =IF(G36="","",G36*$H$15) -> 253.8 | I36: =IF(H36="","",IF(D36="","",IF(AND(H36=0,D36=0),0,H36/D36))) -> 0.28952772 | K36: 6.217741 | N36: РП-1 | P36: 6 | R36: 870
A37: 19-00 | B37: 6124.1753 | C37: =IF(B37="","",IF(LEN(TRUNC(B36,0))-LEN(TRUNC(B37,0))=0,B37-B36,IF(LEN(TRUNC(B36,0))-LEN(TRUNC(B37,0))>0,VALUE(LEFT(B36,LEN(TRUNC(B36,0))-LEN(TRUNC(B37,0))))*POWER(10,LEN(TRUNC(B37,0)))+B37-B36,B37-B36-VALUE(LEFT(B37,LEN(TRUNC(B37,0))-LEN(TRUNC(B36,0))))*POWER(10,LEN(TRUNC(B36,0)))))) -> 0.0476 | D37: =IF(C37="","",C37*$D$15) -> 856.8 | F37: 1979.8966 | G37: =IF(F37="","",IF(LEN(TRUNC(F36,0))-LEN(TRUNC(F37,0))=0,F37-F36,IF(LEN(TRUNC(F36,0))-LEN(TRUNC(F37,0))>0,VALUE(LEFT(F36,LEN(TRUNC(F36,0))-LEN(TRUNC(F37,0))))*POWER(10,LEN(TRUNC(F37,0)))+F37-F36,F37-F36-VALUE(LEFT(F37,LEN(TRUNC(F37,0))-LEN(TRUNC(F36,0))))*POWER(10,LEN(TRUNC(F36,0)))))) -> 0.0138 | H37: =IF(G37="","",G37*$H$15) -> 248.4 | I37: =IF(H37="","",IF(D37="","",IF(AND(H37=0,D37=0),0,H37/D37))) -> 0.28991597 | K37: 6.226002
A38: 20-00 | B38: 6124.2214 | C38: =IF(B38="","",IF(LEN(TRUNC(B37,0))-LEN(TRUNC(B38,0))=0,B38-B37,IF(LEN(TRUNC(B37,0))-LEN(TRUNC(B38,0))>0,VALUE(LEFT(B37,LEN(TRUNC(B37,0))-LEN(TRUNC(B38,0))))*POWER(10,LEN(TRUNC(B38,0)))+B38-B37,B38-B37-VALUE(LEFT(B38,LEN(TRUNC(B38,0))-LEN(TRUNC(B37,0))))*POWER(10,LEN(TRUNC(B37,0)))))) -> 0.0461 | D38: =IF(C38="","",C38*$D$15) -> 829.8 | F38: 1979.9081 | G38: =IF(F38="","",IF(LEN(TRUNC(F37,0))-LEN(TRUNC(F38,0))=0,F38-F37,IF(LEN(TRUNC(F37,0))-LEN(TRUNC(F38,0))>0,VALUE(LEFT(F37,LEN(TRUNC(F37,0))-LEN(TRUNC(F38,0))))*POWER(10,LEN(TRUNC(F38,0)))+F38-F37,F38-F37-VALUE(LEFT(F38,LEN(TRUNC(F38,0))-LEN(TRUNC(F37,0))))*POWER(10,LEN(TRUNC(F37,0)))))) -> 0.0115 | H38: =IF(G38="","",G38*$H$15) -> 207 | I38: =IF(H38="","",IF(D38="","",IF(AND(H38=0,D38=0),0,H38/D38))) -> 0.2494577 | K38: 6.376532
A39: 21-00 | B39: 6124.2695 | C39: =IF(B39="","",IF(LEN(TRUNC(B38,0))-LEN(TRUNC(B39,0))=0,B39-B38,IF(LEN(TRUNC(B38,0))-LEN(TRUNC(B39,0))>0,VALUE(LEFT(B38,LEN(TRUNC(B38,0))-LEN(TRUNC(B39,0))))*POWER(10,LEN(TRUNC(B39,0)))+B39-B38,B39-B38-VALUE(LEFT(B39,LEN(TRUNC(B39,0))-LEN(TRUNC(B38,0))))*POWER(10,LEN(TRUNC(B38,0)))))) -> 0.0481 | D39: =IF(C39="","",C39*$D$15) -> 865.8 | F39: 1979.9227 | G39: =IF(F39="","",IF(LEN(TRUNC(F38,0))-LEN(TRUNC(F39,0))=0,F39-F38,IF(LEN(TRUNC(F38,0))-LEN(TRUNC(F39,0))>0,VALUE(LEFT(F38,LEN(TRUNC(F38,0))-LEN(TRUNC(F39,0))))*POWER(10,LEN(TRUNC(F39,0)))+F39-F38,F39-F38-VALUE(LEFT(F39,LEN(TRUNC(F39,0))-LEN(TRUNC(F38,0))))*POWER(10,LEN(TRUNC(F38,0)))))) -> 0.0146 | H39: =IF(G39="","",G39*$H$15) -> 262.8 | I39: =IF(H39="","",IF(D39="","",IF(AND(H39=0,D39=0),0,H39/D39))) -> 0.3035343 | K39: 6.385406
A40: 22-00 | B40: 6124.3197 | C40: =IF(B40="","",IF(LEN(TRUNC(B39,0))-LEN(TRUNC(B40,0))=0,B40-B39,IF(LEN(TRUNC(B39,0))-LEN(TRUNC(B40,0))>0,VALUE(LEFT(B39,LEN(TRUNC(B39,0))-LEN(TRUNC(B40,0))))*POWER(10,LEN(TRUNC(B40,0)))+B40-B39,B40-B39-VALUE(LEFT(B40,LEN(TRUNC(B40,0))-LEN(TRUNC(B39,0))))*POWER(10,LEN(TRUNC(B39,0)))))) -> 0.0502 | D40: =IF(C40="","",C40*$D$15) -> 903.6 | F40: 1979.9387 | G40: =IF(F40="","",IF(LEN(TRUNC(F39,0))-LEN(TRUNC(F40,0))=0,F40-F39,IF(LEN(TRUNC(F39,0))-LEN(TRUNC(F40,0))>0,VALUE(LEFT(F39,LEN(TRUNC(F39,0))-LEN(TRUNC(F40,0))))*POWER(10,LEN(TRUNC(F40,0)))+F40-F39,F40-F39-VALUE(LEFT(F40,LEN(TRUNC(F40,0))-LEN(TRUNC(F39,0))))*POWER(10,LEN(TRUNC(F39,0)))))) -> 0.016 | H40: =IF(G40="","",G40*$H$15) -> 288 | I40: =IF(H40="","",IF(D40="","",IF(AND(H40=0,D40=0),0,H40/D40))) -> 0.3187251 | K40: 6.348614 | M40: III. Синхронные электродвигатели напряжением до 1000 В
A41: 23-00 | B41: 6124.3704 | C41: =IF(B41="","",IF(LEN(TRUNC(B40,0))-LEN(TRUNC(B41,0))=0,B41-B40,IF(LEN(TRUNC(B40,0))-LEN(TRUNC(B41,0))>0,VALUE(LEFT(B40,LEN(TRUNC(B40,0))-LEN(TRUNC(B41,0))))*POWER(10,LEN(TRUNC(B41,0)))+B41-B40,B41-B40-VALUE(LEFT(B41,LEN(TRUNC(B41,0))-LEN(TRUNC(B40,0))))*POWER(10,LEN(TRUNC(B40,0)))))) -> 0.0507 | D41: =IF(C41="","",C41*$D$15) -> 912.6 | F41: 1979.9553 | G41: =IF(F41="","",IF(LEN(TRUNC(F40,0))-LEN(TRUNC(F41,0))=0,F41-F40,IF(LEN(TRUNC(F40,0))-LEN(TRUNC(F41,0))>0,VALUE(LEFT(F40,LEN(TRUNC(F40,0))-LEN(TRUNC(F41,0))))*POWER(10,LEN(TRUNC(F41,0)))+F41-F40,F41-F40-VALUE(LEFT(F41,LEN(TRUNC(F41,0))-LEN(TRUNC(F40,0))))*POWER(10,LEN(TRUNC(F40,0)))))) -> 0.0166 | H41: =IF(G41="","",G41*$H$15) -> 298.8 | I41: =IF(H41="","",IF(D41="","",IF(AND(H41=0,D41=0),0,H41/D41))) -> 0.32741617 | K41: 6.278701 | M41: №№ | N41: Место | P41: Номинальная | S41: № п-п | T41: Место установки | X41: Номинальная
A42: 24-00 | B42: 6124.421 | C42: =IF(B42="","",IF(LEN(TRUNC(B41,0))-LEN(TRUNC(B42,0))=0,B42-B41,IF(LEN(TRUNC(B41,0))-LEN(TRUNC(B42,0))>0,VALUE(LEFT(B41,LEN(TRUNC(B41,0))-LEN(TRUNC(B42,0))))*POWER(10,LEN(TRUNC(B42,0)))+B42-B41,B42-B41-VALUE(LEFT(B42,LEN(TRUNC(B42,0))-LEN(TRUNC(B41,0))))*POWER(10,LEN(TRUNC(B41,0)))))) -> 0.0506 | D42: =IF(C42="","",C42*$D$15) -> 910.8 | F42: 1979.9722 | G42: =IF(F42="","",IF(LEN(TRUNC(F41,0))-LEN(TRUNC(F42,0))=0,F42-F41,IF(LEN(TRUNC(F41,0))-LEN(TRUNC(F42,0))>0,VALUE(LEFT(F41,LEN(TRUNC(F41,0))-LEN(TRUNC(F42,0))))*POWER(10,LEN(TRUNC(F42,0)))+F42-F41,F42-F41-VALUE(LEFT(F42,LEN(TRUNC(F42,0))-LEN(TRUNC(F41,0))))*POWER(10,LEN(TRUNC(F41,0)))))) -> 0.0169 | H42: =IF(G42="","",G42*$H$15) -> 304.2 | I42: =IF(H42="","",IF(D42="","",IF(AND(H42=0,D42=0),0,H42/D42))) -> 0.33399209 | K42: 6.369748
...

Sheet Ячейка 2
A1: ОАО "Пластик" | G1: Шифр | M1: I. Сведения о присоединенных трансформаторах и высоковольтных электродвигателях
A2: (наименование предприятия) | M2: 1. Трансформаторы
A3: г. Узловая, Тульская, 1 | G3: Питающий центр | I3: П/ст №167 (ГПП-1) | M3: №№ | N3: Место установки | P3: Мощность | R3: Номинальн. | T3: Включен. | V3: Назначение | X3: Примечание
A4: (адрес) | R4: напряжение | T4: на ответвление | V4: тр-ра
G5: № фидера | I5: яч 2 тр-р №2 | M5: п/п | P5: ква | R5: ________ кВ | T5: ________ кВ | V5: силов. освет.
A6: (министерство, ведомство) | V6: печной
A8: ПРОТОКОЛ (первичный)
A9: записей показания электросчетчиков и вольтметров, а также определение
A10: нагрузок и тангенса "фи" за | E10: 21 июня | H10: 2017года
A11: напряжения | E11: _______6000_____________ | I11: вольт
A13: Время записи часы | B13: Активн. сч-к тип | D13: СЭТ-4ТМ.03 | F13: Реактивн. сч-к тип | H13: СЭТ-4ТМ.3 | I13: Тангенс "фи" | J13: Показание | L13: Мощность
B14: ____________л__ | D14: №0808090590 | F14: ____________л__ | H14: №0808090590 | J14: вольтметр. | L14: включен.
B15: Расчетн. коэф | D15: 18000 | F15: Расчетн. коэф | H15: 18000 | J15: на стороне | L15: компенсир.
B16: показ. | C16: разность | D16: расход за | F16: показ. | G16: разность | H16: расход за | J16: в\н | K16: н\н | L16: устройств
B17: сч-ка | C17: показ. | D17: час (кВт) | F17: сч-ка | G17: показ. | H17: час (кВт) | L17: кВар | M17: 2. Высоковольтные электродвигатели
A18: 0-00 | B18: 14262.923 | F18: 7160.236 | M18: №№ | N18: Место | Q18: Тип | T18: Номинальная | W18: Примечание
A19: 1-00 | B19: 14263.12 | C19: =IF(B19="","",IF(LEN(TRUNC(B18,0))-LEN(TRUNC(B19,0))=0,B19-B18,IF(LEN(TRUNC(B18,0))-LEN(TRUNC(B19,0))>0,VALUE(LEFT(B18,LEN(TRUNC(B18,0))-LEN(TRUNC(B19,0))))*POWER(10,LEN(TRUNC(B19,0)))+B19-B18,B19-B18-VALUE(LEFT(B19,LEN(TRUNC(B19,0))-LEN(TRUNC(B18,0))))*POWER(10,LEN(TRUNC(B18,0)))))) -> 0.1972 | D19: =IF(C19="","",C19*$D$15) -> 3549.6 | F19: 7160.3445 | G19: =IF(F19="","",IF(LEN(TRUNC(F18,0))-LEN(TRUNC(F19,0))=0,F19-F18,IF(LEN(TRUNC(F18,0))-LEN(TRUNC(F19,0))>0,VALUE(LEFT(F18,LEN(TRUNC(F18,0))-LEN(TRUNC(F19,0))))*POWER(10,LEN(TRUNC(F19,0)))+F19-F18,F19-F18-VALUE(LEFT(F19,LEN(TRUNC(F19,0))-LEN(TRUNC(F18,0))))*POWER(10,LEN(TRUNC(F18,0)))))) -> 0.1085 | H19: =IF(G19="","",G19*$H$15) -> 1953 | I19: =IF(H19="","",IF(D19="","",IF(AND(H19=0,D19=0),0,H19/D19))) -> 0.55020284 | K19: 6.326905 | Q19: (синхронный,
A20: 2-00 | B20: 14263.318 | C20: =IF(B20="","",IF(LEN(TRUNC(B19,0))-LEN(TRUNC(B20,0))=0,B20-B19,IF(LEN(TRUNC(B19,0))-LEN(TRUNC(B20,0))>0,VALUE(LEFT(B19,LEN(TRUNC(B19,0))-LEN(TRUNC(B20,0))))*POWER(10,LEN(TRUNC(B20,0)))+B20-B19,B20-B19-VALUE(LEFT(B20,LEN(TRUNC(B20,0))-LEN(TRUNC(B19,0))))*POWER(10,LEN(TRUNC(B19,0)))))) -> 0.1982 | D20: =IF(C20="","",C20*$D$15) -> 3567.6 | F20: 7160.458 | G20: =IF(F20="","",IF(LEN(TRUNC(F19,0))-LEN(TRUNC(F20,0))=0,F20-F19,IF(LEN(TRUNC(F19,0))-LEN(TRUNC(F20,0))>0,VALUE(LEFT(F19,LEN(TRUNC(F19,0))-LEN(TRUNC(F20,0))))*POWER(10,LEN(TRUNC(F20,0)))+F20-F19,F20-F19-VALUE(LEFT(F20,LEN(TRUNC(F20,0))-LEN(TRUNC(F19,0))))*POWER(10,LEN(TRUNC(F19,0)))))) -> 0.1135 | H20: =IF(G20="","",G20*$H$15) -> 2043 | I20: =IF(H20="","",IF(D20="","",IF(AND(H20=0,D20=0),0,H20/D20))) -> 0.57265388 | K20: 6.412437 | M20: п/п | N20: установки | Q20: асинхронный) | T20: мощность кВт
A21: 3-00 | B21: 14263.512 | C21: =IF(B21="","",IF(LEN(TRUNC(B20,0))-LEN(TRUNC(B21,0))=0,B21-B20,IF(LEN(TRUNC(B20,0))-LEN(TRUNC(B21,0))>0,VALUE(LEFT(B20,LEN(TRUNC(B20,0))-LEN(TRUNC(B21,0))))*POWER(10,LEN(TRUNC(B21,0)))+B21-B20,B21-B20-VALUE(LEFT(B21,LEN(TRUNC(B21,0))-LEN(TRUNC(B20,0))))*POWER(10,LEN(TRUNC(B20,0)))))) -> 0.1941 | D21: =IF(C21="","",C21*$D$15) -> 3493.8 | F21: 7160.5702 | G21: =IF(F21="","",IF(LEN(TRUNC(F20,0))-LEN(TRUNC(F21,0))=0,F21-F20,IF(LEN(TRUNC(F20,0))-LEN(TRUNC(F21,0))>0,VALUE(LEFT(F20,LEN(TRUNC(F20,0))-LEN(TRUNC(F21,0))))*POWER(10,LEN(TRUNC(F21,0)))+F21-F20,F21-F20-VALUE(LEFT(F21,LEN(TRUNC(F21,0))-LEN(TRUNC(F20,0))))*POWER(10,LEN(TRUNC(F20,0)))))) -> 0.1122 | H21: =IF(G21="","",G21*$H$15) -> 2019.6 | I21: =IF(H21="","",IF(D21="","",IF(AND(H21=0,D21=0),0,H21/D21))) -> 0.57805255 | K21: 6.418342
A22: 4-00 | B22: 14263.704 | C22: =IF(B22="","",IF(LEN(TRUNC(B21,0))-LEN(TRUNC(B22,0))=0,B22-B21,IF(LEN(TRUNC(B21,0))-LEN(TRUNC(B22,0))>0,VALUE(LEFT(B21,LEN(TRUNC(B21,0))-LEN(TRUNC(B22,0))))*POWER(10,LEN(TRUNC(B22,0)))+B22-B21,B22-B21-VALUE(LEFT(B22,LEN(TRUNC(B22,0))-LEN(TRUNC(B21,0))))*POWER(10,LEN(TRUNC(B21,0)))))) -> 0.1915 | D22: =IF(C22="","",C22*$D$15) -> 3447 | F22: 7160.6825 | G22: =IF(F22="","",IF(LEN(TRUNC(F21,0))-LEN(TRUNC(F22,0))=0,F22-F21,IF(LEN(TRUNC(F21,0))-LEN(TRUNC(F22,0))>0,VALUE(LEFT(F21,LEN(TRUNC(F21,0))-LEN(TRUNC(F22,0))))*POWER(10,LEN(TRUNC(F22,0)))+F22-F21,F22-F21-VALUE(LEFT(F22,LEN(TRUNC(F22,0))-LEN(TRUNC(F21,0))))*POWER(10,LEN(TRUNC(F21,0)))))) -> 0.1123 | H22: =IF(G22="","",G22*$H$15) -> 2021.4 | I22: =IF(H22="","",IF(D22="","",IF(AND(H22=0,D22=0),0,H22/D22))) -> 0.58642298 | K22: 6.240928
A23: 5-00 | B23: 14263.894 | C23: =IF(B23="","",IF(LEN(TRUNC(B22,0))-LEN(TRUNC(B23,0))=0,B23-B22,IF(LEN(TRUNC(B22,0))-LEN(TRUNC(B23,0))>0,VALUE(LEFT(B22,LEN(TRUNC(B22,0))-LEN(TRUNC(B23,0))))*POWER(10,LEN(TRUNC(B23,0)))+B23-B22,B23-B22-VALUE(LEFT(B23,LEN(TRUNC(B23,0))-LEN(TRUNC(B22,0))))*POWER(10,LEN(TRUNC(B22,0)))))) -> 0.1903 | D23: =IF(C23="","",C23*$D$15) -> 3425.4 | F23: 7160.7947 | G23: =IF(F23="","",IF(LEN(TRUNC(F22,0))-LEN(TRUNC(F23,0))=0,F23-F22,IF(LEN(TRUNC(F22,0))-LEN(TRUNC(F23,0))>0,VALUE(LEFT(F22,LEN(TRUNC(F22,0))-LEN(TRUNC(F23,0))))*POWER(10,LEN(TRUNC(F23,0)))+F23-F22,F23-F22-VALUE(LEFT(F23,LEN(TRUNC(F23,0))-LEN(TRUNC(F22,0))))*POWER(10,LEN(TRUNC(F22,0)))))) -> 0.1122 | H23: =IF(G23="","",G23*$H$15) -> 2019.6 | I23: =IF(H23="","",IF(D23="","",IF(AND(H23=0,D23=0),0,H23/D23))) -> 0.58959538 | K23: 6.461163
A24: 6-00 | B24: 14264.077 | C24: =IF(B24="","",IF(LEN(TRUNC(B23,0))-LEN(TRUNC(B24,0))=0,B24-B23,IF(LEN(TRUNC(B23,0))-LEN(TRUNC(B24,0))>0,VALUE(LEFT(B23,LEN(TRUNC(B23,0))-LEN(TRUNC(B24,0))))*POWER(10,LEN(TRUNC(B24,0)))+B24-B23,B24-B23-VALUE(LEFT(B24,LEN(TRUNC(B24,0))-LEN(TRUNC(B23,0))))*POWER(10,LEN(TRUNC(B23,0)))))) -> 0.1833 | D24: =IF(C24="","",C24*$D$15) -> 3299.4 | F24: 7160.9015 | G24: =IF(F24="","",IF(LEN(TRUNC(F23,0))-LEN(TRUNC(F24,0))=0,F24-F23,IF(LEN(TRUNC(F23,0))-LEN(TRUNC(F24,0))>0,VALUE(LEFT(F23,LEN(TRUNC(F23,0))-LEN(TRUNC(F24,0))))*POWER(10,LEN(TRUNC(F24,0)))+F24-F23,F24-F23-VALUE(LEFT(F24,LEN(TRUNC(F24,0))-LEN(TRUNC(F23,0))))*POWER(10,LEN(TRUNC(F23,0)))))) -> 0.1068 | H24: =IF(G24="","",G24*$H$15) -> 1922.4 | I24: =IF(H24="","",IF(D24="","",IF(AND(H24=0,D24=0),0,H24/D24))) -> 0.58265139 | K24: 6.475829
A25: 7-00 | B25: 14264.282 | C25: =IF(B25="","",IF(LEN(TRUNC(B24,0))-LEN(TRUNC(B25,0))=0,B25-B24,IF(LEN(TRUNC(B24,0))-LEN(TRUNC(B25,0))>0,VALUE(LEFT(B24,LEN(TRUNC(B24,0))-LEN(TRUNC(B25,0))))*POWER(10,LEN(TRUNC(B25,0)))+B25-B24,B25-B24-VALUE(LEFT(B25,LEN(TRUNC(B25,0))-LEN(TRUNC(B24,0))))*POWER(10,LEN(TRUNC(B24,0)))))) -> 0.205 | D25: =IF(C25="","",C25*$D$15) -> 3690 | F25: 7161.0133 | G25: =IF(F25="","",IF(LEN(TRUNC(F24,0))-LEN(TRUNC(F25,0))=0,F25-F24,IF(LEN(TRUNC(F24,0))-LEN(TRUNC(F25,0))>0,VALUE(LEFT(F24,LEN(TRUNC(F24,0))-LEN(TRUNC(F25,0))))*POWER(10,LEN(TRUNC(F25,0)))+F25-F24,F25-F24-VALUE(LEFT(F25,LEN(TRUNC(F25,0))-LEN(TRUNC(F24,0))))*POWER(10,LEN(TRUNC(F24,0)))))) -> 0.1118 | H25: =IF(G25="","",G25*$H$15) -> 2012.4 | I25: =IF(H25="","",IF(D25="","",IF(AND(H25=0,D25=0),0,H25/D25))) -> 0.54536585 | K25: 6.431985
A26: 8-00 | B26: 14264.501 | C26: =IF(B26="","",IF(LEN(TRUNC(B25,0))-LEN(TRUNC(B26,0))=0,B26-B25,IF(LEN(TRUNC(B25,0))-LEN(TRUNC(B26,0))>0,VALUE(LEFT(B25,LEN(TRUNC(B25,0))-LEN(TRUNC(B26,0))))*POWER(10,LEN(TRUNC(B26,0)))+B26-B25,B26-B25-VALUE(LEFT(B26,LEN(TRUNC(B26,0))-LEN(TRUNC(B25,0))))*POWER(10,LEN(TRUNC(B25,0)))))) -> 0.2185 | D26: =IF(C26="","",C26*$D$15) -> 3933 | F26: 7161.1277 | G26: =IF(F26="","",IF(LEN(TRUNC(F25,0))-LEN(TRUNC(F26,0))=0,F26-F25,IF(LEN(TRUNC(F25,0))-LEN(TRUNC(F26,0))>0,VALUE(LEFT(F25,LEN(TRUNC(F25,0))-LEN(TRUNC(F26,0))))*POWER(10,LEN(TRUNC(F26,0)))+F26-F25,F26-F25-VALUE(LEFT(F26,LEN(TRUNC(F26,0))-LEN(TRUNC(F25,0))))*POWER(10,LEN(TRUNC(F25,0)))))) -> 0.1144 | H26: =IF(G26="","",G26*$H$15) -> 2059.2 | I26: =IF(H26="","",IF(D26="","",IF(AND(H26=0,D26=0),0,H26/D26))) -> 0.52356979 | K26: 6.347073
A27: 9-00 | B27: 14264.733 | C27: =IF(B27="","",IF(LEN(TRUNC(B26,0))-LEN(TRUNC(B27,0))=0,B27-B26,IF(LEN(TRUNC(B26,0))-LEN(TRUNC(B27,0))>0,VALUE(LEFT(B26,LEN(TRUNC(B26,0))-LEN(TRUNC(B27,0))))*POWER(10,LEN(TRUNC(B27,0)))+B27-B26,B27-B26-VALUE(LEFT(B27,LEN(TRUNC(B27,0))-LEN(TRUNC(B26,0))))*POWER(10,LEN(TRUNC(B26,0)))))) -> 0.2324 | D27: =IF(C27="","",C27*$D$15) -> 4183.2 | F27: 7161.2457 | G27: =IF(F27="","",IF(LEN(TRUNC(F26,0))-LEN(TRUNC(F27,0))=0,F27-F26,IF(LEN(TRUNC(F26,0))-LEN(TRUNC(F27,0))>0,VALUE(LEFT(F26,LEN(TRUNC(F26,0))-LEN(TRUNC(F27,0))))*POWER(10,LEN(TRUNC(F27,0)))+F27-F26,F27-F26-VALUE(LEFT(F27,LEN(TRUNC(F27,0))-LEN(TRUNC(F26,0))))*POWER(10,LEN(TRUNC(F26,0)))))) -> 0.118 | H27: =IF(G27="","",G27*$H$15) -> 2124 | I27: =IF(H27="","",IF(D27="","",IF(AND(H27=0,D27=0),0,H27/D27))) -> 0.50774527 | K27: 6.213998
A28: 10-00 | B28: 14264.952 | C28: =IF(B28="","",IF(LEN(TRUNC(B27,0))-LEN(TRUNC(B28,0))=0,B28-B27,IF(LEN(TRUNC(B27,0))-LEN(TRUNC(B28,0))>0,VALUE(LEFT(B27,LEN(TRUNC(B27,0))-LEN(TRUNC(B28,0))))*POWER(10,LEN(TRUNC(B28,0)))+B28-B27,B28-B27-VALUE(LEFT(B28,LEN(TRUNC(B28,0))-LEN(TRUNC(B27,0))))*POWER(10,LEN(TRUNC(B27,0)))))) -> 0.2182 | D28: =IF(C28="","",C28*$D$15) -> 3927.6 | F28: 7161.3532 | G28: =IF(F28="","",IF(LEN(TRUNC(F27,0))-LEN(TRUNC(F28,0))=0,F28-F27,IF(LEN(TRUNC(F27,0))-LEN(TRUNC(F28,0))>0,VALUE(LEFT(F27,LEN(TRUNC(F27,0))-LEN(TRUNC(F28,0))))*POWER(10,LEN(TRUNC(F28,0)))+F28-F27,F28-F27-VALUE(LEFT(F28,LEN(TRUNC(F28,0))-LEN(TRUNC(F27,0))))*POWER(10,LEN(TRUNC(F27,0)))))) -> 0.1075 | H28: =IF(G28="","",G28*$H$15) -> 1935 | I28: =IF(H28="","",IF(D28="","",IF(AND(H28=0,D28=0),0,H28/D28))) -> 0.49266728 | K28: 6.167478
A29: 11-00 | B29: 14265.165 | C29: =IF(B29="","",IF(LEN(TRUNC(B28,0))-LEN(TRUNC(B29,0))=0,B29-B28,IF(LEN(TRUNC(B28,0))-LEN(TRUNC(B29,0))>0,VALUE(LEFT(B28,LEN(TRUNC(B28,0))-LEN(TRUNC(B29,0))))*POWER(10,LEN(TRUNC(B29,0)))+B29-B28,B29-B28-VALUE(LEFT(B29,LEN(TRUNC(B29,0))-LEN(TRUNC(B28,0))))*POWER(10,LEN(TRUNC(B28,0)))))) -> 0.2134 | D29: =IF(C29="","",C29*$D$15) -> 3841.2 | F29: 7161.459 | G29: =IF(F29="","",IF(LEN(TRUNC(F28,0))-LEN(TRUNC(F29,0))=0,F29-F28,IF(LEN(TRUNC(F28,0))-LEN(TRUNC(F29,0))>0,VALUE(LEFT(F28,LEN(TRUNC(F28,0))-LEN(TRUNC(F29,0))))*POWER(10,LEN(TRUNC(F29,0)))+F29-F28,F29-F28-VALUE(LEFT(F29,LEN(TRUNC(F29,0))-LEN(TRUNC(F28,0))))*POWER(10,LEN(TRUNC(F28,0)))))) -> 0.1058 | H29: =IF(G29="","",G29*$H$15) -> 1904.4 | I29: =IF(H29="","",IF(D29="","",IF(AND(H29=0,D29=0),0,H29/D29))) -> 0.49578257 | K29: 6.152082 | M29: Указать отдельно рабочие и запломбированные трансформаторы и высоковольтные электродвигатели
A30: 12-00 | B30: 14265.381 | C30: =IF(B30="","",IF(LEN(TRUNC(B29,0))-LEN(TRUNC(B30,0))=0,B30-B29,IF(LEN(TRUNC(B29,0))-LEN(TRUNC(B30,0))>0,VALUE(LEFT(B29,LEN(TRUNC(B29,0))-LEN(TRUNC(B30,0))))*POWER(10,LEN(TRUNC(B30,0)))+B30-B29,B30-B29-VALUE(LEFT(B30,LEN(TRUNC(B30,0))-LEN(TRUNC(B29,0))))*POWER(10,LEN(TRUNC(B29,0)))))) -> 0.2157 | D30: =IF(C30="","",C30*$D$15) -> 3882.6 | F30: 7161.5673 | G30: =IF(F30="","",IF(LEN(TRUNC(F29,0))-LEN(TRUNC(F30,0))=0,F30-F29,IF(LEN(TRUNC(F29,0))-LEN(TRUNC(F30,0))>0,VALUE(LEFT(F29,LEN(TRUNC(F29,0))-LEN(TRUNC(F30,0))))*POWER(10,LEN(TRUNC(F30,0)))+F30-F29,F30-F29-VALUE(LEFT(F30,LEN(TRUNC(F30,0))-LEN(TRUNC(F29,0))))*POWER(10,LEN(TRUNC(F29,0)))))) -> 0.1083 | H30: =IF(G30="","",G30*$H$15) -> 1949.4 | I30: =IF(H30="","",IF(D30="","",IF(AND(H30=0,D30=0),0,H30/D30))) -> 0.50208623 | K30: 6.171024 | M30: II. Статконденсаторы всех напряжений
A31: 13-00 | B31: 14265.59 | C31: =IF(B31="","",IF(LEN(TRUNC(B30,0))-LEN(TRUNC(B31,0))=0,B31-B30,IF(LEN(TRUNC(B30,0))-LEN(TRUNC(B31,0))>0,VALUE(LEFT(B30,LEN(TRUNC(B30,0))-LEN(TRUNC(B31,0))))*POWER(10,LEN(TRUNC(B31,0)))+B31-B30,B31-B30-VALUE(LEFT(B31,LEN(TRUNC(B31,0))-LEN(TRUNC(B30,0))))*POWER(10,LEN(TRUNC(B30,0)))))) -> 0.2097 | D31: =IF(C31="","",C31*$D$15) -> 3774.6 | F31: 7161.6725 | G31: =IF(F31="","",IF(LEN(TRUNC(F30,0))-LEN(TRUNC(F31,0))=0,F31-F30,IF(LEN(TRUNC(F30,0))-LEN(TRUNC(F31,0))>0,VALUE(LEFT(F30,LEN(TRUNC(F30,0))-LEN(TRUNC(F31,0))))*POWER(10,LEN(TRUNC(F31,0)))+F31-F30,F31-F30-VALUE(LEFT(F31,LEN(TRUNC(F31,0))-LEN(TRUNC(F30,0))))*POWER(10,LEN(TRUNC(F30,0)))))) -> 0.1052 | H31: =IF(G31="","",G31*$H$15) -> 1893.6 | I31: =IF(H31="","",IF(D31="","",IF(AND(H31=0,D31=0),0,H31/D31))) -> 0.50166905 | K31: 6.204159 | M31: №№ | N31: Место | P31: Номинальное | R31: Номинальная | T31: В т.ч. с | V31: Время включения | Y31: Примечание
A32: 14-00 | B32: 14265.802 | C32: =IF(B32="","",IF(LEN(TRUNC(B31,0))-LEN(TRUNC(B32,0))=0,B32-B31,IF(LEN(TRUNC(B31,0))-LEN(TRUNC(B32,0))>0,VALUE(LEFT(B31,LEN(TRUNC(B31,0))-LEN(TRUNC(B32,0))))*POWER(10,LEN(TRUNC(B32,0)))+B32-B31,B32-B31-VALUE(LEFT(B32,LEN(TRUNC(B32,0))-LEN(TRUNC(B31,0))))*POWER(10,LEN(TRUNC(B31,0)))))) -> 0.2117 | D32: =IF(C32="","",C32*$D$15) -> 3810.6 | F32: 7161.7822 | G32: =IF(F32="","",IF(LEN(TRUNC(F31,0))-LEN(TRUNC(F32,0))=0,F32-F31,IF(LEN(TRUNC(F31,0))-LEN(TRUNC(F32,0))>0,VALUE(LEFT(F31,LEN(TRUNC(F31,0))-LEN(TRUNC(F32,0))))*POWER(10,LEN(TRUNC(F32,0)))+F32-F31,F32-F31-VALUE(LEFT(F32,LEN(TRUNC(F32,0))-LEN(TRUNC(F31,0))))*POWER(10,LEN(TRUNC(F31,0)))))) -> 0.1097 | H32: =IF(G32="","",G32*$H$15) -> 1974.6 | I32: =IF(H32="","",IF(D32="","",IF(AND(H32=0,D32=0),0,H32/D32))) -> 0.51818611 | K32: 6.05011 | P32: напряжение | R32: мощность | T32: авторегулир. | V32: и отключения
A33: 15-00 | B33: 14266.015 | C33: =IF(B33="","",IF(LEN(TRUNC(B32,0))-LEN(TRUNC(B33,0))=0,B33-B32,IF(LEN(TRUNC(B32,0))-LEN(TRUNC(B33,0))>0,VALUE(LEFT(B32,LEN(TRUNC(B32,0))-LEN(TRUNC(B33,0))))*POWER(10,LEN(TRUNC(B33,0)))+B33-B32,B33-B32-VALUE(LEFT(B33,LEN(TRUNC(B33,0))-LEN(TRUNC(B32,0))))*POWER(10,LEN(TRUNC(B32,0)))))) -> 0.213 | D33: =IF(C33="","",C33*$D$15) -> 3834 | F33: 7161.8914 | G33: =IF(F33="","",IF(LEN(TRUNC(F32,0))-LEN(TRUNC(F33,0))=0,F33-F32,IF(LEN(TRUNC(F32,0))-LEN(TRUNC(F33,0))>0,VALUE(LEFT(F32,LEN(TRUNC(F32,0))-LEN(TRUNC(F33,0))))*POWER(10,LEN(TRUNC(F33,0)))+F33-F32,F33-F32-VALUE(LEFT(F33,LEN(TRUNC(F33,0))-LEN(TRUNC(F32,0))))*POWER(10,LEN(TRUNC(F32,0)))))) -> 0.1092 | H33: =IF(G33="","",G33*$H$15) -> 1965.6 | I33: =IF(H33="","",IF(D33="","",IF(AND(H33=0,D33=0),0,H33/D33))) -> 0.51267606 | K33: 6.020441 | M33: п/п | N33: установки | P33: кВ | R33: кВар | T33: кВар | V33: установки за сутки
A34: 16-00 | B34: 14266.232 | C34: =IF(B34="","",IF(LEN(TRUNC(B33,0))-LEN(TRUNC(B34,0))=0,B34-B33,IF(LEN(TRUNC(B33,0))-LEN(TRUNC(B34,0))>0,VALUE(LEFT(B33,LEN(TRUNC(B33,0))-LEN(TRUNC(B34,0))))*POWER(10,LEN(TRUNC(B34,0)))+B34-B33,B34-B33-VALUE(LEFT(B34,LEN(TRUNC(B34,0))-LEN(TRUNC(B33,0))))*POWER(10,LEN(TRUNC(B33,0)))))) -> 0.2167 | D34: =IF(C34="","",C34*$D$15) -> 3900.6 | F34: 7162.0019 | G34: =IF(F34="","",IF(LEN(TRUNC(F33,0))-LEN(TRUNC(F34,0))=0,F34-F33,IF(LEN(TRUNC(F33,0))-LEN(TRUNC(F34,0))>0,VALUE(LEFT(F33,LEN(TRUNC(F33,0))-LEN(TRUNC(F34,0))))*POWER(10,LEN(TRUNC(F34,0)))+F34-F33,F34-F33-VALUE(LEFT(F34,LEN(TRUNC(F34,0))-LEN(TRUNC(F33,0))))*POWER(10,LEN(TRUNC(F33,0)))))) -> 0.1105 | H34: =IF(G34="","",G34*$H$15) -> 1989 | I34: =IF(H34="","",IF(D34="","",IF(AND(H34=0,D34=0),0,H34/D34))) -> 0.50992155 | K34: 5.895202
A35: 17-00 | B35: 14266.447 | C35: =IF(B35="","",IF(LEN(TRUNC(B34,0))-LEN(TRUNC(B35,0))=0,B35-B34,IF(LEN(TRUNC(B34,0))-LEN(TRUNC(B35,0))>0,VALUE(LEFT(B34,LEN(TRUNC(B34,0))-LEN(TRUNC(B35,0))))*POWER(10,LEN(TRUNC(B35,0)))+B35-B34,B35-B34-VALUE(LEFT(B35,LEN(TRUNC(B35,0))-LEN(TRUNC(B34,0))))*POWER(10,LEN(TRUNC(B34,0)))))) -> 0.2154 | D35: =IF(C35="","",C35*$D$15) -> 3877.2 | F35: 7162.1122 | G35: =IF(F35="","",IF(LEN(TRUNC(F34,0))-LEN(TRUNC(F35,0))=0,F35-F34,IF(LEN(TRUNC(F34,0))-LEN(TRUNC(F35,0))>0,VALUE(LEFT(F34,LEN(TRUNC(F34,0))-LEN(TRUNC(F35,0))))*POWER(10,LEN(TRUNC(F35,0)))+F35-F34,F35-F34-VALUE(LEFT(F35,LEN(TRUNC(F35,0))-LEN(TRUNC(F34,0))))*POWER(10,LEN(TRUNC(F34,0)))))) -> 0.1103 | H35: =IF(G35="","",G35*$H$15) -> 1985.4 | I35: =IF(H35="","",IF(D35="","",IF(AND(H35=0,D35=0),0,H35/D35))) -> 0.51207057 | K35: 6.033041 | N35: КТП-22,23,24,25 | P35: 0.4 | R35: 696
A36: 18-00 | B36: 14266.65 | C36: =IF(B36="","",IF(LEN(TRUNC(B35,0))-LEN(TRUNC(B36,0))=0,B36-B35,IF(LEN(TRUNC(B35,0))-LEN(TRUNC(B36,0))>0,VALUE(LEFT(B35,LEN(TRUNC(B35,0))-LEN(TRUNC(B36,0))))*POWER(10,LEN(TRUNC(B36,0)))+B36-B35,B36-B35-VALUE(LEFT(B36,LEN(TRUNC(B36,0))-LEN(TRUNC(B35,0))))*POWER(10,LEN(TRUNC(B35,0)))))) -> 0.2032 | D36: =IF(C36="","",C36*$D$15) -> 3657.6 | F36: 7162.2181 | G36: =IF(F36="","",IF(LEN(TRUNC(F35,0))-LEN(TRUNC(F36,0))=0,F36-F35,IF(LEN(TRUNC(F35,0))-LEN(TRUNC(F36,0))>0,VALUE(LEFT(F35,LEN(TRUNC(F35,0))-LEN(TRUNC(F36,0))))*POWER(10,LEN(TRUNC(F36,0)))+F36-F35,F36-F35-VALUE(LEFT(F36,LEN(TRUNC(F36,0))-LEN(TRUNC(F35,0))))*POWER(10,LEN(TRUNC(F35,0)))))) -> 0.1059 | H36: =IF(G36="","",G36*$H$15) -> 1906.2 | I36: =IF(H36="","",IF(D36="","",IF(AND(H36=0,D36=0),0,H36/D36))) -> 0.52116142 | K36: 6.206874 | N36: РП-1 | P36: 6 | R36: 870
A37: 19-00 | B37: 14266.857 | C37: =IF(B37="","",IF(LEN(TRUNC(B36,0))-LEN(TRUNC(B37,0))=0,B37-B36,IF(LEN(TRUNC(B36,0))-LEN(TRUNC(B37,0))>0,VALUE(LEFT(B36,LEN(TRUNC(B36,0))-LEN(TRUNC(B37,0))))*POWER(10,LEN(TRUNC(B37,0)))+B37-B36,B37-B36-VALUE(LEFT(B37,LEN(TRUNC(B37,0))-LEN(TRUNC(B36,0))))*POWER(10,LEN(TRUNC(B36,0)))))) -> 0.2062 | D37: =IF(C37="","",C37*$D$15) -> 3711.6 | F37: 7162.3242 | G37: =IF(F37="","",IF(LEN(TRUNC(F36,0))-LEN(TRUNC(F37,0))=0,F37-F36,IF(LEN(TRUNC(F36,0))-LEN(TRUNC(F37,0))>0,VALUE(LEFT(F36,LEN(TRUNC(F36,0))-LEN(TRUNC(F37,0))))*POWER(10,LEN(TRUNC(F37,0)))+F37-F36,F37-F36-VALUE(LEFT(F37,LEN(TRUNC(F37,0))-LEN(TRUNC(F36,0))))*POWER(10,LEN(TRUNC(F36,0)))))) -> 0.1061 | H37: =IF(G37="","",G37*$H$15) -> 1909.8 | I37: =IF(H37="","",IF(D37="","",IF(AND(H37=0,D37=0),0,H37/D37))) -> 0.51454898 | K37: 6.177349
A38: 20-00 | B38: 14267.062 | C38: =IF(B38="","",IF(LEN(TRUNC(B37,0))-LEN(TRUNC(B38,0))=0,B38-B37,IF(LEN(TRUNC(B37,0))-LEN(TRUNC(B38,0))>0,VALUE(LEFT(B37,LEN(TRUNC(B37,0))-LEN(TRUNC(B38,0))))*POWER(10,LEN(TRUNC(B38,0)))+B38-B37,B38-B37-VALUE(LEFT(B38,LEN(TRUNC(B38,0))-LEN(TRUNC(B37,0))))*POWER(10,LEN(TRUNC(B37,0)))))) -> 0.2054 | D38: =IF(C38="","",C38*$D$15) -> 3697.2 | F38: 7162.4286 | G38: =IF(F38="","",IF(LEN(TRUNC(F37,0))-LEN(TRUNC(F38,0))=0,F38-F37,IF(LEN(TRUNC(F37,0))-LEN(TRUNC(F38,0))>0,VALUE(LEFT(F37,LEN(TRUNC(F37,0))-LEN(TRUNC(F38,0))))*POWER(10,LEN(TRUNC(F38,0)))+F38-F37,F38-F37-VALUE(LEFT(F38,LEN(TRUNC(F38,0))-LEN(TRUNC(F37,0))))*POWER(10,LEN(TRUNC(F37,0)))))) -> 0.1044 | H38: =IF(G38="","",G38*$H$15) -> 1879.2 | I38: =IF(H38="","",IF(D38="","",IF(AND(H38=0,D38=0),0,H38/D38))) -> 0.50827653 | K38: 6.189968
A39: 21-00 | B39: 14267.263 | C39: =IF(B39="","",IF(LEN(TRUNC(B38,0))-LEN(TRUNC(B39,0))=0,B39-B38,IF(LEN(TRUNC(B38,0))-LEN(TRUNC(B39,0))>0,VALUE(LEFT(B38,LEN(TRUNC(B38,0))-LEN(TRUNC(B39,0))))*POWER(10,LEN(TRUNC(B39,0)))+B39-B38,B39-B38-VALUE(LEFT(B39,LEN(TRUNC(B39,0))-LEN(TRUNC(B38,0))))*POWER(10,LEN(TRUNC(B38,0)))))) -> 0.2007 | D39: =IF(C39="","",C39*$D$15) -> 3612.6 | F39: 7162.5313 | G39: =IF(F39="","",IF(LEN(TRUNC(F38,0))-LEN(TRUNC(F39,0))=0,F39-F38,IF(LEN(TRUNC(F38,0))-LEN(TRUNC(F39,0))>0,VALUE(LEFT(F38,LEN(TRUNC(F38,0))-LEN(TRUNC(F39,0))))*POWER(10,LEN(TRUNC(F39,0)))+F39-F38,F39-F38-VALUE(LEFT(F39,LEN(TRUNC(F39,0))-LEN(TRUNC(F38,0))))*POWER(10,LEN(TRUNC(F38,0)))))) -> 0.1027 | H39: =IF(G39="","",G39*$H$15) -> 1848.6 | I39: =IF(H39="","",IF(D39="","",IF(AND(H39=0,D39=0),0,H39/D39))) -> 0.51170902 | K39: 6.24457
A40: 22-00 | B40: 14267.458 | C40: =IF(B40="","",IF(LEN(TRUNC(B39,0))-LEN(TRUNC(B40,0))=0,B40-B39,IF(LEN(TRUNC(B39,0))-LEN(TRUNC(B40,0))>0,VALUE(LEFT(B39,LEN(TRUNC(B39,0))-LEN(TRUNC(B40,0))))*POWER(10,LEN(TRUNC(B40,0)))+B40-B39,B40-B39-VALUE(LEFT(B40,LEN(TRUNC(B40,0))-LEN(TRUNC(B39,0))))*POWER(10,LEN(TRUNC(B39,0)))))) -> 0.1953 | D40: =IF(C40="","",C40*$D$15) -> 3515.4 | F40: 7162.6294 | G40: =IF(F40="","",IF(LEN(TRUNC(F39,0))-LEN(TRUNC(F40,0))=0,F40-F39,IF(LEN(TRUNC(F39,0))-LEN(TRUNC(F40,0))>0,VALUE(LEFT(F39,LEN(TRUNC(F39,0))-LEN(TRUNC(F40,0))))*POWER(10,LEN(TRUNC(F40,0)))+F40-F39,F40-F39-VALUE(LEFT(F40,LEN(TRUNC(F40,0))-LEN(TRUNC(F39,0))))*POWER(10,LEN(TRUNC(F39,0)))))) -> 0.0981 | H40: =IF(G40="","",G40*$H$15) -> 1765.8 | I40: =IF(H40="","",IF(D40="","",IF(AND(H40=0,D40=0),0,H40/D40))) -> 0.50230415 | K40: 6.297552 | M40: III. Синхронные электродвигатели напряжением до 1000 В
A41: 23-00 | B41: 14267.658 | C41: =IF(B41="","",IF(LEN(TRUNC(B40,0))-LEN(TRUNC(B41,0))=0,B41-B40,IF(LEN(TRUNC(B40,0))-LEN(TRUNC(B41,0))>0,VALUE(LEFT(B40,LEN(TRUNC(B40,0))-LEN(TRUNC(B41,0))))*POWER(10,LEN(TRUNC(B41,0)))+B41-B40,B41-B40-VALUE(LEFT(B41,LEN(TRUNC(B41,0))-LEN(TRUNC(B40,0))))*POWER(10,LEN(TRUNC(B40,0)))))) -> 0.2002 | D41: =IF(C41="","",C41*$D$15) -> 3603.6 | F41: 7162.7285 | G41: =IF(F41="","",IF(LEN(TRUNC(F40,0))-LEN(TRUNC(F41,0))=0,F41-F40,IF(LEN(TRUNC(F40,0))-LEN(TRUNC(F41,0))>0,VALUE(LEFT(F40,LEN(TRUNC(F40,0))-LEN(TRUNC(F41,0))))*POWER(10,LEN(TRUNC(F41,0)))+F41-F40,F41-F40-VALUE(LEFT(F41,LEN(TRUNC(F41,0))-LEN(TRUNC(F40,0))))*POWER(10,LEN(TRUNC(F40,0)))))) -> 0.0991 | H41: =IF(G41="","",G41*$H$15) -> 1783.8 | I41: =IF(H41="","",IF(D41="","",IF(AND(H41=0,D41=0),0,H41/D41))) -> 0.495005 | K41: 6.27785 | M41: №№ | N41: Место | P41: Номинальная | S41: № п-п | T41: Место установки | X41: Номинальная
A42: 24-00 | B42: 14267.853 | C42: =IF(B42="","",IF(LEN(TRUNC(B41,0))-LEN(TRUNC(B42,0))=0,B42-B41,IF(LEN(TRUNC(B41,0))-LEN(TRUNC(B42,0))>0,VALUE(LEFT(B41,LEN(TRUNC(B41,0))-LEN(TRUNC(B42,0))))*POWER(10,LEN(TRUNC(B42,0)))+B42-B41,B42-B41-VALUE(LEFT(B42,LEN(TRUNC(B42,0))-LEN(TRUNC(B41,0))))*POWER(10,LEN(TRUNC(B41,0)))))) -> 0.1948 | D42: =IF(C42="","",C42*$D$15) -> 3506.4 | F42: 7162.829 | G42: =IF(F42="","",IF(LEN(TRUNC(F41,0))-LEN(TRUNC(F42,0))=0,F42-F41,IF(LEN(TRUNC(F41,0))-LEN(TRUNC(F42,0))>0,VALUE(LEFT(F41,LEN(TRUNC(F41,0))-LEN(TRUNC(F42,0))))*POWER(10,LEN(TRUNC(F42,0)))+F42-F41,F42-F41-VALUE(LEFT(F42,LEN(TRUNC(F42,0))-LEN(TRUNC(F41,0))))*POWER(10,LEN(TRUNC(F41,0)))))) -> 0.1005 | H42: =IF(G42="","",G42*$H$15) -> 1809 | I42: =IF(H42="","",IF(D42="","",IF(AND(H42=0,D42=0),0,H42/D42))) -> 0.51591376 | K42: 6.317398
...

Sheet Ячейка 30
A1: ОАО "Пластик" | G1: Шифр | M1: I. Сведения о присоединенных трансформаторах и высоковольтных электродвигателях
A2: (наименование предприятия) | M2: 1. Трансформаторы
A3: г. Узловая, Тульская, 1 | G3: Питающий центр | I3: П/ст №167 (ГПП-1) | M3: №№ | N3: Место установки | P3: Мощность | R3: Номинальн. | T3: Включен. | V3: Назначение | X3: Примечание
A4: (адрес) | R4: напряжение | T4: на ответвление | V4: тр-ра
G5: № фидера | I5: яч 30 Воейково-2 | M5: п/п | P5: ква | R5: ________ кВ | T5: ________ кВ | V5: силов. освет.
A6: (министерство, ведомство) | V6: печной
A8: ПРОТОКОЛ (первичный)
A9: записей показания электросчетчиков и вольтметров, а также определение
A10: нагрузок и тангенса "фи" за | E10: 21 июня | H10: 2017года
A11: напряжения | E11: ______6000______________ | I11: вольт
A13: Время записи часы | B13: Активн. сч-к тип | D13: СЭТ-4ТМ.03 | F13: Реактивн. сч-к тип | H13: СЭТ-4ТМ.03 | I13: Тангенс "фи" | J13: Показание | L13: Мощность
B14: ____________л__ | D14: № 0808090624 | F14: ____________л__ | H14: № 0808090624 | J14: вольтметр. | L14: включен.
B15: Расчетн. коэф | D15: 12000 | F15: Расчетн. коэф | H15: 12000 | J15: на стороне | L15: компенсир.
B16: показ. | C16: разность | D16: расход за | F16: показ. | G16: разность | H16: расход за | J16: в\н | K16: н\н | L16: устройств
B17: сч-ка | C17: показ. | D17: час (кВт) | F17: сч-ка | G17: показ. | H17: час (кВт) | L17: кВар | M17: 2. Высоковольтные электродвигатели
A18: 0-00 | B18: 9274.7926 | F18: 5892.7028 | M18: №№ | N18: Место | Q18: Тип | T18: Номинальная | W18: Примечание
A19: 1-00 | B19: 9274.8786 | C19: =IF(B19="","",IF(LEN(TRUNC(B18,0))-LEN(TRUNC(B19,0))=0,B19-B18,IF(LEN(TRUNC(B18,0))-LEN(TRUNC(B19,0))>0,VALUE(LEFT(B18,LEN(TRUNC(B18,0))-LEN(TRUNC(B19,0))))*POWER(10,LEN(TRUNC(B19,0)))+B19-B18,B19-B18-VALUE(LEFT(B19,LEN(TRUNC(B19,0))-LEN(TRUNC(B18,0))))*POWER(10,LEN(TRUNC(B18,0)))))) -> 0.086 | D19: =IF(C19="","",C19*$D$15) -> 1032 | F19: 5892.7856 | G19: =F19-ReportObject3_3 -> 0.0828 | H19: =IF(G19="","",G19*$H$15) -> 993.6 | I19: =IF(H19="","",IF(D19="","",IF(AND(H19=0,D19=0),0,H19/D19))) -> 0.9627907 | K19: 6.326905 | Q19: (синхронный,
A20: 2-00 | B20: 9274.961 | C20: =IF(B20="","",IF(LEN(TRUNC(B19,0))-LEN(TRUNC(B20,0))=0,B20-B19,IF(LEN(TRUNC(B19,0))-LEN(TRUNC(B20,0))>0,VALUE(LEFT(B19,LEN(TRUNC(B19,0))-LEN(TRUNC(B20,0))))*POWER(10,LEN(TRUNC(B20,0)))+B20-B19,B20-B19-VALUE(LEFT(B20,LEN(TRUNC(B20,0))-LEN(TRUNC(B19,0))))*POWER(10,LEN(TRUNC(B19,0)))))) -> 0.0824 | D20: =IF(C20="","",C20*$D$15) -> 988.8 | F20: 5892.8684 | G20: =F20-F19 -> 0.0828 | H20: =IF(G20="","",G20*$H$15) -> 993.6 | I20: =IF(H20="","",IF(D20="","",IF(AND(H20=0,D20=0),0,H20/D20))) -> 1.0048544 | K20: 6.412437 | M20: п/п | N20: установки | Q20: асинхронный) | T20: мощность кВт
A21: 3-00 | B21: 9275.0416 | C21: =IF(B21="","",IF(LEN(TRUNC(B20,0))-LEN(TRUNC(B21,0))=0,B21-B20,IF(LEN(TRUNC(B20,0))-LEN(TRUNC(B21,0))>0,VALUE(LEFT(B20,LEN(TRUNC(B20,0))-LEN(TRUNC(B21,0))))*POWER(10,LEN(TRUNC(B21,0)))+B21-B20,B21-B20-VALUE(LEFT(B21,LEN(TRUNC(B21,0))-LEN(TRUNC(B20,0))))*POWER(10,LEN(TRUNC(B20,0)))))) -> 0.0806 | D21: =IF(C21="","",C21*$D$15) -> 967.2 | F21: 5892.9507 | G21: =F21-F20 -> 0.0823 | H21: =IF(G21="","",G21*$H$15) -> 987.6 | I21: =IF(H21="","",IF(D21="","",IF(AND(H21=0,D21=0),0,H21/D21))) -> 1.0210918 | K21: 6.418342
A22: 4-00 | B22: 9275.1223 | C22: =IF(B22="","",IF(LEN(TRUNC(B21,0))-LEN(TRUNC(B22,0))=0,B22-B21,IF(LEN(TRUNC(B21,0))-LEN(TRUNC(B22,0))>0,VALUE(LEFT(B21,LEN(TRUNC(B21,0))-LEN(TRUNC(B22,0))))*POWER(10,LEN(TRUNC(B22,0)))+B22-B21,B22-B21-VALUE(LEFT(B22,LEN(TRUNC(B22,0))-LEN(TRUNC(B21,0))))*POWER(10,LEN(TRUNC(B21,0)))))) -> 0.0807 | D22: =IF(C22="","",C22*$D$15) -> 968.4 | F22: 5893.0339 | G22: =F22-F21 -> 0.0832 | H22: =IF(G22="","",G22*$H$15) -> 998.4 | I22: =IF(H22="","",IF(D22="","",IF(AND(H22=0,D22=0),0,H22/D22))) -> 1.0309789 | K22: 6.240928
A23: 5-00 | B23: 9275.2005 | C23: =IF(B23="","",IF(LEN(TRUNC(B22,0))-LEN(TRUNC(B23,0))=0,B23-B22,IF(LEN(TRUNC(B22,0))-LEN(TRUNC(B23,0))>0,VALUE(LEFT(B22,LEN(TRUNC(B22,0))-LEN(TRUNC(B23,0))))*POWER(10,LEN(TRUNC(B23,0)))+B23-B22,B23-B22-VALUE(LEFT(B23,LEN(TRUNC(B23,0))-LEN(TRUNC(B22,0))))*POWER(10,LEN(TRUNC(B22,0)))))) -> 0.0782 | D23: =IF(C23="","",C23*$D$15) -> 938.4 | F23: 5893.1162 | G23: =F23-F22 -> 0.0823 | H23: =IF(G23="","",G23*$H$15) -> 987.6 | I23: =IF(H23="","",IF(D23="","",IF(AND(H23=0,D23=0),0,H23/D23))) -> 1.0524297 | K23: 6.461163
A24: 6-00 | B24: 9275.271 | C24: =IF(B24="","",IF(LEN(TRUNC(B23,0))-LEN(TRUNC(B24,0))=0,B24-B23,IF(LEN(TRUNC(B23,0))-LEN(TRUNC(B24,0))>0,VALUE(LEFT(B23,LEN(TRUNC(B23,0))-LEN(TRUNC(B24,0))))*POWER(10,LEN(TRUNC(B24,0)))+B24-B23,B24-B23-VALUE(LEFT(B24,LEN(TRUNC(B24,0))-LEN(TRUNC(B23,0))))*POWER(10,LEN(TRUNC(B23,0)))))) -> 0.0705 | D24: =IF(C24="","",C24*$D$15) -> 846 | F24: 5893.1943 | G24: =F24-F23 -> 0.0781 | H24: =IF(G24="","",G24*$H$15) -> 937.2 | I24: =IF(H24="","",IF(D24="","",IF(AND(H24=0,D24=0),0,H24/D24))) -> 1.1078014 | K24: 6.475829
A25: 7-00 | B25: 9275.3644 | C25: =IF(B25="","",IF(LEN(TRUNC(B24,0))-LEN(TRUNC(B25,0))=0,B25-B24,IF(LEN(TRUNC(B24,0))-LEN(TRUNC(B25,0))>0,VALUE(LEFT(B24,LEN(TRUNC(B24,0))-LEN(TRUNC(B25,0))))*POWER(10,LEN(TRUNC(B25,0)))+B25-B24,B25-B24-VALUE(LEFT(B25,LEN(TRUNC(B25,0))-LEN(TRUNC(B24,0))))*POWER(10,LEN(TRUNC(B24,0)))))) -> 0.0934 | D25: =IF(C25="","",C25*$D$15) -> 1120.8 | F25: 5893.2811 | G25: =F25-F24 -> 0.0868 | H25: =IF(G25="","",G25*$H$15) -> 1041.6 | I25: =IF(H25="","",IF(D25="","",IF(AND(H25=0,D25=0),0,H25/D25))) -> 0.92933619 | K25: 6.431985
A26: 8-00 | B26: 9275.4796 | C26: =IF(B26="","",IF(LEN(TRUNC(B25,0))-LEN(TRUNC(B26,0))=0,B26-B25,IF(LEN(TRUNC(B25,0))-LEN(TRUNC(B26,0))>0,VALUE(LEFT(B25,LEN(TRUNC(B25,0))-LEN(TRUNC(B26,0))))*POWER(10,LEN(TRUNC(B26,0)))+B26-B25,B26-B25-VALUE(LEFT(B26,LEN(TRUNC(B26,0))-LEN(TRUNC(B25,0))))*POWER(10,LEN(TRUNC(B25,0)))))) -> 0.1152 | D26: =IF(C26="","",C26*$D$15) -> 1382.4 | F26: 5893.3784 | G26: =F26-F25 -> 0.0973 | H26: =IF(G26="","",G26*$H$15) -> 1167.6 | I26: =IF(H26="","",IF(D26="","",IF(AND(H26=0,D26=0),0,H26/D26))) -> 0.84461806 | K26: 6.347073
A27: 9-00 | B27: 9275.6091 | C27: =IF(B27="","",IF(LEN(TRUNC(B26,0))-LEN(TRUNC(B27,0))=0,B27-B26,IF(LEN(TRUNC(B26,0))-LEN(TRUNC(B27,0))>0,VALUE(LEFT(B26,LEN(TRUNC(B26,0))-LEN(TRUNC(B27,0))))*POWER(10,LEN(TRUNC(B27,0)))+B27-B26,B27-B26-VALUE(LEFT(B27,LEN(TRUNC(B27,0))-LEN(TRUNC(B26,0))))*POWER(10,LEN(TRUNC(B26,0)))))) -> 0.1295 | D27: =IF(C27="","",C27*$D$15) -> 1554 | F27: 5893.4796 | G27: =F27-F26 -> 0.1012 | H27: =IF(G27="","",G27*$H$15) -> 1214.4 | I27: =IF(H27="","",IF(D27="","",IF(AND(H27=0,D27=0),0,H27/D27))) -> 0.78146718 | K27: 6.213998
A28: 10-00 | B28: 9275.7083 | C28: =IF(B28="","",IF(LEN(TRUNC(B27,0))-LEN(TRUNC(B28,0))=0,B28-B27,IF(LEN(TRUNC(B27,0))-LEN(TRUNC(B28,0))>0,VALUE(LEFT(B27,LEN(TRUNC(B27,0))-LEN(TRUNC(B28,0))))*POWER(10,LEN(TRUNC(B28,0)))+B28-B27,B28-B27-VALUE(LEFT(B28,LEN(TRUNC(B28,0))-LEN(TRUNC(B27,0))))*POWER(10,LEN(TRUNC(B27,0)))))) -> 0.0992 | D28: =IF(C28="","",C28*$D$15) -> 1190.4 | F28: 5893.5653 | G28: =F28-F27 -> 0.0857 | H28: =IF(G28="","",G28*$H$15) -> 1028.4 | I28: =IF(H28="","",IF(D28="","",IF(AND(H28=0,D28=0),0,H28/D28))) -> 0.86391129 | K28: 6.167478
