Workbook
Name ReportObject1_0: 'Ячейка 24'!$E$10
Name ReportObject1_1: 'Ячейка 24'!$H$10
Name ReportObject1_2: 'Ячейка 24'!$B$18
Name ReportObject1_3: 'Ячейка 24'!$F$18
Name ReportObject10_0: 'Ячейка 4'!$E$10
Name ReportObject10_1: 'Ячейка 4'!$H$10
Name ReportObject10_2: 'Ячейка 4'!$B$18
Name ReportObject10_3: 'Ячейка 4'!$F$18
Name ReportObject11_0: 'Ячейка 36'!$E$10
Name ReportObject11_1: 'Ячейка 36'!$H$10
Name ReportObject11_2: 'Ячейка 36'!$B$18
Name ReportObject11_3: 'Ячейка 36'!$F$18
Name ReportObject12_0: 'Ячейка 37'!$E$10
Name ReportObject12_1: 'Ячейка 37'!$H$10
Name ReportObject12_2: 'Ячейка 37'!$B$18
Name ReportObject12_3: 'Ячейка 37'!$F$18
Name ReportObject13_0: 'Ячейка 10'!$E$10
Name ReportObject13_1: 'Ячейка 10'!$H$10
Name ReportObject13_2: 'Ячейка 10'!$B$18
Name ReportObject13_3: 'Ячейка 10'!$F$18
Name ReportObject14_0: 'Ячейка 16'!$E$10
Name ReportObject14_1: 'Ячейка 16'!$H$10
Name ReportObject14_2: 'Ячейка 16'!$B$18
Name ReportObject14_3: 'Ячейка 16'!$F$18
Name ReportObject15_0: 'Ячейка 14 '!$E$10
Name ReportObject15_1: 'Ячейка 14 '!$H$10
Name ReportObject15_2: 'Ячейка 14 '!$B$18
Name ReportObject15_3: 'Ячейка 14 '!$F$18
Name ReportObject16_0: 'Ячейка 13Л'!$E$10
Name ReportObject16_1: 'Ячейка 13Л'!$H$10
Name ReportObject16_2: 'Ячейка 13Л'!$B$18
Name ReportObject16_3: 'Ячейка 13Л'!$F$18
Name ReportObject17_0: 'Ячейка 32Л'!$E$10
Name ReportObject17_1: 'Ячейка 32Л'!$H$10
Name ReportObject17_2: 'Ячейка 32Л'!$B$18
Name ReportObject17_3: 'Ячейка 32Л'!$F$18
Name ReportObject18_0: 'ячейка 25Л'!$E$10
Name ReportObject18_1: 'ячейка 25Л'!$H$10
Name ReportObject18_2: 'ячейка 25Л'!$B$18
Name ReportObject18_3: 'ячейка 25Л'!$F$18
Name ReportObject2_0: 'Ячейка 2'!$E$10
Name ReportObject2_1: 'Ячейка 2'!$H$10
Name ReportObject2_2: 'Ячейка 2'!$B$18
Name ReportObject2_3: 'Ячейка 2'!$F$18
Name ReportObject3_0: 'Ячейка 30'!$E$10
Name ReportObject3_1: 'Ячейка 30'!$H$10
Name ReportObject3_2: 'Ячейка 30'!$B$18
Name ReportObject3_3: 'Ячейка 30'!$F$18
Name ReportObject4_0: 'Ячейка 27'!$E$10
Name ReportObject4_1: 'Ячейка 27'!$H$10
Name ReportObject4_2: 'Ячейка 27'!$B$18
Name ReportObject4_3: 'Ячейка 27'!$F$18
Name ReportObject5_0: 'Ячейка 3Гео'!$E$10
Name ReportObject5_1: 'Ячейка 3Гео'!$H$10
Name ReportObject5_2: 'Ячейка 3Гео'!$B$18
Name ReportObject5_3: 'Ячейка 3Гео'!$F$18
Name ReportObject6_0: 'Ячейка 26Гео '!$E$10
Name ReportObject6_1: 'Ячейка 26Гео '!$H$10
Name ReportObject6_2: 'Ячейка 26Гео '!$B$18
Name ReportObject6_3: 'Ячейка 26Гео '!$F$18

Sheet ObserverReportInfo_&!()$bbQ
A1: Режимный день
A2: TYPE2 | B2: HOUR | C2: 25 | D2: 1 | E2: H | F2: 1 | G2: MAIN | K2: EXCEL | M2: 4 | W2: 1
A3: MAINSHEET | B3: 2
A4: DATE | B4: 10 | C4: 5 | D4: dd mmmm | F4: BEGIN | O4: NOSHIFT
A5: DATE | B5: 10 | C5: 8 | D5: yyyy года | F5: BEGIN | O5: NOSHIFT
A6: COLUMN | B6: 18 | C6: 2 | E6: 692 | G6: RESNONE | J6: NONE | K6: CHN | M6: BEGINVALUE | N6: 0 | O6: 480 | P6: 4 | T6: ZONENAMES | Z6: RESULT_CAPTIONS | AF6: -1 | AG6: 0 | AO6: NOSHIFT | AT6: 0 | AV6: 61 | AW6: NOCHANGE | BC6: CUTDATEBEGIN | BI6: 4 | BJ6: 0 | BK6: 0 | BL6: 1 | BM6: 0
A7: COLUMN | B7: 18 | C7: 6 | E7: 694 | G7: RESNONE | J7: NONE | K7: CHN | M7: BEGINVALUE | N7: 0 | O7: 480 | P7: 4 | T7: ZONENAMES | Z7: RESULT_CAPTIONS | AF7: -1 | AG7: 0 | AO7: NOSHIFT | AT7: 0 | AV7: 95 | AW7: NOCHANGE | BC7: CUTDATEBEGIN | BE7: ENLIKEPOW | BI7: 8 | BJ7: 0 | BK7: 0 | BL7: 1 | BM7: 0
A8: MAINSHEET | B8: 3
A9: DATE | B9: 10 | C9: 5 | D9: dd mmmm | F9: BEGIN | O9: NOSHIFT
A10: DATE | B10: 10 | C10: 8 | D10: yyyy года | F10: BEGIN | O10: NOSHIFT
A11: COLUMN | B11: 18 | C11: 2 | E11: 687 | G11: RESNONE | J11: NONE | K11: CHN | M11: BEGINVALUE | N11: 0 | O11: 483 | P11: 4 | T11: ZONENAMES | Z11: RESULT_CAPTIONS | AF11: -1 | AG11: 0 | AO11: NOSHIFT | AT11: 0 | AV11: 61 | AW11: NOCHANGE | BC11: CUTDATEBEGIN | BI11: 4 | BJ11: 0 | BK11: 0 | BL11: 1 | BM11: 0
A12: COLUMN | B12: 18 | C12: 6 | E12: 689 | G12: RESNONE | J12: NONE | K12: CHN | M12: BEGINVALUE | N12: 0 | O12: 483 | P12: 4 | T12: ZONENAMES | Z12: RESULT_CAPTIONS | AF12: -1 | AG12: 0 | AO12: NOSHIFT | AT12: 0 | AV12: 95 | AW12: NOCHANGE | BC12: CUTDATEBEGIN | BE12: ENLIKEPOW | BI12: 8 | BJ12: 0 | BK12: 0 | BL12: 1 | BM12: 0
A13: MAINSHEET | B13: 4
A14: DATE | B14: 10 | C14: 5 | D14: dd mmmm | F14: BEGIN | O14: NOSHIFT
A15: DATE | B15: 10 | C15: 8 | D15: yyyy года | F15: BEGIN | O15: NOSHIFT
A16: COLUMN | B16: 18 | C16: 2 | E16: 702 | G16: RESNONE | J16: NONE | K16: CHN | M16: BEGINVALUE | N16: 0 | O16: 484 | P16: 4 | T16: ZONENAMES | Z16: RESULT_CAPTIONS | AF16: -1 | AG16: 0 | AO16: NOSHIFT | AT16: 0 | AV16: 61 | AW16: NOCHANGE | BC16: CUTDATEBEGIN | BI16: 4 | BJ16: 0 | BK16: 0 | BL16: 1 | BM16: 0
A17: COLUMN | B17: 18 | C17: 6 | E17: 704 | G17: RESNONE | J17: NONE | K17: CHN | M17: BEGINVALUE | N17: 0 | O17: 484 | P17: 4 | T17: ZONENAMES | Z17: RESULT_CAPTIONS | AF17: -1 | AG17: 0 | AO17: NOSHIFT | AT17: 0 | AV17: 95 | AW17: NOCHANGE | BC17: CUTDATEBEGIN | BE17: ENLIKEPOW | BI17: 8 | BJ17: 0 | BK17: 0 | BL17: 1 | BM17: 0
A18: MAINSHEET | B18: 5
A19: DATE | B19: 10 | C19: 5 | D19: dd mmmm | F19: BEGIN | O19: NOSHIFT
A20: DATE | B20: 10 | C20: 8 | D20: yyyy года | F20: BEGIN | O20: NOSHIFT
A21: COLUMN | B21: 18 | C21: 2 | E21: 697 | G21: RESNONE | J21: NONE | K21: CHN | M21: BEGINVALUE | N21: 0 | O21: 481 | P21: 4 | T21: ZONENAMES | Z21: RESULT_CAPTIONS | AF21: -1 | AG21: 0 | AO21: NOSHIFT | AT21: 0 | AV21: 61 | AW21: NOCHANGE | BC21: CUTDATEBEGIN | BI21: 4 | BJ21: 0 | BK21: 0 | BL21: 1 | BM21: 0
A22: COLUMN | B22: 18 | C22: 6 | E22: 699 | G22: RESNONE | J22: NONE | K22: CHN | M22: BEGINVALUE | N22: 0 | O22: 481 | P22: 4 | T22: ZONENAMES | Z22: RESULT_CAPTIONS | AF22: -1 | AG22: 0 | AO22: NOSHIFT | AT22: 0 | AV22: 95 | AW22: NOCHANGE | BC22: CUTDATEBEGIN | BE22: ENLIKEPOW | BI22: 8 | BJ22: 0 | BK22: 0 | BL22: 1 | BM22: 0
A23: MAINSHEET | B23: 6
A24: DATE | B24: 10 | C24: 5 | D24: dd mmmm | F24: BEGIN | O24: NOSHIFT
A25: DATE | B25: 10 | C25: 8 | D25: yyyy года | F25: BEGIN | O25: NOSHIFT
A26: COLUMN | B26: 18 | C26: 2 | E26: 1786 | G26: RESNONE | J26: NONE | K26: CHN | M26: BEGINVALUE | N26: 0 | O26: 790 | P26: 4 | T26: ZONENAMES | Z26: RESULT_CAPTIONS | AF26: -1 | AG26: 0 | AO26: NOSHIFT | AT26: 0 | AV26: 61 | AW26: NOCHANGE | BC26: CUTDATEBEGIN | BI26: 4 | BJ26: 0 | BK26: 0 | BL26: 1 | BM26: 0
A27: COLUMN | B27: 18 | C27: 6 | E27: 1788 | G27: RESNONE | J27: NONE | K27: CHN | M27: BEGINVALUE | N27: 0 | O27: 790 | P27: 4 | T27: ZONENAMES | Z27: RESULT_CAPTIONS | AF27: -1 | AG27: 0 | AO27: NOSHIFT | AT27: 0 | AV27: 95 | AW27: NOCHANGE | BC27: CUTDATEBEGIN | BE27: ENLIKEPOW | BI27: 8 | BJ27: 0 | BK27: 0 | BL27: 1 | BM27: 0
A28: MAINSHEET | B28: 7
A29: DATE | B29: 10 | C29: 5 | D29: dd mmmm | F29: BEGIN | O29: NOSHIFT
A30: DATE | B30: 10 | C30: 8 | D30: yyyy года | F30: BEGIN | O30: NOSHIFT
A31: COLUMN | B31: 18 | C31: 2 | E31: 1769 | G31: RESNONE | J31: NONE | K31: CHN | M31: BEGINVALUE | N31: 0 | O31: 784 | P31: 4 | T31: ZONENAMES | Z31: RESULT_CAPTIONS | AF31: -1 | AG31: 0 | AO31: NOSHIFT | AT31: 0 | AV31: 61 | AW31: NOCHANGE | BC31: CUTDATEBEGIN | BI31: 4 | BJ31: 0 | BK31: 0 | BL31: 1 | BM31: 0
A32: COLUMN | B32: 18 | C32: 6 | E32: 1771 | G32: RESNONE | J32: NONE | K32: CHN | M32: BEGINVALUE | N32: 0 | O32: 784 | P32: 4 | T32: ZONENAMES | Z32: RESULT_CAPTIONS | AF32: -1 | AG32: 0 | AO32: NOSHIFT | AT32: 0 | AV32: 95 | AW32: NOCHANGE | BC32: CUTDATEBEGIN | BE32: ENLIKEPOW | BI32: 8 | BJ32: 0 | BK32: 0 | BL32: 1 | BM32: 0
A33: MAINSHEET | B33: 8
A34: DATE | B34: 10 | C34: 5 | D34: dd mmmm | F34: BEGIN | O34: NOSHIFT
A35: DATE | B35: 10 | C35: 8 | D35: yyyy года | F35: BEGIN | O35: NOSHIFT
A36: COLUMN | B36: 18 | C36: 2 | E36: 117 | G36: RESNONE | J36: NONE | K36: CHN | M36: BEGINVALUE | N36: 0 | O36: 201 | P36: 4 | T36: ZONENAMES | Z36: RESULT_CAPTIONS | AF36: -1 | AG36: 0 | AO36: NOSHIFT | AT36: 0 | AV36: 61 | AW36: NOCHANGE | BC36: CUTDATEBEGIN | BI36: 4 | BJ36: 0 | BK36: 0 | BL36: 1 | BM36: 0
A37: COLUMN | B37: 18 | C37: 6 | E37: 119 | G37: RESNONE | J37: NONE | K37: CHN | M37: BEGINVALUE | N37: 0 | O37: 201 | P37: 4 | T37: ZONENAMES | Z37: RESULT_CAPTIONS | AF37: -1 | AG37: 0 | AO37: NOSHIFT | AT37: 0 | AV37: 95 | AW37: NOCHANGE | BC37: CUTDATEBEGIN | BE37: ENLIKEPOW | BI37: 8 | BJ37: 0 | BK37: 0 | BL37: 1 | BM37: 0
A38: MAINSHEET | B38: 9
A39: DATE | B39: 10 | C39: 5 | D39: dd mmmm | F39: BEGIN | O39: NOSHIFT
A40: DATE | B40: 10 | C40: 8 | D40: yyyy года | F40: BEGIN | O40: NOSHIFT
...

Sheet Ячейка 24
A1: ОАО "Пластик" | G1: Шифр | M1: I. Сведения о присоединенных трансформаторах и высоковольтных электродвигателях
A2: (наименование предприятия) | M2: 1. Трансформаторы
A3: г. Узловая, Тульская, 1 | G3: Питающий центр | I3: П/ст №167 (ГПП-1) | M3: №№ | N3: Место установки | P3: Мощность | R3: Номинальн. | T3: Включен. | V3: Назначение | X3: Примечание
A4: (адрес) | R4: напряжение | T4: на ответвление | V4: тр-ра
G5: № фидера | I5: яч 24 тр-р №1 | M5: п/п | P5: ква | R5: ________ кВ | T5: ________ кВ | V5: силов. освет.
A6: (министерство, ведомство) | V6: печной
A8: ПРОТОКОЛ (первичный)
A9: записей показания электросчетчиков и вольтметров, а также определение
A10: нагрузок и тангенса "фи" за | E10: 18 Декабрь | H10: 2013 года
A11: напряжения | E11: ______6000_____________ | I11: вольт
A13: Время записи часы | B13: Активн. сч-к тип | D13: СЭТ-4ТМ.03 | F13: Реактивн. сч-к тип | H13: СЭТ-4ТМ.03 | I13: Тангенс "фи" | J13: Показание | L13: Мощность
B14: ____________л__ | D14: № 812091210 | F14: ____________л__ | H14: №812091210 | J14: вольтметр. | L14: включен.
B15: Расчетн. коэф | D15: 18000 | F15: Расчетн. коэф | H15: 18000 | J15: на стороне | L15: компенсир.
B16: показ. | C16: разность | D16: расход за | F16: показ. | G16: разность | H16: расход за | J16: в\н | K16: н\н | L16: устройств
B17: сч-ка | C17: показ. | D17: час (кВт) | F17: сч-ка | G17: показ. | H17: час (кВт) | L17: кВар | M17: 2. Высоковольтные электродвигатели
A18: 0-00 | B18: 3499.2466 | F18: 1295.7374 | K18: 6.5 | M18: №№ | N18: Место | Q18: Тип | T18: Номинальная | W18: Примечание
A19: 1-00 | B19: 3499.3317 | C19: =IF(B19="","",IF(LEN(TRUNC(B18,0))-LEN(TRUNC(B19,0))=0,B19-B18,IF(LEN(TRUNC(B18,0))-LEN(TRUNC(B19,0))>0,VALUE(LEFT(B18,LEN(TRUNC(B18,0))-LEN(TRUNC(B19,0))))*POWER(10,LEN(TRUNC(B19,0)))+B19-B18,B19-B18-VALUE(LEFT(B19,LEN(TRUNC(B19,0))-LEN(TRUNC(B18,0))))*POWER(10,LEN(TRUNC(B18,0)))))) -> 0.0851 | D19: =IF(C19="","",C19*$D$15) -> 1531.8 | F19: 1295.7784 | G19: =IF(F19="","",IF(LEN(TRUNC(F18,0))-LEN(TRUNC(F19,0))=0,F19-F18,IF(LEN(TRUNC(F18,0))-LEN(TRUNC(F19,0))>0,VALUE(LEFT(F18,LEN(TRUNC(F18,0))-LEN(TRUNC(F19,0))))*POWER(10,LEN(TRUNC(F19,0)))+F19-F18,F19-F18-VALUE(LEFT(F19,LEN(TRUNC(F19,0))-LEN(TRUNC(F18,0))))*POWER(10,LEN(TRUNC(F18,0)))))) -> 0.041 | H19: =IF(G19="","",G19*$H$15) -> 738 | I19: =IF(H19="","",IF(D19="","",IF(AND(H19=0,D19=0),0,H19/D19))) -> 0.48178613 | K19: 6.5 | Q19: (синхронный,
A20: 2-00 | B20: 3499.4171 | C20: =IF(B20="","",IF(LEN(TRUNC(B19,0))-LEN(TRUNC(B20,0))=0,B20-B19,IF(LEN(TRUNC(B19,0))-LEN(TRUNC(B20,0))>0,VALUE(LEFT(B19,LEN(TRUNC(B19,0))-LEN(TRUNC(B20,0))))*POWER(10,LEN(TRUNC(B20,0)))+B20-B19,B20-B19-VALUE(LEFT(B20,LEN(TRUNC(B20,0))-LEN(TRUNC(B19,0))))*POWER(10,LEN(TRUNC(B19,0)))))) -> 0.0854 | D20: =IF(C20="","",C20*$D$15) -> 1537.2 | F20: 1295.8197 | G20: =IF(F20="","",IF(LEN(TRUNC(F19,0))-LEN(TRUNC(F20,0))=0,F20-F19,IF(LEN(TRUNC(F19,0))-LEN(TRUNC(F20,0))>0,VALUE(LEFT(F19,LEN(TRUNC(F19,0))-LEN(TRUNC(F20,0))))*POWER(10,LEN(TRUNC(F20,0)))+F20-F19,F20-F19-VALUE(LEFT(F20,LEN(TRUNC(F20,0))-LEN(TRUNC(F19,0))))*POWER(10,LEN(TRUNC(F19,0)))))) -> 0.0413 | H20: =IF(G20="","",G20*$H$15) -> 743.4 | I20: =IF(H20="","",IF(D20="","",IF(AND(H20=0,D20=0),0,H20/D20))) -> 0.48360656 | K20: 6.5 | M20: п/п | N20: установки | Q20: асинхронный) | T20: мощность кВт
A21: 3-00 | B21: 3499.5023 | C21: =IF(B21="","",IF(LEN(TRUNC(B20,0))-LEN(TRUNC(B21,0))=0,B21-B20,IF(LEN(TRUNC(B20,0))-LEN(TRUNC(B21,0))>0,VALUE(LEFT(B20,LEN(TRUNC(B20,0))-LEN(TRUNC(B21,0))))*POWER(10,LEN(TRUNC(B21,0)))+B21-B20,B21-B20-VALUE(LEFT(B21,LEN(TRUNC(B21,0))-LEN(TRUNC(B20,0))))*POWER(10,LEN(TRUNC(B20,0)))))) -> 0.0852 | D21: =IF(C21="","",C21*$D$15) -> 1533.6 | F21: 1295.8615 | G21: =IF(F21="","",IF(LEN(TRUNC(F20,0))-LEN(TRUNC(F21,0))=0,F21-F20,IF(LEN(TRUNC(F20,0))-LEN(TRUNC(F21,0))>0,VALUE(LEFT(F20,LEN(TRUNC(F20,0))-LEN(TRUNC(F21,0))))*POWER(10,LEN(TRUNC(F21,0)))+F21-F20,F21-F20-VALUE(LEFT(F21,LEN(TRUNC(F21,0))-LEN(TRUNC(F20,0))))*POWER(10,LEN(TRUNC(F20,0)))))) -> 0.0418 | H21: =IF(G21="","",G21*$H$15) -> 752.4 | I21: =IF(H21="","",IF(D21="","",IF(AND(H21=0,D21=0),0,H21/D21))) -> 0.49061033 | K21: 6.5
A22: 4-00 | B22: 3499.5868 | C22: =IF(B22="","",IF(LEN(TRUNC(B21,0))-LEN(TRUNC(B22,0))=0,B22-B21,IF(LEN(TRUNC(B21,0))-LEN(TRUNC(B22,0))>0,VALUE(LEFT(B21,LEN(TRUNC(B21,0))-LEN(TRUNC(B22,0))))*POWER(10,LEN(TRUNC(B22,0)))+B22-B21,B22-B21-VALUE(LEFT(B22,LEN(TRUNC(B22,0))-LEN(TRUNC(B21,0))))*POWER(10,LEN(TRUNC(B21,0)))))) -> 0.0845 | D22: =IF(C22="","",C22*$D$15) -> 1521 | F22: 1295.9026 | G22: =IF(F22="","",IF(LEN(TRUNC(F21,0))-LEN(TRUNC(F22,0))=0,F22-F21,IF(LEN(TRUNC(F21,0))-LEN(TRUNC(F22,0))>0,VALUE(LEFT(F21,LEN(TRUNC(F21,0))-LEN(TRUNC(F22,0))))*POWER(10,LEN(TRUNC(F22,0)))+F22-F21,F22-F21-VALUE(LEFT(F22,LEN(TRUNC(F22,0))-LEN(TRUNC(F21,0))))*POWER(10,LEN(TRUNC(F21,0)))))) -> 0.0411 | H22: =IF(G22="","",G22*$H$15) -> 739.8 | I22: =IF(H22="","",IF(D22="","",IF(AND(H22=0,D22=0),0,H22/D22))) -> 0.48639053 | K22: 6.5
A23: 5-00 | B23: 3499.6704 | C23: =IF(B23="","",IF(LEN(TRUNC(B22,0))-LEN(TRUNC(B23,0))=0,B23-B22,IF(LEN(TRUNC(B22,0))-LEN(TRUNC(B23,0))>0,VALUE(LEFT(B22,LEN(TRUNC(B22,0))-LEN(TRUNC(B23,0))))*POWER(10,LEN(TRUNC(B23,0)))+B23-B22,B23-B22-VALUE(LEFT(B23,LEN(TRUNC(B23,0))-LEN(TRUNC(B22,0))))*POWER(10,LEN(TRUNC(B22,0)))))) -> 0.0836 | D23: =IF(C23="","",C23*$D$15) -> 1504.8 | F23: 1295.9424 | G23: =IF(F23="","",IF(LEN(TRUNC(F22,0))-LEN(TRUNC(F23,0))=0,F23-F22,IF(LEN(TRUNC(F22,0))-LEN(TRUNC(F23,0))>0,VALUE(LEFT(F22,LEN(TRUNC(F22,0))-LEN(TRUNC(F23,0))))*POWER(10,LEN(TRUNC(F23,0)))+F23-F22,F23-F22-VALUE(LEFT(F23,LEN(TRUNC(F23,0))-LEN(TRUNC(F22,0))))*POWER(10,LEN(TRUNC(F22,0)))))) -> 0.0398 | H23: =IF(G23="","",G23*$H$15) -> 716.4 | I23: =IF(H23="","",IF(D23="","",IF(AND(H23=0,D23=0),0,H23/D23))) -> 0.47607656 | K23: 6.5
A24: 6-00 | B24: 3499.7559 | C24: =IF(B24="","",IF(LEN(TRUNC(B23,0))-LEN(TRUNC(B24,0))=0,B24-B23,IF(LEN(TRUNC(B23,0))-LEN(TRUNC(B24,0))>0,VALUE(LEFT(B23,LEN(TRUNC(B23,0))-LEN(TRUNC(B24,0))))*POWER(10,LEN(TRUNC(B24,0)))+B24-B23,B24-B23-VALUE(LEFT(B24,LEN(TRUNC(B24,0))-LEN(TRUNC(B23,0))))*POWER(10,LEN(TRUNC(B23,0)))))) -> 0.0855 | D24: =IF(C24="","",C24*$D$15) -> 1539 | F24: 1295.9805 | G24: =IF(F24="","",IF(LEN(TRUNC(F23,0))-LEN(TRUNC(F24,0))=0,F24-F23,IF(LEN(TRUNC(F23,0))-LEN(TRUNC(F24,0))>0,VALUE(LEFT(F23,LEN(TRUNC(F23,0))-LEN(TRUNC(F24,0))))*POWER(10,LEN(TRUNC(F24,0)))+F24-F23,F24-F23-VALUE(LEFT(F24,LEN(TRUNC(F24,0))-LEN(TRUNC(F23,0))))*POWER(10,LEN(TRUNC(F23,0)))))) -> 0.0381 | H24: =IF(G24="","",G24*$H$15) -> 685.8 | I24: =IF(H24="","",IF(D24="","",IF(AND(H24=0,D24=0),0,H24/D24))) -> 0.44561404 | K24: 6.5
A25: 7-00 | B25: 3499.8444 | C25: =IF(B25="","",IF(LEN(TRUNC(B24,0))-LEN(TRUNC(B25,0))=0,B25-B24,IF(LEN(TRUNC(B24,0))-LEN(TRUNC(B25,0))>0,VALUE(LEFT(B24,LEN(TRUNC(B24,0))-LEN(TRUNC(B25,0))))*POWER(10,LEN(TRUNC(B25,0)))+B25-B24,B25-B24-VALUE(LEFT(B25,LEN(TRUNC(B25,0))-LEN(TRUNC(B24,0))))*POWER(10,LEN(TRUNC(B24,0)))))) -> 0.0885 | D25: =IF(C25="","",C25*$D$15) -> 1593 | F25: 1296.0175 | G25: =IF(F25="","",IF(LEN(TRUNC(F24,0))-LEN(TRUNC(F25,0))=0,F25-F24,IF(LEN(TRUNC(F24,0))-LEN(TRUNC(F25,0))>0,VALUE(LEFT(F24,LEN(TRUNC(F24,0))-LEN(TRUNC(F25,0))))*POWER(10,LEN(TRUNC(F25,0)))+F25-F24,F25-F24-VALUE(LEFT(F25,LEN(TRUNC(F25,0))-LEN(TRUNC(F24,0))))*POWER(10,LEN(TRUNC(F24,0)))))) -> 0.037 | H25: =IF(G25="","",G25*$H$15) -> 666 | I25: =IF(H25="","",IF(D25="","",IF(AND(H25=0,D25=0),0,H25/D25))) -> 0.4180791 | K25: 6.5
A26: 8-00 | B26: 3499.9368 | C26: =IF(B26="","",IF(LEN(TRUNC(B25,0))-LEN(TRUNC(B26,0))=0,B26-B25,IF(LEN(TRUNC(B25,0))-LEN(TRUNC(B26,0))>0,VALUE(LEFT(B25,LEN(TRUNC(B25,0))-LEN(TRUNC(B26,0))))*POWER(10,LEN(TRUNC(B26,0)))+B26-B25,B26-B25-VALUE(LEFT(B26,LEN(TRUNC(B26,0))-LEN(TRUNC(B25,0))))*POWER(10,LEN(TRUNC(B25,0)))))) -> 0.0924 | D26: =IF(C26="","",C26*$D$15) -> 1663.2 | F26: 1296.0557 | G26: =IF(F26="","",IF(LEN(TRUNC(F25,0))-LEN(TRUNC(F26,0))=0,F26-F25,IF(LEN(TRUNC(F25,0))-LEN(TRUNC(F26,0))>0,VALUE(LEFT(F25,LEN(TRUNC(F25,0))-LEN(TRUNC(F26,0))))*POWER(10,LEN(TRUNC(F26,0)))+F26-F25,F26-F25-VALUE(LEFT(F26,LEN(TRUNC(F26,0))-LEN(TRUNC(F25,0))))*POWER(10,LEN(TRUNC(F25,0)))))) -> 0.0382 | H26: =IF(G26="","",G26*$H$15) -> 687.6 | I26: =IF(H26="","",IF(D26="","",IF(AND(H26=0,D26=0),0,H26/D26))) -> 0.41341991 | K26: 6.5
A27: 9-00 | B27: 3500.0377 | C27: =IF(B27="","",IF(LEN(TRUNC(B26,0))-LEN(TRUNC(B27,0))=0,B27-B26,IF(LEN(TRUNC(B26,0))-LEN(TRUNC(B27,0))>0,VALUE(LEFT(B26,LEN(TRUNC(B26,0))-LEN(TRUNC(B27,0))))*POWER(10,LEN(TRUNC(B27,0)))+B27-B26,B27-B26-VALUE(LEFT(B27,LEN(TRUNC(B27,0))-LEN(TRUNC(B26,0))))*POWER(10,LEN(TRUNC(B26,0)))))) -> 0.1009 | D27: =IF(C27="","",C27*$D$15) -> 1816.2 | F27: 1296.1028 | G27: =IF(F27="","",IF(LEN(TRUNC(F26,0))-LEN(TRUNC(F27,0))=0,F27-F26,IF(LEN(TRUNC(F26,0))-LEN(TRUNC(F27,0))>0,VALUE(LEFT(F26,LEN(TRUNC(F26,0))-LEN(TRUNC(F27,0))))*POWER(10,LEN(TRUNC(F27,0)))+F27-F26,F27-F26-VALUE(LEFT(F27,LEN(TRUNC(F27,0))-LEN(TRUNC(F26,0))))*POWER(10,LEN(TRUNC(F26,0)))))) -> 0.0471 | H27: =IF(G27="","",G27*$H$15) -> 847.8 | I27: =IF(H27="","",IF(D27="","",IF(AND(H27=0,D27=0),0,H27/D27))) -> 0.46679881 | K27: 6.5
A28: 10-00 | B28: 3500.136 | C28: =IF(B28="","",IF(LEN(TRUNC(B27,0))-LEN(TRUNC(B28,0))=0,B28-B27,IF(LEN(TRUNC(B27,0))-LEN(TRUNC(B28,0))>0,VALUE(LEFT(B27,LEN(TRUNC(B27,0))-LEN(TRUNC(B28,0))))*POWER(10,LEN(TRUNC(B28,0)))+B28-B27,B28-B27-VALUE(LEFT(B28,LEN(TRUNC(B28,0))-LEN(TRUNC(B27,0))))*POWER(10,LEN(TRUNC(B27,0)))))) -> 0.0983 | D28: =IF(C28="","",C28*$D$15) -> 1769.4 | F28: 1296.1466 | G28: =IF(F28="","",IF(LEN(TRUNC(F27,0))-LEN(TRUNC(F28,0))=0,F28-F27,IF(LEN(TRUNC(F27,0))-LEN(TRUNC(F28,0))>0,VALUE(LEFT(F27,LEN(TRUNC(F27,0))-LEN(TRUNC(F28,0))))*POWER(10,LEN(TRUNC(F28,0)))+F28-F27,F28-F27-VALUE(LEFT(F28,LEN(TRUNC(F28,0))-LEN(TRUNC(F27,0))))*POWER(10,LEN(TRUNC(F27,0)))))) -> 0.0438 | H28: =IF(G28="","",G28*$H$15) -> 788.4 | I28: =IF(H28="","",IF(D28="","",IF(AND(H28=0,D28=0),0,H28/D28))) -> 0.44557477 | K28: 6.5
A29: 11-00 | B29: 3500.2323 | C29: =IF(B29="","",IF(LEN(TRUNC(B28,0))-LEN(TRUNC(B29,0))=0,B29-B28,IF(LEN(TRUNC(B28,0))-LEN(TRUNC(B29,0))>0,VALUE(LEFT(B28,LEN(TRUNC(B28,0))-LEN(TRUNC(B29,0))))*POWER(10,LEN(TRUNC(B29,0)))+B29-B28,B29-B28-VALUE(LEFT(B29,LEN(TRUNC(B29,0))-LEN(TRUNC(B28,0))))*POWER(10,LEN(TRUNC(B28,0)))))) -> 0.0963 | D29: =IF(C29="","",C29*$D$15) -> 1733.4 | F29: 1296.1931 | G29: =IF(F29="","",IF(LEN(TRUNC(F28,0))-LEN(TRUNC(F29,0))=0,F29-F28,IF(LEN(TRUNC(F28,0))-LEN(TRUNC(F29,0))>0,VALUE(LEFT(F28,LEN(TRUNC(F28,0))-LEN(TRUNC(F29,0))))*POWER(10,LEN(TRUNC(F29,0)))+F29-F28,F29-F28-VALUE(LEFT(F29,LEN(TRUNC(F29,0))-LEN(TRUNC(F28,0))))*POWER(10,LEN(TRUNC(F28,0)))))) -> 0.0465 | H29: =IF(G29="","",G29*$H$15) -> 837 | I29: =IF(H29="","",IF(D29="","",IF(AND(H29=0,D29=0),0,H29/D29))) -> 0.48286604 | K29: 6.4 | M29: Указать отдельно рабочие и запломбированные трансформаторы и высоковольтные электродвигатели
A30: 12-00 | B30: 3500.3237 | C30: =IF(B30="","",IF(LEN(TRUNC(B29,0))-LEN(TRUNC(B30,0))=0,B30-B29,IF(LEN(TRUNC(B29,0))-LEN(TRUNC(B30,0))>0,VALUE(LEFT(B29,LEN(TRUNC(B29,0))-LEN(TRUNC(B30,0))))*POWER(10,LEN(TRUNC(B30,0)))+B30-B29,B30-B29-VALUE(LEFT(B30,LEN(TRUNC(B30,0))-LEN(TRUNC(B29,0))))*POWER(10,LEN(TRUNC(B29,0)))))) -> 0.0914 | D30: =IF(C30="","",C30*$D$15) -> 1645.2 | F30: 1296.2353 | G30: =IF(F30="","",IF(LEN(TRUNC(F29,0))-LEN(TRUNC(F30,0))=0,F30-F29,IF(LEN(TRUNC(F29,0))-LEN(TRUNC(F30,0))>0,VALUE(LEFT(F29,LEN(TRUNC(F29,0))-LEN(TRUNC(F30,0))))*POWER(10,LEN(TRUNC(F30,0)))+F30-F29,F30-F29-VALUE(LEFT(F30,LEN(TRUNC(F30,0))-LEN(TRUNC(F29,0))))*POWER(10,LEN(TRUNC(F29,0)))))) -> 0.0422 | H30: =IF(G30="","",G30*$H$15) -> 759.6 | I30: =IF(H30="","",IF(D30="","",IF(AND(H30=0,D30=0),0,H30/D30))) -> 0.46170678 | K30: 6.4 | M30: II. Статконденсаторы всех напряжений
A31: 13-00 | B31: 3500.4128 | C31: =IF(B31="","",IF(LEN(TRUNC(B30,0))-LEN(TRUNC(B31,0))=0,B31-B30,IF(LEN(TRUNC(B30,0))-LEN(TRUNC(B31,0))>0,VALUE(LEFT(B30,LEN(TRUNC(B30,0))-LEN(TRUNC(B31,0))))*POWER(10,LEN(TRUNC(B31,0)))+B31-B30,B31-B30-VALUE(LEFT(B31,LEN(TRUNC(B31,0))-LEN(TRUNC(B30,0))))*POWER(10,LEN(TRUNC(B30,0)))))) -> 0.0891 | D31: =IF(C31="","",C31*$D$15) -> 1603.8 | F31: 1296.2744 | G31: =IF(F31="","",IF(LEN(TRUNC(F30,0))-LEN(TRUNC(F31,0))=0,F31-F30,IF(LEN(TRUNC(F30,0))-LEN(TRUNC(F31,0))>0,VALUE(LEFT(F30,LEN(TRUNC(F30,0))-LEN(TRUNC(F31,0))))*POWER(10,LEN(TRUNC(F31,0)))+F31-F30,F31-F30-VALUE(LEFT(F31,LEN(TRUNC(F31,0))-LEN(TRUNC(F30,0))))*POWER(10,LEN(TRUNC(F30,0)))))) -> 0.0391 | H31: =IF(G31="","",G31*$H$15) -> 703.8 | I31: =IF(H31="","",IF(D31="","",IF(AND(H31=0,D31=0),0,H31/D31))) -> 0.43883277 | K31: 6.4 | M31: №№ | N31: Место | P31: Номинальное | R31: Номинальная | T31: В т.ч. с | V31: Время включения | Y31: Примечание
A32: 14-00 | B32: 3500.4975 | C32: =IF(B32="","",IF(LEN(TRUNC(B31,0))-LEN(TRUNC(B32,0))=0,B32-B31,IF(LEN(TRUNC(B31,0))-LEN(TRUNC(B32,0))>0,VALUE(LEFT(B31,LEN(TRUNC(B31,0))-LEN(TRUNC(B32,0))))*POWER(10,LEN(TRUNC(B32,0)))+B32-B31,B32-B31-VALUE(LEFT(B32,LEN(TRUNC(B32,0))-LEN(TRUNC(B31,0))))*POWER(10,LEN(TRUNC(B31,0)))))) -> 0.0847 | D32: =IF(C32="","",C32*$D$15) -> 1524.6 | F32: 1296.3113 | G32: =IF(F32="","",IF(LEN(TRUNC(F31,0))-LEN(TRUNC(F32,0))=0,F32-F31,IF(LEN(TRUNC(F31,0))-LEN(TRUNC(F32,0))>0,VALUE(LEFT(F31,LEN(TRUNC(F31,0))-LEN(TRUNC(F32,0))))*POWER(10,LEN(TRUNC(F32,0)))+F32-F31,F32-F31-VALUE(LEFT(F32,LEN(TRUNC(F32,0))-LEN(TRUNC(F31,0))))*POWER(10,LEN(TRUNC(F31,0)))))) -> 0.0369 | H32: =IF(G32="","",G32*$H$15) -> 664.2 | I32: =IF(H32="","",IF(D32="","",IF(AND(H32=0,D32=0),0,H32/D32))) -> 0.43565525 | K32: 6.4 | P32: напряжение | R32: мощность | T32: авторегулир. | V32: и отключения
A33: 15-00 | B33: 3500.5804 | C33: =IF(B33="","",IF(LEN(TRUNC(B32,0))-LEN(TRUNC(B33,0))=0,B33-B32,IF(LEN(TRUNC(B32,0))-LEN(TRUNC(B33,0))>0,VALUE(LEFT(B32,LEN(TRUNC(B32,0))-LEN(TRUNC(B33,0))))*POWER(10,LEN(TRUNC(B33,0)))+B33-B32,B33-B32-VALUE(LEFT(B33,LEN(TRUNC(B33,0))-LEN(TRUNC(B32,0))))*POWER(10,LEN(TRUNC(B32,0)))))) -> 0.0829 | D33: =IF(C33="","",C33*$D$15) -> 1492.2 | F33: 1296.3476 | G33: =IF(F33="","",IF(LEN(TRUNC(F32,0))-LEN(TRUNC(F33,0))=0,F33-F32,IF(LEN(TRUNC(F32,0))-LEN(TRUNC(F33,0))>0,VALUE(LEFT(F32,LEN(TRUNC(F32,0))-LEN(TRUNC(F33,0))))*POWER(10,LEN(TRUNC(F33,0)))+F33-F32,F33-F32-VALUE(LEFT(F33,LEN(TRUNC(F33,0))-LEN(TRUNC(F32,0))))*POWER(10,LEN(TRUNC(F32,0)))))) -> 0.0363 | H33: =IF(G33="","",G33*$H$15) -> 653.4 | I33: =IF(H33="","",IF(D33="","",IF(AND(H33=0,D33=0),0,H33/D33))) -> 0.43787696 | K33: 6.4 | M33: п/п | N33: установки | P33: кВ | R33: кВар | T33: кВар | V33: установки за сутки
A34: 16-00 | B34: 3500.6642 | C34: =IF(B34="","",IF(LEN(TRUNC(B33,0))-LEN(TRUNC(B34,0))=0,B34-B33,IF(LEN(TRUNC(B33,0))-LEN(TRUNC(B34,0))>0,VALUE(LEFT(B33,LEN(TRUNC(B33,0))-LEN(TRUNC(B34,0))))*POWER(10,LEN(TRUNC(B34,0)))+B34-B33,B34-B33-VALUE(LEFT(B34,LEN(TRUNC(B34,0))-LEN(TRUNC(B33,0))))*POWER(10,LEN(TRUNC(B33,0)))))) -> 0.0838 | D34: =IF(C34="","",C34*$D$15) -> 1508.4 | F34: 1296.385 | G34: =IF(F34="","",IF(LEN(TRUNC(F33,0))-LEN(TRUNC(F34,0))=0,F34-F33,IF(LEN(TRUNC(F33,0))-LEN(TRUNC(F34,0))>0,VALUE(LEFT(F33,LEN(TRUNC(F33,0))-LEN(TRUNC(F34,0))))*POWER(10,LEN(TRUNC(F34,0)))+F34-F33,F34-F33-VALUE(LEFT(F34,LEN(TRUNC(F34,0))-LEN(TRUNC(F33,0))))*POWER(10,LEN(TRUNC(F33,0)))))) -> 0.0374 | H34: =IF(G34="","",G34*$H$15) -> 673.2 | I34: =IF(H34="","",IF(D34="","",IF(AND(H34=0,D34=0),0,H34/D34))) -> 0.44630072 | K34: 6.4
A35: 17-00 | B35: 3500.7479 | C35: =IF(B35="","",IF(LEN(TRUNC(B34,0))-LEN(TRUNC(B35,0))=0,B35-B34,IF(LEN(TRUNC(B34,0))-LEN(TRUNC(B35,0))>0,VALUE(LEFT(B34,LEN(TRUNC(B34,0))-LEN(TRUNC(B35,0))))*POWER(10,LEN(TRUNC(B35,0)))+B35-B34,B35-B34-VALUE(LEFT(B35,LEN(TRUNC(B35,0))-LEN(TRUNC(B34,0))))*POWER(10,LEN(TRUNC(B34,0)))))) -> 0.0837 | D35: =IF(C35="","",C35*$D$15) -> 1506.6 | F35: 1296.4201 | G35: =IF(F35="","",IF(LEN(TRUNC(F34,0))-LEN(TRUNC(F35,0))=0,F35-F34,IF(LEN(TRUNC(F34,0))-LEN(TRUNC(F35,0))>0,VALUE(LEFT(F34,LEN(TRUNC(F34,0))-LEN(TRUNC(F35,0))))*POWER(10,LEN(TRUNC(F35,0)))+F35-F34,F35-F34-VALUE(LEFT(F35,LEN(TRUNC(F35,0))-LEN(TRUNC(F34,0))))*POWER(10,LEN(TRUNC(F34,0)))))) -> 0.0351 | H35: =IF(G35="","",G35*$H$15) -> 631.8 | I35: =IF(H35="","",IF(D35="","",IF(AND(H35=0,D35=0),0,H35/D35))) -> 0.41935484 | K35: 6.4 | N35: ТП-13, РП-19 | P35: 0.4 | R35: 2160
A36: 18-00 | B36: 3500.8377 | C36: =IF(B36="","",IF(LEN(TRUNC(B35,0))-LEN(TRUNC(B36,0))=0,B36-B35,IF(LEN(TRUNC(B35,0))-LEN(TRUNC(B36,0))>0,VALUE(LEFT(B35,LEN(TRUNC(B35,0))-LEN(TRUNC(B36,0))))*POWER(10,LEN(TRUNC(B36,0)))+B36-B35,B36-B35-VALUE(LEFT(B36,LEN(TRUNC(B36,0))-LEN(TRUNC(B35,0))))*POWER(10,LEN(TRUNC(B35,0)))))) -> 0.0898 | D36: =IF(C36="","",C36*$D$15) -> 1616.4 | F36: 1296.458 | G36: =IF(F36="","",IF(LEN(TRUNC(F35,0))-LEN(TRUNC(F36,0))=0,F36-F35,IF(LEN(TRUNC(F35,0))-LEN(TRUNC(F36,0))>0,VALUE(LEFT(F35,LEN(TRUNC(F35,0))-LEN(TRUNC(F36,0))))*POWER(10,LEN(TRUNC(F36,0)))+F36-F35,F36-F35-VALUE(LEFT(F36,LEN(TRUNC(F36,0))-LEN(TRUNC(F35,0))))*POWER(10,LEN(TRUNC(F35,0)))))) -> 0.0379 | H36: =IF(G36="","",G36*$H$15) -> 682.2 | I36: =IF(H36="","",IF(D36="","",IF(AND(H36=0,D36=0),0,H36/D36))) -> 0.422049 | K36: 6.4 | N36: КТП-22,23,24,25
A37: 19-00 | B37: 3500.9233 | C37: =IF(B37="","",IF(LEN(TRUNC(B36,0))-LEN(TRUNC(B37,0))=0,B37-B36,IF(LEN(TRUNC(B36,0))-LEN(TRUNC(B37,0))>0,VALUE(LEFT(B36,LEN(TRUNC(B36,0))-LEN(TRUNC(B37,0))))*POWER(10,LEN(TRUNC(B37,0)))+B37-B36,B37-B36-VALUE(LEFT(B37,LEN(TRUNC(B37,0))-LEN(TRUNC(B36,0))))*POWER(10,LEN(TRUNC(B36,0)))))) -> 0.0856 | D37: =IF(C37="","",C37*$D$15) -> 1540.8 | F37: 1296.4978 | G37: =IF(F37="","",IF(LEN(TRUNC(F36,0))-LEN(TRUNC(F37,0))=0,F37-F36,IF(LEN(TRUNC(F36,0))-LEN(TRUNC(F37,0))>0,VALUE(LEFT(F36,LEN(TRUNC(F36,0))-LEN(TRUNC(F37,0))))*POWER(10,LEN(TRUNC(F37,0)))+F37-F36,F37-F36-VALUE(LEFT(F37,LEN(TRUNC(F37,0))-LEN(TRUNC(F36,0))))*POWER(10,LEN(TRUNC(F36,0)))))) -> 0.0398 | H37: =IF(G37="","",G37*$H$15) -> 716.4 | I37: =IF(H37="","",IF(D37="","",IF(AND(H37=0,D37=0),0,H37/D37))) -> 0.46495327 | K37: 6.4 | N37: РТП-1
A38: 20-00 | B38: 3501.0045 | C38: =IF(B38="","",IF(LEN(TRUNC(B37,0))-LEN(TRUNC(B38,0))=0,B38-B37,IF(LEN(TRUNC(B37,0))-LEN(TRUNC(B38,0))>0,VALUE(LEFT(B37,LEN(TRUNC(B37,0))-LEN(TRUNC(B38,0))))*POWER(10,LEN(TRUNC(B38,0)))+B38-B37,B38-B37-VALUE(LEFT(B38,LEN(TRUNC(B38,0))-LEN(TRUNC(B37,0))))*POWER(10,LEN(TRUNC(B37,0)))))) -> 0.0812 | D38: =IF(C38="","",C38*$D$15) -> 1461.6 | F38: 1296.5346 | G38: =IF(F38="","",IF(LEN(TRUNC(F37,0))-LEN(TRUNC(F38,0))=0,F38-F37,IF(LEN(TRUNC(F37,0))-LEN(TRUNC(F38,0))>0,VALUE(LEFT(F37,LEN(TRUNC(F37,0))-LEN(TRUNC(F38,0))))*POWER(10,LEN(TRUNC(F38,0)))+F38-F37,F38-F37-VALUE(LEFT(F38,LEN(TRUNC(F38,0))-LEN(TRUNC(F37,0))))*POWER(10,LEN(TRUNC(F37,0)))))) -> 0.0368 | H38: =IF(G38="","",G38*$H$15) -> 662.4 | I38: =IF(H38="","",IF(D38="","",IF(AND(H38=0,D38=0),0,H38/D38))) -> 0.45320197 | K38: 6.5 | N38: РП-1 | P38: 6 | R38: 870
A39: 21-00 | B39: 3501.0884 | C39: =IF(B39="","",IF(LEN(TRUNC(B38,0))-LEN(TRUNC(B39,0))=0,B39-B38,IF(LEN(TRUNC(B38,0))-LEN(TRUNC(B39,0))>0,VALUE(LEFT(B38,LEN(TRUNC(B38,0))-LEN(TRUNC(B39,0))))*POWER(10,LEN(TRUNC(B39,0)))+B39-B38,B39-B38-VALUE(LEFT(B39,LEN(TRUNC(B39,0))-LEN(TRUNC(B38,0))))*POWER(10,LEN(TRUNC(B38,0)))))) -> 0.0839 | D39: =IF(C39="","",C39*$D$15) -> 1510.2 | F39: 1296.5734 | G39: =IF(F39="","",IF(LEN(TRUNC(F38,0))-LEN(TRUNC(F39,0))=0,F39-F38,IF(LEN(TRUNC(F38,0))-LEN(TRUNC(F39,0))>0,VALUE(LEFT(F38,LEN(TRUNC(F38,0))-LEN(TRUNC(F39,0))))*POWER(10,LEN(TRUNC(F39,0)))+F39-F38,F39-F38-VALUE(LEFT(F39,LEN(TRUNC(F39,0))-LEN(TRUNC(F38,0))))*POWER(10,LEN(TRUNC(F38,0)))))) -> 0.0388 | H39: =IF(G39="","",G39*$H$15) -> 698.4 | I39: =IF(H39="","",IF(D39="","",IF(AND(H39=0,D39=0),0,H39/D39))) -> 0.4624553 | K39: 6.5
A40: 22-00 | B40: 3501.1791 | C40: =IF(B40="","",IF(LEN(TRUNC(B39,0))-LEN(TRUNC(B40,0))=0,B40-B39,IF(LEN(TRUNC(B39,0))-LEN(TRUNC(B40,0))>0,VALUE(LEFT(B39,LEN(TRUNC(B39,0))-LEN(TRUNC(B40,0))))*POWER(10,LEN(TRUNC(B40,0)))+B40-B39,B40-B39-VALUE(LEFT(B40,LEN(TRUNC(B40,0))-LEN(TRUNC(B39,0))))*POWER(10,LEN(TRUNC(B39,0)))))) -> 0.0907 | D40: =IF(C40="","",C40*$D$15) -> 1632.6 | F40: 1296.6189 | G40: =IF(F40="","",IF(LEN(TRUNC(F39,0))-LEN(TRUNC(F40,0))=0,F40-F39,IF(LEN(TRUNC(F39,0))-LEN(TRUNC(F40,0))>0,VALUE(LEFT(F39,LEN(TRUNC(F39,0))-LEN(TRUNC(F40,0))))*POWER(10,LEN(TRUNC(F40,0)))+F40-F39,F40-F39-VALUE(LEFT(F40,LEN(TRUNC(F40,0))-LEN(TRUNC(F39,0))))*POWER(10,LEN(TRUNC(F39,0)))))) -> 0.0455 | H40: =IF(G40="","",G40*$H$15) -> 819 | I40: =IF(H40="","",IF(D40="","",IF(AND(H40=0,D40=0),0,H40/D40))) -> 0.5016538 | K40: 6.5 | M40: III. Синхронные электродвигатели напряжением до 1000 В
A41: 23-00 | B41: 3501.2687 | C41: =IF(B41="","",IF(LEN(TRUNC(B40,0))-LEN(TRUNC(B41,0))=0,B41-B40,IF(LEN(TRUNC(B40,0))-LEN(TRUNC(B41,0))>0,VALUE(LEFT(B40,LEN(TRUNC(B40,0))-LEN(TRUNC(B41,0))))*POWER(10,LEN(TRUNC(B41,0)))+B41-B40,B41-B40-VALUE(LEFT(B41,LEN(TRUNC(B41,0))-LEN(TRUNC(B40,0))))*POWER(10,LEN(TRUNC(B40,0)))))) -> 0.0896 | D41: =IF(C41="","",C41*$D$15) -> 1612.8 | F41: 1296.6646 | G41: =IF(F41="","",IF(LEN(TRUNC(F40,0))-LEN(TRUNC(F41,0))=0,F41-F40,IF(LEN(TRUNC(F40,0))-LEN(TRUNC(F41,0))>0,VALUE(LEFT(F40,LEN(TRUNC(F40,0))-LEN(TRUNC(F41,0))))*POWER(10,LEN(TRUNC(F41,0)))+F41-F40,F41-F40-VALUE(LEFT(F41,LEN(TRUNC(F41,0))-LEN(TRUNC(F40,0))))*POWER(10,LEN(TRUNC(F40,0)))))) -> 0.0457 | H41: =IF(G41="","",G41*$H$15) -> 822.6 | I41: =IF(H41="","",IF(D41="","",IF(AND(H41=0,D41=0),0,H41/D41))) -> 0.51004464 | K41: 6.5 | M41: №№ | N41: Место | P41: Номинальная | S41: № п-п | T41: Место установки | X41: Номинальная
A42: 24-00 | B42: 3501.3565 | C42: =IF(B42="","",IF(LEN(TRUNC(B41,0))-LEN(TRUNC(B42,0))=0,B42-B41,IF(LEN(TRUNC(B41,0))-LEN(TRUNC(B42,0))>0,VALUE(LEFT(B41,LEN(TRUNC(B41,0))-LEN(TRUNC(B42,0))))*POWER(10,LEN(TRUNC(B42,0)))+B42-B41,B42-B41-VALUE(LEFT(B42,LEN(TRUNC(B42,0))-LEN(TRUNC(B41,0))))*POWER(10,LEN(TRUNC(B41,0)))))) -> 0.0878 | D42: =IF(C42="","",C42*$D$15) -> 1580.4 | F42: 1296.709 | G42: =IF(F42="","",IF(LEN(TRUNC(F41,0))-LEN(TRUNC(F42,0))=0,F42-F41,IF(LEN(TRUNC(F41,0))-LEN(TRUNC(F42,0))>0,VALUE(LEFT(F41,LEN(TRUNC(F41,0))-LEN(TRUNC(F42,0))))*POWER(10,LEN(TRUNC(F42,0)))+F42-F41,F42-F41-VALUE(LEFT(F42,LEN(TRUNC(F42,0))-LEN(TRUNC(F41,0))))*POWER(10,LEN(TRUNC(F41,0)))))) -> 0.0444 | H42: =IF(G42="","",G42*$H$15) -> 799.2 | I42: =IF(H42="","",IF(D42="","",IF(AND(H42=0,D42=0),0,H42/D42))) -> 0.50569476 | K42: 6.5
...

Sheet Ячейка 2
A1: ОАО "Пластик" | G1: Шифр | M1: I. Сведения о присоединенных трансформаторах и высоковольтных электродвигателях
A2: (наименование предприятия) | M2: 1. Трансформаторы
A3: г. Узловая, Тульская, 1 | G3: Питающий центр | I3: П/ст №167 (ГПП-1) | M3: №№ | N3: Место установки | P3: Мощность | R3: Номинальн. | T3: Включен. | V3: Назначение | X3: Примечание
A4: (адрес) | R4: напряжение | T4: на ответвление | V4: тр-ра
G5: № фидера | I5: яч 2 тр-р №2 | M5: п/п | P5: ква | R5: ________ кВ | T5: ________ кВ | V5: силов. освет.
A6: (министерство, ведомство) | V6: печной
A8: ПРОТОКОЛ (первичный)
A9: записей показания электросчетчиков и вольтметров, а также определение
A10: нагрузок и тангенса "фи" за | E10: 18 Декабрь | H10: 2013 года
A11: напряжения | E11: _______6000_____________ | I11: вольт
A13: Время записи часы | B13: Активн. сч-к тип | D13: СЭТ-4ТМ.03 | F13: Реактивн. сч-к тип | H13: СЭТ-4ТМ.3 | I13: Тангенс "фи" | J13: Показание | L13: Мощность
B14: ____________л__ | D14: №0808090590 | F14: ____________л__ | H14: №0808090590 | J14: вольтметр. | L14: включен.
B15: Расчетн. коэф | D15: 18000 | F15: Расчетн. коэф | H15: 18000 | J15: на стороне | L15: компенсир.
B16: показ. | C16: разность | D16: расход за | F16: показ. | G16: разность | H16: расход за | J16: в\н | K16: н\н | L16: устройств
B17: сч-ка | C17: показ. | D17: час (кВт) | F17: сч-ка | G17: показ. | H17: час (кВт) | L17: кВар | M17: 2. Высоковольтные электродвигатели
A18: 0-00 | B18: 7872.147 | F18: 4165.9185 | K18: 6.6 | M18: №№ | N18: Место | Q18: Тип | T18: Номинальная | W18: Примечание
A19: 1-00 | B19: 7872.398 | C19: =IF(B19="","",IF(LEN(TRUNC(B18,0))-LEN(TRUNC(B19,0))=0,B19-B18,IF(LEN(TRUNC(B18,0))-LEN(TRUNC(B19,0))>0,VALUE(LEFT(B18,LEN(TRUNC(B18,0))-LEN(TRUNC(B19,0))))*POWER(10,LEN(TRUNC(B19,0)))+B19-B18,B19-B18-VALUE(LEFT(B19,LEN(TRUNC(B19,0))-LEN(TRUNC(B18,0))))*POWER(10,LEN(TRUNC(B18,0)))))) -> 0.251 | D19: =IF(C19="","",C19*$D$15) -> 4518 | F19: 4166.0414 | G19: =IF(F19="","",IF(LEN(TRUNC(F18,0))-LEN(TRUNC(F19,0))=0,F19-F18,IF(LEN(TRUNC(F18,0))-LEN(TRUNC(F19,0))>0,VALUE(LEFT(F18,LEN(TRUNC(F18,0))-LEN(TRUNC(F19,0))))*POWER(10,LEN(TRUNC(F19,0)))+F19-F18,F19-F18-VALUE(LEFT(F19,LEN(TRUNC(F19,0))-LEN(TRUNC(F18,0))))*POWER(10,LEN(TRUNC(F18,0)))))) -> 0.1229 | H19: =IF(G19="","",G19*$H$15) -> 2212.2 | I19: =IF(H19="","",IF(D19="","",IF(AND(H19=0,D19=0),0,H19/D19))) -> 0.48964143 | K19: 6.6 | Q19: (синхронный,
A20: 2-00 | B20: 7872.6493 | C20: =IF(B20="","",IF(LEN(TRUNC(B19,0))-LEN(TRUNC(B20,0))=0,B20-B19,IF(LEN(TRUNC(B19,0))-LEN(TRUNC(B20,0))>0,VALUE(LEFT(B19,LEN(TRUNC(B19,0))-LEN(TRUNC(B20,0))))*POWER(10,LEN(TRUNC(B20,0)))+B20-B19,B20-B19-VALUE(LEFT(B20,LEN(TRUNC(B20,0))-LEN(TRUNC(B19,0))))*POWER(10,LEN(TRUNC(B19,0)))))) -> 0.2513 | D20: =IF(C20="","",C20*$D$15) -> 4523.4 | F20: 4166.1638 | G20: =IF(F20="","",IF(LEN(TRUNC(F19,0))-LEN(TRUNC(F20,0))=0,F20-F19,IF(LEN(TRUNC(F19,0))-LEN(TRUNC(F20,0))>0,VALUE(LEFT(F19,LEN(TRUNC(F19,0))-LEN(TRUNC(F20,0))))*POWER(10,LEN(TRUNC(F20,0)))+F20-F19,F20-F19-VALUE(LEFT(F20,LEN(TRUNC(F20,0))-LEN(TRUNC(F19,0))))*POWER(10,LEN(TRUNC(F19,0)))))) -> 0.1224 | H20: =IF(G20="","",G20*$H$15) -> 2203.2 | I20: =IF(H20="","",IF(D20="","",IF(AND(H20=0,D20=0),0,H20/D20))) -> 0.48706725 | K20: 6.6 | M20: п/п | N20: установки | Q20: асинхронный) | T20: мощность кВт
A21: 3-00 | B21: 7872.8988 | C21: =IF(B21="","",IF(LEN(TRUNC(B20,0))-LEN(TRUNC(B21,0))=0,B21-B20,IF(LEN(TRUNC(B20,0))-LEN(TRUNC(B21,0))>0,VALUE(LEFT(B20,LEN(TRUNC(B20,0))-LEN(TRUNC(B21,0))))*POWER(10,LEN(TRUNC(B21,0)))+B21-B20,B21-B20-VALUE(LEFT(B21,LEN(TRUNC(B21,0))-LEN(TRUNC(B20,0))))*POWER(10,LEN(TRUNC(B20,0)))))) -> 0.2495 | D21: =IF(C21="","",C21*$D$15) -> 4491 | F21: 4166.2846 | G21: =IF(F21="","",IF(LEN(TRUNC(F20,0))-LEN(TRUNC(F21,0))=0,F21-F20,IF(LEN(TRUNC(F20,0))-LEN(TRUNC(F21,0))>0,VALUE(LEFT(F20,LEN(TRUNC(F20,0))-LEN(TRUNC(F21,0))))*POWER(10,LEN(TRUNC(F21,0)))+F21-F20,F21-F20-VALUE(LEFT(F21,LEN(TRUNC(F21,0))-LEN(TRUNC(F20,0))))*POWER(10,LEN(TRUNC(F20,0)))))) -> 0.1208 | H21: =IF(G21="","",G21*$H$15) -> 2174.4 | I21: =IF(H21="","",IF(D21="","",IF(AND(H21=0,D21=0),0,H21/D21))) -> 0.48416834 | K21: 6.6
A22: 4-00 | B22: 7873.1527 | C22: =IF(B22="","",IF(LEN(TRUNC(B21,0))-LEN(TRUNC(B22,0))=0,B22-B21,IF(LEN(TRUNC(B21,0))-LEN(TRUNC(B22,0))>0,VALUE(LEFT(B21,LEN(TRUNC(B21,0))-LEN(TRUNC(B22,0))))*POWER(10,LEN(TRUNC(B22,0)))+B22-B21,B22-B21-VALUE(LEFT(B22,LEN(TRUNC(B22,0))-LEN(TRUNC(B21,0))))*POWER(10,LEN(TRUNC(B21,0)))))) -> 0.2539 | D22: =IF(C22="","",C22*$D$15) -> 4570.2 | F22: 4166.4064 | G22: =IF(F22="","",IF(LEN(TRUNC(F21,0))-LEN(TRUNC(F22,0))=0,F22-F21,IF(LEN(TRUNC(F21,0))-LEN(TRUNC(F22,0))>0,VALUE(LEFT(F21,LEN(TRUNC(F21,0))-LEN(TRUNC(F22,0))))*POWER(10,LEN(TRUNC(F22,0)))+F22-F21,F22-F21-VALUE(LEFT(F22,LEN(TRUNC(F22,0))-LEN(TRUNC(F21,0))))*POWER(10,LEN(TRUNC(F21,0)))))) -> 0.1218 | H22: =IF(G22="","",G22*$H$15) -> 2192.4 | I22: =IF(H22="","",IF(D22="","",IF(AND(H22=0,D22=0),0,H22/D22))) -> 0.47971642 | K22: 6.6
A23: 5-00 | B23: 7873.403 | C23: =IF(B23="","",IF(LEN(TRUNC(B22,0))-LEN(TRUNC(B23,0))=0,B23-B22,IF(LEN(TRUNC(B22,0))-LEN(TRUNC(B23,0))>0,VALUE(LEFT(B22,LEN(TRUNC(B22,0))-LEN(TRUNC(B23,0))))*POWER(10,LEN(TRUNC(B23,0)))+B23-B22,B23-B22-VALUE(LEFT(B23,LEN(TRUNC(B23,0))-LEN(TRUNC(B22,0))))*POWER(10,LEN(TRUNC(B22,0)))))) -> 0.2503 | D23: =IF(C23="","",C23*$D$15) -> 4505.4 | F23: 4166.5258 | G23: =IF(F23="","",IF(LEN(TRUNC(F22,0))-LEN(TRUNC(F23,0))=0,F23-F22,IF(LEN(TRUNC(F22,0))-LEN(TRUNC(F23,0))>0,VALUE(LEFT(F22,LEN(TRUNC(F22,0))-LEN(TRUNC(F23,0))))*POWER(10,LEN(TRUNC(F23,0)))+F23-F22,F23-F22-VALUE(LEFT(F23,LEN(TRUNC(F23,0))-LEN(TRUNC(F22,0))))*POWER(10,LEN(TRUNC(F22,0)))))) -> 0.1194 | H23: =IF(G23="","",G23*$H$15) -> 2149.2 | I23: =IF(H23="","",IF(D23="","",IF(AND(H23=0,D23=0),0,H23/D23))) -> 0.47702757 | K23: 6.6
A24: 6-00 | B24: 7873.6549 | C24: =IF(B24="","",IF(LEN(TRUNC(B23,0))-LEN(TRUNC(B24,0))=0,B24-B23,IF(LEN(TRUNC(B23,0))-LEN(TRUNC(B24,0))>0,VALUE(LEFT(B23,LEN(TRUNC(B23,0))-LEN(TRUNC(B24,0))))*POWER(10,LEN(TRUNC(B24,0)))+B24-B23,B24-B23-VALUE(LEFT(B24,LEN(TRUNC(B24,0))-LEN(TRUNC(B23,0))))*POWER(10,LEN(TRUNC(B23,0)))))) -> 0.2519 | D24: =IF(C24="","",C24*$D$15) -> 4534.2 | F24: 4166.6421 | G24: =IF(F24="","",IF(LEN(TRUNC(F23,0))-LEN(TRUNC(F24,0))=0,F24-F23,IF(LEN(TRUNC(F23,0))-LEN(TRUNC(F24,0))>0,VALUE(LEFT(F23,LEN(TRUNC(F23,0))-LEN(TRUNC(F24,0))))*POWER(10,LEN(TRUNC(F24,0)))+F24-F23,F24-F23-VALUE(LEFT(F24,LEN(TRUNC(F24,0))-LEN(TRUNC(F23,0))))*POWER(10,LEN(TRUNC(F23,0)))))) -> 0.1163 | H24: =IF(G24="","",G24*$H$15) -> 2093.4 | I24: =IF(H24="","",IF(D24="","",IF(AND(H24=0,D24=0),0,H24/D24))) -> 0.46169115 | K24: 6.6
A25: 7-00 | B25: 7873.9124 | C25: =IF(B25="","",IF(LEN(TRUNC(B24,0))-LEN(TRUNC(B25,0))=0,B25-B24,IF(LEN(TRUNC(B24,0))-LEN(TRUNC(B25,0))>0,VALUE(LEFT(B24,LEN(TRUNC(B24,0))-LEN(TRUNC(B25,0))))*POWER(10,LEN(TRUNC(B25,0)))+B25-B24,B25-B24-VALUE(LEFT(B25,LEN(TRUNC(B25,0))-LEN(TRUNC(B24,0))))*POWER(10,LEN(TRUNC(B24,0)))))) -> 0.2575 | D25: =IF(C25="","",C25*$D$15) -> 4635 | F25: 4166.7582 | G25: =IF(F25="","",IF(LEN(TRUNC(F24,0))-LEN(TRUNC(F25,0))=0,F25-F24,IF(LEN(TRUNC(F24,0))-LEN(TRUNC(F25,0))>0,VALUE(LEFT(F24,LEN(TRUNC(F24,0))-LEN(TRUNC(F25,0))))*POWER(10,LEN(TRUNC(F25,0)))+F25-F24,F25-F24-VALUE(LEFT(F25,LEN(TRUNC(F25,0))-LEN(TRUNC(F24,0))))*POWER(10,LEN(TRUNC(F24,0)))))) -> 0.1161 | H25: =IF(G25="","",G25*$H$15) -> 2089.8 | I25: =IF(H25="","",IF(D25="","",IF(AND(H25=0,D25=0),0,H25/D25))) -> 0.45087379 | K25: 6.6
A26: 8-00 | B26: 7874.1876 | C26: =IF(B26="","",IF(LEN(TRUNC(B25,0))-LEN(TRUNC(B26,0))=0,B26-B25,IF(LEN(TRUNC(B25,0))-LEN(TRUNC(B26,0))>0,VALUE(LEFT(B25,LEN(TRUNC(B25,0))-LEN(TRUNC(B26,0))))*POWER(10,LEN(TRUNC(B26,0)))+B26-B25,B26-B25-VALUE(LEFT(B26,LEN(TRUNC(B26,0))-LEN(TRUNC(B25,0))))*POWER(10,LEN(TRUNC(B25,0)))))) -> 0.2752 | D26: =IF(C26="","",C26*$D$15) -> 4953.6 | F26: 4166.8782 | G26: =IF(F26="","",IF(LEN(TRUNC(F25,0))-LEN(TRUNC(F26,0))=0,F26-F25,IF(LEN(TRUNC(F25,0))-LEN(TRUNC(F26,0))>0,VALUE(LEFT(F25,LEN(TRUNC(F25,0))-LEN(TRUNC(F26,0))))*POWER(10,LEN(TRUNC(F26,0)))+F26-F25,F26-F25-VALUE(LEFT(F26,LEN(TRUNC(F26,0))-LEN(TRUNC(F25,0))))*POWER(10,LEN(TRUNC(F25,0)))))) -> 0.12 | H26: =IF(G26="","",G26*$H$15) -> 2160 | I26: =IF(H26="","",IF(D26="","",IF(AND(H26=0,D26=0),0,H26/D26))) -> 0.43604651 | K26: 6.6
A27: 9-00 | B27: 7874.4785 | C27: =IF(B27="","",IF(LEN(TRUNC(B26,0))-LEN(TRUNC(B27,0))=0,B27-B26,IF(LEN(TRUNC(B26,0))-LEN(TRUNC(B27,0))>0,VALUE(LEFT(B26,LEN(TRUNC(B26,0))-LEN(TRUNC(B27,0))))*POWER(10,LEN(TRUNC(B27,0)))+B27-B26,B27-B26-VALUE(LEFT(B27,LEN(TRUNC(B27,0))-LEN(TRUNC(B26,0))))*POWER(10,LEN(TRUNC(B26,0)))))) -> 0.2909 | D27: =IF(C27="","",C27*$D$15) -> 5236.2 | F27: 4167.0063 | G27: =IF(F27="","",IF(LEN(TRUNC(F26,0))-LEN(TRUNC(F27,0))=0,F27-F26,IF(LEN(TRUNC(F26,0))-LEN(TRUNC(F27,0))>0,VALUE(LEFT(F26,LEN(TRUNC(F26,0))-LEN(TRUNC(F27,0))))*POWER(10,LEN(TRUNC(F27,0)))+F27-F26,F27-F26-VALUE(LEFT(F27,LEN(TRUNC(F27,0))-LEN(TRUNC(F26,0))))*POWER(10,LEN(TRUNC(F26,0)))))) -> 0.1281 | H27: =IF(G27="","",G27*$H$15) -> 2305.8 | I27: =IF(H27="","",IF(D27="","",IF(AND(H27=0,D27=0),0,H27/D27))) -> 0.44035751 | K27: 6.6
A28: 10-00 | B28: 7874.7882 | C28: =IF(B28="","",IF(LEN(TRUNC(B27,0))-LEN(TRUNC(B28,0))=0,B28-B27,IF(LEN(TRUNC(B27,0))-LEN(TRUNC(B28,0))>0,VALUE(LEFT(B27,LEN(TRUNC(B27,0))-LEN(TRUNC(B28,0))))*POWER(10,LEN(TRUNC(B28,0)))+B28-B27,B28-B27-VALUE(LEFT(B28,LEN(TRUNC(B28,0))-LEN(TRUNC(B27,0))))*POWER(10,LEN(TRUNC(B27,0)))))) -> 0.3097 | D28: =IF(C28="","",C28*$D$15) -> 5574.6 | F28: 4167.1416 | G28: =IF(F28="","",IF(LEN(TRUNC(F27,0))-LEN(TRUNC(F28,0))=0,F28-F27,IF(LEN(TRUNC(F27,0))-LEN(TRUNC(F28,0))>0,VALUE(LEFT(F27,LEN(TRUNC(F27,0))-LEN(TRUNC(F28,0))))*POWER(10,LEN(TRUNC(F28,0)))+F28-F27,F28-F27-VALUE(LEFT(F28,LEN(TRUNC(F28,0))-LEN(TRUNC(F27,0))))*POWER(10,LEN(TRUNC(F27,0)))))) -> 0.1353 | H28: =IF(G28="","",G28*$H$15) -> 2435.4 | I28: =IF(H28="","",IF(D28="","",IF(AND(H28=0,D28=0),0,H28/D28))) -> 0.43687439 | K28: 6.5
A29: 11-00 | B29: 7875.1068 | C29: =IF(B29="","",IF(LEN(TRUNC(B28,0))-LEN(TRUNC(B29,0))=0,B29-B28,IF(LEN(TRUNC(B28,0))-LEN(TRUNC(B29,0))>0,VALUE(LEFT(B28,LEN(TRUNC(B28,0))-LEN(TRUNC(B29,0))))*POWER(10,LEN(TRUNC(B29,0)))+B29-B28,B29-B28-VALUE(LEFT(B29,LEN(TRUNC(B29,0))-LEN(TRUNC(B28,0))))*POWER(10,LEN(TRUNC(B28,0)))))) -> 0.3186 | D29: =IF(C29="","",C29*$D$15) -> 5734.8 | F29: 4167.2824 | G29: =IF(F29="","",IF(LEN(TRUNC(F28,0))-LEN(TRUNC(F29,0))=0,F29-F28,IF(LEN(TRUNC(F28,0))-LEN(TRUNC(F29,0))>0,VALUE(LEFT(F28,LEN(TRUNC(F28,0))-LEN(TRUNC(F29,0))))*POWER(10,LEN(TRUNC(F29,0)))+F29-F28,F29-F28-VALUE(LEFT(F29,LEN(TRUNC(F29,0))-LEN(TRUNC(F28,0))))*POWER(10,LEN(TRUNC(F28,0)))))) -> 0.1408 | H29: =IF(G29="","",G29*$H$15) -> 2534.4 | I29: =IF(H29="","",IF(D29="","",IF(AND(H29=0,D29=0),0,H29/D29))) -> 0.44193346 | K29: 6.5 | M29: Указать отдельно рабочие и запломбированные трансформаторы и высоковольтные электродвигатели
A30: 12-00 | B30: 7875.4225 | C30: =IF(B30="","",IF(LEN(TRUNC(B29,0))-LEN(TRUNC(B30,0))=0,B30-B29,IF(LEN(TRUNC(B29,0))-LEN(TRUNC(B30,0))>0,VALUE(LEFT(B29,LEN(TRUNC(B29,0))-LEN(TRUNC(B30,0))))*POWER(10,LEN(TRUNC(B30,0)))+B30-B29,B30-B29-VALUE(LEFT(B30,LEN(TRUNC(B30,0))-LEN(TRUNC(B29,0))))*POWER(10,LEN(TRUNC(B29,0)))))) -> 0.3157 | D30: =IF(C30="","",C30*$D$15) -> 5682.6 | F30: 4167.4262 | G30: =IF(F30="","",IF(LEN(TRUNC(F29,0))-LEN(TRUNC(F30,0))=0,F30-F29,IF(LEN(TRUNC(F29,0))-LEN(TRUNC(F30,0))>0,VALUE(LEFT(F29,LEN(TRUNC(F29,0))-LEN(TRUNC(F30,0))))*POWER(10,LEN(TRUNC(F30,0)))+F30-F29,F30-F29-VALUE(LEFT(F30,LEN(TRUNC(F30,0))-LEN(TRUNC(F29,0))))*POWER(10,LEN(TRUNC(F29,0)))))) -> 0.1438 | H30: =IF(G30="","",G30*$H$15) -> 2588.4 | I30: =IF(H30="","",IF(D30="","",IF(AND(H30=0,D30=0),0,H30/D30))) -> 0.45549572 | K30: 6.5 | M30: II. Статконденсаторы всех напряжений
A31: 13-00 | B31: 7875.7256 | C31: =IF(B31="","",IF(LEN(TRUNC(B30,0))-LEN(TRUNC(B31,0))=0,B31-B30,IF(LEN(TRUNC(B30,0))-LEN(TRUNC(B31,0))>0,VALUE(LEFT(B30,LEN(TRUNC(B30,0))-LEN(TRUNC(B31,0))))*POWER(10,LEN(TRUNC(B31,0)))+B31-B30,B31-B30-VALUE(LEFT(B31,LEN(TRUNC(B31,0))-LEN(TRUNC(B30,0))))*POWER(10,LEN(TRUNC(B30,0)))))) -> 0.3031 | D31: =IF(C31="","",C31*$D$15) -> 5455.8 | F31: 4167.5685 | G31: =IF(F31="","",IF(LEN(TRUNC(F30,0))-LEN(TRUNC(F31,0))=0,F31-F30,IF(LEN(TRUNC(F30,0))-LEN(TRUNC(F31,0))>0,VALUE(LEFT(F30,LEN(TRUNC(F30,0))-LEN(TRUNC(F31,0))))*POWER(10,LEN(TRUNC(F31,0)))+F31-F30,F31-F30-VALUE(LEFT(F31,LEN(TRUNC(F31,0))-LEN(TRUNC(F30,0))))*POWER(10,LEN(TRUNC(F30,0)))))) -> 0.1423 | H31: =IF(G31="","",G31*$H$15) -> 2561.4 | I31: =IF(H31="","",IF(D31="","",IF(AND(H31=0,D31=0),0,H31/D31))) -> 0.46948202 | K31: 6.5 | M31: №№ | N31: Место | P31: Номинальное | R31: Номинальная | T31: В т.ч. с | V31: Время включения | Y31: Примечание
A32: 14-00 | B32: 7876.0306 | C32: =IF(B32="","",IF(LEN(TRUNC(B31,0))-LEN(TRUNC(B32,0))=0,B32-B31,IF(LEN(TRUNC(B31,0))-LEN(TRUNC(B32,0))>0,VALUE(LEFT(B31,LEN(TRUNC(B31,0))-LEN(TRUNC(B32,0))))*POWER(10,LEN(TRUNC(B32,0)))+B32-B31,B32-B31-VALUE(LEFT(B32,LEN(TRUNC(B32,0))-LEN(TRUNC(B31,0))))*POWER(10,LEN(TRUNC(B31,0)))))) -> 0.305 | D32: =IF(C32="","",C32*$D$15) -> 5490 | F32: 4167.7093 | G32: =IF(F32="","",IF(LEN(TRUNC(F31,0))-LEN(TRUNC(F32,0))=0,F32-F31,IF(LEN(TRUNC(F31,0))-LEN(TRUNC(F32,0))>0,VALUE(LEFT(F31,LEN(TRUNC(F31,0))-LEN(TRUNC(F32,0))))*POWER(10,LEN(TRUNC(F32,0)))+F32-F31,F32-F31-VALUE(LEFT(F32,LEN(TRUNC(F32,0))-LEN(TRUNC(F31,0))))*POWER(10,LEN(TRUNC(F31,0)))))) -> 0.1408 | H32: =IF(G32="","",G32*$H$15) -> 2534.4 | I32: =IF(H32="","",IF(D32="","",IF(AND(H32=0,D32=0),0,H32/D32))) -> 0.46163934 | K32: 6.5 | P32: напряжение | R32: мощность | T32: авторегулир. | V32: и отключения
A33: 15-00 | B33: 7876.3307 | C33: =IF(B33="","",IF(LEN(TRUNC(B32,0))-LEN(TRUNC(B33,0))=0,B33-B32,IF(LEN(TRUNC(B32,0))-LEN(TRUNC(B33,0))>0,VALUE(LEFT(B32,LEN(TRUNC(B32,0))-LEN(TRUNC(B33,0))))*POWER(10,LEN(TRUNC(B33,0)))+B33-B32,B33-B32-VALUE(LEFT(B33,LEN(TRUNC(B33,0))-LEN(TRUNC(B32,0))))*POWER(10,LEN(TRUNC(B32,0)))))) -> 0.3001 | D33: =IF(C33="","",C33*$D$15) -> 5401.8 | F33: 4167.8487 | G33: =IF(F33="","",IF(LEN(TRUNC(F32,0))-LEN(TRUNC(F33,0))=0,F33-F32,IF(LEN(TRUNC(F32,0))-LEN(TRUNC(F33,0))>0,VALUE(LEFT(F32,LEN(TRUNC(F32,0))-LEN(TRUNC(F33,0))))*POWER(10,LEN(TRUNC(F33,0)))+F33-F32,F33-F32-VALUE(LEFT(F33,LEN(TRUNC(F33,0))-LEN(TRUNC(F32,0))))*POWER(10,LEN(TRUNC(F32,0)))))) -> 0.1394 | H33: =IF(G33="","",G33*$H$15) -> 2509.2 | I33: =IF(H33="","",IF(D33="","",IF(AND(H33=0,D33=0),0,H33/D33))) -> 0.46451183 | K33: 6.5 | M33: п/п | N33: установки | P33: кВ | R33: кВар | T33: кВар | V33: установки за сутки
A34: 16-00 | B34: 7876.6261 | C34: =IF(B34="","",IF(LEN(TRUNC(B33,0))-LEN(TRUNC(B34,0))=0,B34-B33,IF(LEN(TRUNC(B33,0))-LEN(TRUNC(B34,0))>0,VALUE(LEFT(B33,LEN(TRUNC(B33,0))-LEN(TRUNC(B34,0))))*POWER(10,LEN(TRUNC(B34,0)))+B34-B33,B34-B33-VALUE(LEFT(B34,LEN(TRUNC(B34,0))-LEN(TRUNC(B33,0))))*POWER(10,LEN(TRUNC(B33,0)))))) -> 0.2954 | D34: =IF(C34="","",C34*$D$15) -> 5317.2 | F34: 4167.9862 | G34: =IF(F34="","",IF(LEN(TRUNC(F33,0))-LEN(TRUNC(F34,0))=0,F34-F33,IF(LEN(TRUNC(F33,0))-LEN(TRUNC(F34,0))>0,VALUE(LEFT(F33,LEN(TRUNC(F33,0))-LEN(TRUNC(F34,0))))*POWER(10,LEN(TRUNC(F34,0)))+F34-F33,F34-F33-VALUE(LEFT(F34,LEN(TRUNC(F34,0))-LEN(TRUNC(F33,0))))*POWER(10,LEN(TRUNC(F33,0)))))) -> 0.1375 | H34: =IF(G34="","",G34*$H$15) -> 2475 | I34: =IF(H34="","",IF(D34="","",IF(AND(H34=0,D34=0),0,H34/D34))) -> 0.46547055 | K34: 6.5
A35: 17-00 | B35: 7876.9201 | C35: =IF(B35="","",IF(LEN(TRUNC(B34,0))-LEN(TRUNC(B35,0))=0,B35-B34,IF(LEN(TRUNC(B34,0))-LEN(TRUNC(B35,0))>0,VALUE(LEFT(B34,LEN(TRUNC(B34,0))-LEN(TRUNC(B35,0))))*POWER(10,LEN(TRUNC(B35,0)))+B35-B34,B35-B34-VALUE(LEFT(B35,LEN(TRUNC(B35,0))-LEN(TRUNC(B34,0))))*POWER(10,LEN(TRUNC(B34,0)))))) -> 0.294 | D35: =IF(C35="","",C35*$D$15) -> 5292 | F35: 4168.1227 | G35: =IF(F35="","",IF(LEN(TRUNC(F34,0))-LEN(TRUNC(F35,0))=0,F35-F34,IF(LEN(TRUNC(F34,0))-LEN(TRUNC(F35,0))>0,VALUE(LEFT(F34,LEN(TRUNC(F34,0))-LEN(TRUNC(F35,0))))*POWER(10,LEN(TRUNC(F35,0)))+F35-F34,F35-F34-VALUE(LEFT(F35,LEN(TRUNC(F35,0))-LEN(TRUNC(F34,0))))*POWER(10,LEN(TRUNC(F34,0)))))) -> 0.1365 | H35: =IF(G35="","",G35*$H$15) -> 2457 | I35: =IF(H35="","",IF(D35="","",IF(AND(H35=0,D35=0),0,H35/D35))) -> 0.46428571 | K35: 6.5 | N35: ТП-13, РТП-1 | P35: 0.4 | R35: 320
A36: 18-00 | B36: 7877.2036 | C36: =IF(B36="","",IF(LEN(TRUNC(B35,0))-LEN(TRUNC(B36,0))=0,B36-B35,IF(LEN(TRUNC(B35,0))-LEN(TRUNC(B36,0))>0,VALUE(LEFT(B35,LEN(TRUNC(B35,0))-LEN(TRUNC(B36,0))))*POWER(10,LEN(TRUNC(B36,0)))+B36-B35,B36-B35-VALUE(LEFT(B36,LEN(TRUNC(B36,0))-LEN(TRUNC(B35,0))))*POWER(10,LEN(TRUNC(B35,0)))))) -> 0.2835 | D36: =IF(C36="","",C36*$D$15) -> 5103 | F36: 4168.2488 | G36: =IF(F36="","",IF(LEN(TRUNC(F35,0))-LEN(TRUNC(F36,0))=0,F36-F35,IF(LEN(TRUNC(F35,0))-LEN(TRUNC(F36,0))>0,VALUE(LEFT(F35,LEN(TRUNC(F35,0))-LEN(TRUNC(F36,0))))*POWER(10,LEN(TRUNC(F36,0)))+F36-F35,F36-F35-VALUE(LEFT(F36,LEN(TRUNC(F36,0))-LEN(TRUNC(F35,0))))*POWER(10,LEN(TRUNC(F35,0)))))) -> 0.1261 | H36: =IF(G36="","",G36*$H$15) -> 2269.8 | I36: =IF(H36="","",IF(D36="","",IF(AND(H36=0,D36=0),0,H36/D36))) -> 0.44479718 | K36: 6.5 | N36: РП-1 | P36: 6 | R36: 870
A37: 19-00 | B37: 7877.4933 | C37: =IF(B37="","",IF(LEN(TRUNC(B36,0))-LEN(TRUNC(B37,0))=0,B37-B36,IF(LEN(TRUNC(B36,0))-LEN(TRUNC(B37,0))>0,VALUE(LEFT(B36,LEN(TRUNC(B36,0))-LEN(TRUNC(B37,0))))*POWER(10,LEN(TRUNC(B37,0)))+B37-B36,B37-B36-VALUE(LEFT(B37,LEN(TRUNC(B37,0))-LEN(TRUNC(B36,0))))*POWER(10,LEN(TRUNC(B36,0)))))) -> 0.2897 | D37: =IF(C37="","",C37*$D$15) -> 5214.6 | F37: 4168.377 | G37: =IF(F37="","",IF(LEN(TRUNC(F36,0))-LEN(TRUNC(F37,0))=0,F37-F36,IF(LEN(TRUNC(F36,0))-LEN(TRUNC(F37,0))>0,VALUE(LEFT(F36,LEN(TRUNC(F36,0))-LEN(TRUNC(F37,0))))*POWER(10,LEN(TRUNC(F37,0)))+F37-F36,F37-F36-VALUE(LEFT(F37,LEN(TRUNC(F37,0))-LEN(TRUNC(F36,0))))*POWER(10,LEN(TRUNC(F36,0)))))) -> 0.1282 | H37: =IF(G37="","",G37*$H$15) -> 2307.6 | I37: =IF(H37="","",IF(D37="","",IF(AND(H37=0,D37=0),0,H37/D37))) -> 0.44252675 | K37: 6.5
A38: 20-00 | B38: 7877.7848 | C38: =IF(B38="","",IF(LEN(TRUNC(B37,0))-LEN(TRUNC(B38,0))=0,B38-B37,IF(LEN(TRUNC(B37,0))-LEN(TRUNC(B38,0))>0,VALUE(LEFT(B37,LEN(TRUNC(B37,0))-LEN(TRUNC(B38,0))))*POWER(10,LEN(TRUNC(B38,0)))+B38-B37,B38-B37-VALUE(LEFT(B38,LEN(TRUNC(B38,0))-LEN(TRUNC(B37,0))))*POWER(10,LEN(TRUNC(B37,0)))))) -> 0.2915 | D38: =IF(C38="","",C38*$D$15) -> 5247 | F38: 4168.5076 | G38: =IF(F38="","",IF(LEN(TRUNC(F37,0))-LEN(TRUNC(F38,0))=0,F38-F37,IF(LEN(TRUNC(F37,0))-LEN(TRUNC(F38,0))>0,VALUE(LEFT(F37,LEN(TRUNC(F37,0))-LEN(TRUNC(F38,0))))*POWER(10,LEN(TRUNC(F38,0)))+F38-F37,F38-F37-VALUE(LEFT(F38,LEN(TRUNC(F38,0))-LEN(TRUNC(F37,0))))*POWER(10,LEN(TRUNC(F37,0)))))) -> 0.1306 | H38: =IF(G38="","",G38*$H$15) -> 2350.8 | I38: =IF(H38="","",IF(D38="","",IF(AND(H38=0,D38=0),0,H38/D38))) -> 0.44802744 | K38: 6.5
A39: 21-00 | B39: 7878.0807 | C39: =IF(B39="","",IF(LEN(TRUNC(B38,0))-LEN(TRUNC(B39,0))=0,B39-B38,IF(LEN(TRUNC(B38,0))-LEN(TRUNC(B39,0))>0,VALUE(LEFT(B38,LEN(TRUNC(B38,0))-LEN(TRUNC(B39,0))))*POWER(10,LEN(TRUNC(B39,0)))+B39-B38,B39-B38-VALUE(LEFT(B39,LEN(TRUNC(B39,0))-LEN(TRUNC(B38,0))))*POWER(10,LEN(TRUNC(B38,0)))))) -> 0.2959 | D39: =IF(C39="","",C39*$D$15) -> 5326.2 | F39: 4168.641 | G39: =IF(F39="","",IF(LEN(TRUNC(F38,0))-LEN(TRUNC(F39,0))=0,F39-F38,IF(LEN(TRUNC(F38,0))-LEN(TRUNC(F39,0))>0,VALUE(LEFT(F38,LEN(TRUNC(F38,0))-LEN(TRUNC(F39,0))))*POWER(10,LEN(TRUNC(F39,0)))+F39-F38,F39-F38-VALUE(LEFT(F39,LEN(TRUNC(F39,0))-LEN(TRUNC(F38,0))))*POWER(10,LEN(TRUNC(F38,0)))))) -> 0.1334 | H39: =IF(G39="","",G39*$H$15) -> 2401.2 | I39: =IF(H39="","",IF(D39="","",IF(AND(H39=0,D39=0),0,H39/D39))) -> 0.45082798 | K39: 6.5
A40: 22-00 | B40: 7878.3691 | C40: =IF(B40="","",IF(LEN(TRUNC(B39,0))-LEN(TRUNC(B40,0))=0,B40-B39,IF(LEN(TRUNC(B39,0))-LEN(TRUNC(B40,0))>0,VALUE(LEFT(B39,LEN(TRUNC(B39,0))-LEN(TRUNC(B40,0))))*POWER(10,LEN(TRUNC(B40,0)))+B40-B39,B40-B39-VALUE(LEFT(B40,LEN(TRUNC(B40,0))-LEN(TRUNC(B39,0))))*POWER(10,LEN(TRUNC(B39,0)))))) -> 0.2884 | D40: =IF(C40="","",C40*$D$15) -> 5191.2 | F40: 4168.7731 | G40: =IF(F40="","",IF(LEN(TRUNC(F39,0))-LEN(TRUNC(F40,0))=0,F40-F39,IF(LEN(TRUNC(F39,0))-LEN(TRUNC(F40,0))>0,VALUE(LEFT(F39,LEN(TRUNC(F39,0))-LEN(TRUNC(F40,0))))*POWER(10,LEN(TRUNC(F40,0)))+F40-F39,F40-F39-VALUE(LEFT(F40,LEN(TRUNC(F40,0))-LEN(TRUNC(F39,0))))*POWER(10,LEN(TRUNC(F39,0)))))) -> 0.1321 | H40: =IF(G40="","",G40*$H$15) -> 2377.8 | I40: =IF(H40="","",IF(D40="","",IF(AND(H40=0,D40=0),0,H40/D40))) -> 0.45804438 | K40: 6.5 | M40: III. Синхронные электродвигатели напряжением до 1000 В
A41: 23-00 | B41: 7878.6474 | C41: =IF(B41="","",IF(LEN(TRUNC(B40,0))-LEN(TRUNC(B41,0))=0,B41-B40,IF(LEN(TRUNC(B40,0))-LEN(TRUNC(B41,0))>0,VALUE(LEFT(B40,LEN(TRUNC(B40,0))-LEN(TRUNC(B41,0))))*POWER(10,LEN(TRUNC(B41,0)))+B41-B40,B41-B40-VALUE(LEFT(B41,LEN(TRUNC(B41,0))-LEN(TRUNC(B40,0))))*POWER(10,LEN(TRUNC(B40,0)))))) -> 0.2783 | D41: =IF(C41="","",C41*$D$15) -> 5009.4 | F41: 4168.9022 | G41: =IF(F41="","",IF(LEN(TRUNC(F40,0))-LEN(TRUNC(F41,0))=0,F41-F40,IF(LEN(TRUNC(F40,0))-LEN(TRUNC(F41,0))>0,VALUE(LEFT(F40,LEN(TRUNC(F40,0))-LEN(TRUNC(F41,0))))*POWER(10,LEN(TRUNC(F41,0)))+F41-F40,F41-F40-VALUE(LEFT(F41,LEN(TRUNC(F41,0))-LEN(TRUNC(F40,0))))*POWER(10,LEN(TRUNC(F40,0)))))) -> 0.1291 | H41: =IF(G41="","",G41*$H$15) -> 2323.8 | I41: =IF(H41="","",IF(D41="","",IF(AND(H41=0,D41=0),0,H41/D41))) -> 0.46388789 | K41: 6.5 | M41: №№ | N41: Место | P41: Номинальная | S41: № п-п | T41: Место установки | X41: Номинальная
A42: 24-00 | B42: 7878.9178 | C42: =IF(B42="","",IF(LEN(TRUNC(B41,0))-LEN(TRUNC(B42,0))=0,B42-B41,IF(LEN(TRUNC(B41,0))-LEN(TRUNC(B42,0))>0,VALUE(LEFT(B41,LEN(TRUNC(B41,0))-LEN(TRUNC(B42,0))))*POWER(10,LEN(TRUNC(B42,0)))+B42-B41,B42-B41-VALUE(LEFT(B42,LEN(TRUNC(B42,0))-LEN(TRUNC(B41,0))))*POWER(10,LEN(TRUNC(B41,0)))))) -> 0.2704 | D42: =IF(C42="","",C42*$D$15) -> 4867.2 | F42: 4169.0276 | G42: =IF(F42="","",IF(LEN(TRUNC(F41,0))-LEN(TRUNC(F42,0))=0,F42-F41,IF(LEN(TRUNC(F41,0))-LEN(TRUNC(F42,0))>0,VALUE(LEFT(F41,LEN(TRUNC(F41,0))-LEN(TRUNC(F42,0))))*POWER(10,LEN(TRUNC(F42,0)))+F42-F41,F42-F41-VALUE(LEFT(F42,LEN(TRUNC(F42,0))-LEN(TRUNC(F41,0))))*POWER(10,LEN(TRUNC(F41,0)))))) -> 0.1254 | H42: =IF(G42="","",G42*$H$15) -> 2257.2 | I42: =IF(H42="","",IF(D42="","",IF(AND(H42=0,D42=0),0,H42/D42))) -> 0.4637574 | K42: 6.5
...

Sheet Ячейка 30
A1: ОАО "Пластик" | G1: Шифр | M1: I. Сведения о присоединенных трансформаторах и высоковольтных электродвигателях
A2: (наименование предприятия) | M2: 1. Трансформаторы
A3: г. Узловая, Тульская, 1 | G3: Питающий центр | I3: П/ст №167 (ГПП-1) | M3: №№ | N3: Место установки | P3: Мощность | R3: Номинальн. | T3: Включен. | V3: Назначение | X3: Примечание
A4: (адрес) | R4: напряжение | T4: на ответвление | V4: тр-ра
G5: № фидера | I5: яч 30 Воейково-2 | M5: п/п | P5: ква | R5: ________ кВ | T5: ________ кВ | V5: силов. освет.
A6: (министерство, ведомство) | V6: печной
A8: ПРОТОКОЛ (первичный)
A9: записей показания электросчетчиков и вольтметров, а также определение
A10: нагрузок и тангенса "фи" за | E10: 18 Декабрь | H10: 2013 года
A11: напряжения | E11: ______6000______________ | I11: вольт
A13: Время записи часы | B13: Активн. сч-к тип | D13: СЭТ-4ТМ.03 | F13: Реактивн. сч-к тип | H13: СЭТ-4ТМ.03 | I13: Тангенс "фи" | J13: Показание | L13: Мощность
B14: ____________л__ | D14: № 0808090624 | F14: ____________л__ | H14: № 0808090624 | J14: вольтметр. | L14: включен.
B15: Расчетн. коэф | D15: 12000 | F15: Расчетн. коэф | H15: 12000 | J15: на стороне | L15: компенсир.
B16: показ. | C16: разность | D16: расход за | F16: показ. | G16: разность | H16: расход за | J16: в\н | K16: н\н | L16: устройств
B17: сч-ка | C17: показ. | D17: час (кВт) | F17: сч-ка | G17: показ. | H17: час (кВт) | L17: кВар | M17: 2. Высоковольтные электродвигатели
A18: 0-00 | B18: 5114.3808 | F18: 3185.2857 | K18: 6.6 | M18: №№ | N18: Место | Q18: Тип | T18: Номинальная | W18: Примечание
A19: 1-00 | B19: 5114.5666 | C19: =IF(B19="","",IF(LEN(TRUNC(B18,0))-LEN(TRUNC(B19,0))=0,B19-B18,IF(LEN(TRUNC(B18,0))-LEN(TRUNC(B19,0))>0,VALUE(LEFT(B18,LEN(TRUNC(B18,0))-LEN(TRUNC(B19,0))))*POWER(10,LEN(TRUNC(B19,0)))+B19-B18,B19-B18-VALUE(LEFT(B19,LEN(TRUNC(B19,0))-LEN(TRUNC(B18,0))))*POWER(10,LEN(TRUNC(B18,0)))))) -> 0.1858 | D19: =IF(C19="","",C19*$D$15) -> 2229.6 | F19: 3185.3895 | G19: =IF(F19="","",IF(LEN(TRUNC(F18,0))-LEN(TRUNC(F19,0))=0,F19-F18,IF(LEN(TRUNC(F18,0))-LEN(TRUNC(F19,0))>0,VALUE(LEFT(F18,LEN(TRUNC(F18,0))-LEN(TRUNC(F19,0))))*POWER(10,LEN(TRUNC(F19,0)))+F19-F18,F19-F18-VALUE(LEFT(F19,LEN(TRUNC(F19,0))-LEN(TRUNC(F18,0))))*POWER(10,LEN(TRUNC(F18,0)))))) -> 0.1038 | H19: =IF(G19="","",G19*$H$15) -> 1245.6 | I19: =IF(H19="","",IF(D19="","",IF(AND(H19=0,D19=0),0,H19/D19))) -> 0.55866523 | K19: 6.6 | Q19: (синхронный,
A20: 2-00 | B20: 5114.7452 | C20: =IF(B20="","",IF(LEN(TRUNC(B19,0))-LEN(TRUNC(B20,0))=0,B20-B19,IF(LEN(TRUNC(B19,0))-LEN(TRUNC(B20,0))>0,VALUE(LEFT(B19,LEN(TRUNC(B19,0))-LEN(TRUNC(B20,0))))*POWER(10,LEN(TRUNC(B20,0)))+B20-B19,B20-B19-VALUE(LEFT(B20,LEN(TRUNC(B20,0))-LEN(TRUNC(B19,0))))*POWER(10,LEN(TRUNC(B19,0)))))) -> 0.1786 | D20: =IF(C20="","",C20*$D$15) -> 2143.2 | F20: 3185.4907 | G20: =IF(F20="","",IF(LEN(TRUNC(F19,0))-LEN(TRUNC(F20,0))=0,F20-F19,IF(LEN(TRUNC(F19,0))-LEN(TRUNC(F20,0))>0,VALUE(LEFT(F19,LEN(TRUNC(F19,0))-LEN(TRUNC(F20,0))))*POWER(10,LEN(TRUNC(F20,0)))+F20-F19,F20-F19-VALUE(LEFT(F20,LEN(TRUNC(F20,0))-LEN(TRUNC(F19,0))))*POWER(10,LEN(TRUNC(F19,0)))))) -> 0.1012 | H20: =IF(G20="","",G20*$H$15) -> 1214.4 | I20: =IF(H20="","",IF(D20="","",IF(AND(H20=0,D20=0),0,H20/D20))) -> 0.56662934 | K20: 6.6 | M20: п/п | N20: установки | Q20: асинхронный) | T20: мощность кВт
A21: 3-00 | B21: 5114.9223 | C21: =IF(B21="","",IF(LEN(TRUNC(B20,0))-LEN(TRUNC(B21,0))=0,B21-B20,IF(LEN(TRUNC(B20,0))-LEN(TRUNC(B21,0))>0,VALUE(LEFT(B20,LEN(TRUNC(B20,0))-LEN(TRUNC(B21,0))))*POWER(10,LEN(TRUNC(B21,0)))+B21-B20,B21-B20-VALUE(LEFT(B21,LEN(TRUNC(B21,0))-LEN(TRUNC(B20,0))))*POWER(10,LEN(TRUNC(B20,0)))))) -> 0.1771 | D21: =IF(C21="","",C21*$D$15) -> 2125.2 | F21: 3185.5922 | G21: =IF(F21="","",IF(LEN(TRUNC(F20,0))-LEN(TRUNC(F21,0))=0,F21-F20,IF(LEN(TRUNC(F20,0))-LEN(TRUNC(F21,0))>0,VALUE(LEFT(F20,LEN(TRUNC(F20,0))-LEN(TRUNC(F21,0))))*POWER(10,LEN(TRUNC(F21,0)))+F21-F20,F21-F20-VALUE(LEFT(F21,LEN(TRUNC(F21,0))-LEN(TRUNC(F20,0))))*POWER(10,LEN(TRUNC(F20,0)))))) -> 0.1015 | H21: =IF(G21="","",G21*$H$15) -> 1218 | I21: =IF(H21="","",IF(D21="","",IF(AND(H21=0,D21=0),0,H21/D21))) -> 0.57312253 | K21: 6.6
A22: 4-00 | B22: 5115.1049 | C22: =IF(B22="","",IF(LEN(TRUNC(B21,0))-LEN(TRUNC(B22,0))=0,B22-B21,IF(LEN(TRUNC(B21,0))-LEN(TRUNC(B22,0))>0,VALUE(LEFT(B21,LEN(TRUNC(B21,0))-LEN(TRUNC(B22,0))))*POWER(10,LEN(TRUNC(B22,0)))+B22-B21,B22-B21-VALUE(LEFT(B22,LEN(TRUNC(B22,0))-LEN(TRUNC(B21,0))))*POWER(10,LEN(TRUNC(B21,0)))))) -> 0.1826 | D22: =IF(C22="","",C22*$D$15) -> 2191.2 | F22: 3185.6937 | G22: =IF(F22="","",IF(LEN(TRUNC(F21,0))-LEN(TRUNC(F22,0))=0,F22-F21,IF(LEN(TRUNC(F21,0))-LEN(TRUNC(F22,0))>0,VALUE(LEFT(F21,LEN(TRUNC(F21,0))-LEN(TRUNC(F22,0))))*POWER(10,LEN(TRUNC(F22,0)))+F22-F21,F22-F21-VALUE(LEFT(F22,LEN(TRUNC(F22,0))-LEN(TRUNC(F21,0))))*POWER(10,LEN(TRUNC(F21,0)))))) -> 0.1015 | H22: =IF(G22="","",G22*$H$15) -> 1218 | I22: =IF(H22="","",IF(D22="","",IF(AND(H22=0,D22=0),0,H22/D22))) -> 0.5558598 | K22: 6.6
A23: 5-00 | B23: 5115.2855 | C23: =IF(B23="","",IF(LEN(TRUNC(B22,0))-LEN(TRUNC(B23,0))=0,B23-B22,IF(LEN(TRUNC(B22,0))-LEN(TRUNC(B23,0))>0,VALUE(LEFT(B22,LEN(TRUNC(B22,0))-LEN(TRUNC(B23,0))))*POWER(10,LEN(TRUNC(B23,0)))+B23-B22,B23-B22-VALUE(LEFT(B23,LEN(TRUNC(B23,0))-LEN(TRUNC(B22,0))))*POWER(10,LEN(TRUNC(B22,0)))))) -> 0.1806 | D23: =IF(C23="","",C23*$D$15) -> 2167.2 | F23: 3185.7937 | G23: =IF(F23="","",IF(LEN(TRUNC(F22,0))-LEN(TRUNC(F23,0))=0,F23-F22,IF(LEN(TRUNC(F22,0))-LEN(TRUNC(F23,0))>0,VALUE(LEFT(F22,LEN(TRUNC(F22,0))-LEN(TRUNC(F23,0))))*POWER(10,LEN(TRUNC(F23,0)))+F23-F22,F23-F22-VALUE(LEFT(F23,LEN(TRUNC(F23,0))-LEN(TRUNC(F22,0))))*POWER(10,LEN(TRUNC(F22,0)))))) -> 0.1 | H23: =IF(G23="","",G23*$H$15) -> 1200 | I23: =IF(H23="","",IF(D23="","",IF(AND(H23=0,D23=0),0,H23/D23))) -> 0.55370986 | K23: 6.6
A24: 6-00 | B24: 5115.4697 | C24: =IF(B24="","",IF(LEN(TRUNC(B23,0))-LEN(TRUNC(B24,0))=0,B24-B23,IF(LEN(TRUNC(B23,0))-LEN(TRUNC(B24,0))>0,VALUE(LEFT(B23,LEN(TRUNC(B23,0))-LEN(TRUNC(B24,0))))*POWER(10,LEN(TRUNC(B24,0)))+B24-B23,B24-B23-VALUE(LEFT(B24,LEN(TRUNC(B24,0))-LEN(TRUNC(B23,0))))*POWER(10,LEN(TRUNC(B23,0)))))) -> 0.1842 | D24: =IF(C24="","",C24*$D$15) -> 2210.4 | F24: 3185.8936 | G24: =IF(F24="","",IF(LEN(TRUNC(F23,0))-LEN(TRUNC(F24,0))=0,F24-F23,IF(LEN(TRUNC(F23,0))-LEN(TRUNC(F24,0))>0,VALUE(LEFT(F23,LEN(TRUNC(F23,0))-LEN(TRUNC(F24,0))))*POWER(10,LEN(TRUNC(F24,0)))+F24-F23,F24-F23-VALUE(LEFT(F24,LEN(TRUNC(F24,0))-LEN(TRUNC(F23,0))))*POWER(10,LEN(TRUNC(F23,0)))))) -> 0.0999 | H24: =IF(G24="","",G24*$H$15) -> 1198.8 | I24: =IF(H24="","",IF(D24="","",IF(AND(H24=0,D24=0),0,H24/D24))) -> 0.54234528 | K24: 6.6
